Workbook

Sheet ANALYSIS BY SUBJECTS
A1: BAHASA MELAYU (1201)
D2: Distinction | F2: Credit | J2: Pass | L2: Fail
A3: Class | B3: Taught By | C3: Total | D3: A* | E3: A2 | F3: B3 | G3: B4 | H3: C5 | I3: C6 | J3: D7 | K3: E8 | L3: U | M3: Total 1-6 | N3: % 1-6 | O3: Total 1-8 | P3: % 1-8
A4: YEAR 10S | B4: CG SALMIAH | C4: =SUM(D4:L4) -> 20 | D4: ='[1]MASTER '!$J$38 -> 0 | E4: ='[2]MASTER '!$J$39 -> 0 | F4: ='[2]MASTER '!$J$40 -> 0 | G4: ='[2]MASTER '!$J$41 -> 2 | H4: ='[2]MASTER '!$J$42 -> 3 | I4: ='[2]MASTER '!$J$43 -> 1 | J4: ='[2]MASTER '!$J$44 -> 12 | K4: ='[2]MASTER '!$J$45 -> 2 | L4: ='[2]MASTER '!$J$46 -> 0 | M4: =SUM(D4:I4) -> 6 | N4: =((M4/C4)*100) -> 30 | O4: =SUM(D4:K4) -> 20 | P4: =((O4/C4)*100) -> 100
A5: YEAR 10C | B5: CG RAFIDAH | C5: =SUM(D5:L5) -> 18 | D5: ='[1]MASTER '!$J$38 -> 0 | E5: ='[1]MASTER '!$J$39 -> 1 | F5: ='[1]MASTER '!$J$40 -> 1 | G5: ='[1]MASTER '!$J$41 -> 1 | H5: ='[1]MASTER '!$J$42 -> 4 | I5: ='[1]MASTER '!$J$43 -> 6 | J5: ='[1]MASTER '!$J$44 -> 5 | K5: ='[1]MASTER '!$J$45 -> 0 | L5: ='[1]MASTER '!$J$46 -> 0 | M5: =SUM(D5:I5) -> 13 | N5: =((M5/C5)*100) -> 72.222222 | O5: =SUM(D5:K5) -> 18 | P5: =((O5/C5)*100) -> 100
A6: YEAR 10H | B6: CG NOOR ZURINA | C6: =SUM(D6:L6) -> 23 | D6: ='[3]MASTER '!$J$38 -> 0 | E6: ='[3]MASTER '!$J$39 -> 2 | F6: ='[3]MASTER '!$J$40 -> 8 | G6: ='[3]MASTER '!$J$41 -> 4 | H6: ='[3]MASTER '!$J$42 -> 2 | I6: ='[3]MASTER '!$J$43 -> 3 | J6: ='[3]MASTER '!$J$44 -> 3 | K6: ='[3]MASTER '!$J$45 -> 1 | L6: ='[3]MASTER '!$J$46 -> 0 | M6: =SUM(D6:I6) -> 19 | N6: =((M6/C6)*100) -> 82.608696 | O6: =SUM(D6:K6) -> 23 | P6: =((O6/C6)*100) -> 100
A7: YEAR 10O | B7: CG SALMIAH | C7: =SUM(D7:L7) -> 20 | D7: ='[4]MASTER '!$J$38 -> 0 | E7: ='[4]MASTER '!$J$39 -> 0 | F7: ='[4]MASTER '!$J$40 -> 0 | G7: ='[4]MASTER '!$J$41 -> 0 | H7: ='[4]MASTER '!$J$42 -> 5 | I7: ='[4]MASTER '!$J$43 -> 2 | J7: ='[4]MASTER '!$J$44 -> 9 | K7: ='[4]MASTER '!$J$45 -> 3 | L7: ='[4]MASTER '!$J$46 -> 1 | M7: =SUM(D7:I7) -> 7 | N7: =((M7/C7)*100) -> 35 | O7: =SUM(D7:K7) -> 19 | P7: =((O7/C7)*100) -> 95
A8: YEAR 10L | B8: CG SALMIAH | C8: =SUM(D8:L8) -> 23 | D8: ='[5]MASTER '!$J$38 -> 0 | E8: ='[5]MASTER '!$J$39 -> 1 | F8: ='[5]MASTER '!$J$40 -> 3 | G8: ='[5]MASTER '!$J$41 -> 6 | H8: ='[5]MASTER '!$J$42 -> 3 | I8: ='[5]MASTER '!$J$43 -> 6 | J8: ='[5]MASTER '!$J$44 -> 3 | K8: ='[5]MASTER '!$J$45 -> 1 | L8: ='[5]MASTER '!$J$46 -> 0 | M8: =SUM(D8:I8) -> 19 | N8: =((M8/C8)*100) -> 82.608696 | O8: =SUM(D8:K8) -> 23 | P8: =((O8/C8)*100) -> 100
A9: YEAR 10A | B9: CG RAFIDAH | C9: =SUM(D9:L9) -> 19 | D9: ='[6]MASTER '!$J$38 -> 0 | E9: ='[6]MASTER '!$J$39 -> 0 | F9: ='[6]MASTER '!$J$40 -> 2 | G9: ='[6]MASTER '!$J$41 -> 1 | H9: ='[6]MASTER '!$J$42 -> 3 | I9: ='[6]MASTER '!$J$43 -> 3 | J9: ='[6]MASTER '!$J$44 -> 9 | K9: ='[6]MASTER '!$J$45 -> 1 | L9: ='[6]MASTER '!$J$46 -> 0 | M9: =SUM(D9:I9) -> 9 | N9: =((M9/C9)*100) -> 47.368421 | O9: =SUM(D9:K9) -> 19 | P9: =((O9/C9)*100) -> 100
A10: YEAR 1OR | B10: CG NOOR ZURINA | C10: =SUM(D10:L10) -> 19 | D10: ='[7]MASTER '!$J$38 -> 2 | E10: ='[7]MASTER '!$J$39 -> 2 | F10: ='[7]MASTER '!$J$40 -> 4 | G10: ='[7]MASTER '!$J$41 -> 2 | H10: ='[7]MASTER '!$J$42 -> 4 | I10: ='[7]MASTER '!$J$43 -> 3 | J10: ='[7]MASTER '!$J$44 -> 1 | K10: ='[7]MASTER '!$J$45 -> 1 | L10: ='[7]MASTER '!$J$46 -> 0 | M10: =SUM(D10:I10) -> 17 | N10: =((M10/C10)*100) -> 89.473684 | O10: =SUM(D10:K10) -> 19 | P10: =((O10/C10)*100) -> 100
B11: Overall | C11: =SUM(D11:L11) -> 142 | D11: =SUM(D4:D10) -> 2 | E11: =SUM(E4:E10) -> 6 | F11: =SUM(F4:F10) -> 18 | G11: =SUM(G4:G10) -> 16 | H11: =SUM(H4:H10) -> 24 | I11: =SUM(I4:I10) -> 24 | J11: =SUM(J4:J10) -> 42 | K11: =SUM(K4:K10) -> 9 | ... M11: =SUM(M4:M10) -> 90 | N11: =((M11/C11)*100) -> 63.380282 | O11: =SUM(O4:O10) -> 141 | P11: =((O11/C11)*100) -> 99.295775
A13: SASTERA (2023)
D14: Distinction | G14: Credit | J14: Pass | L14: Fail
A15: Class | B15: Taught By | C15: Total | D15: A* | E15: A2 | F15: B3 | G15: B4 | H15: C5 | I15: C6 | J15: D7 | K15: E8 | L15: U | M15: Total 1-6 | N15: % 1-6 | O15: Total 1-8 | P15: % 1-8
A16: YEAR 10A | B16: CG YULI | C16: =SUM(D16:L16) -> 19 | D16: ='[6]MASTER '!$BI$38 -> 0 | E16: ='[6]MASTER '!$BI$39 -> 1 | F16: ='[6]MASTER '!$BI$40 -> 0 | G16: ='[6]MASTER '!$BI$41 -> 3 | H16: ='[6]MASTER '!$BI$42 -> 1 | I16: ='[6]MASTER '!$BI$43 -> 3 | J16: ='[6]MASTER '!$BI$44 -> 6 | K16: ='[6]MASTER '!$BI$45 -> 1 | L16: ='[6]MASTER '!$BI$46 -> 4 | M16: =SUM(D16:I16) -> 8 | N16: =((M16/C16)*100) -> 42.105263 | O16: =SUM(D16:K16) -> 15 | P16: =((O16/C16)*100) -> 78.947368
A17: YEAR 1OR | B17: CG YULI | C17: =SUM(D17:L17) -> 19 | D17: ='[7]MASTER '!$BI$37 -> 1 | E17: ='[7]MASTER '!$BI$38 -> 1 | F17: ='[7]MASTER '!$BI$39 -> 4 | G17: ='[7]MASTER '!$BI$40 -> 2 | H17: ='[7]MASTER '!$BI$41 -> 1 | I17: ='[7]MASTER '!$BI$42 -> 1 | J17: ='[7]MASTER '!$BI$43 -> 5 | K17: ='[7]MASTER '!$BI$44 -> 3 | L17: ='[7]MASTER '!$BI$45 -> 1 | M17: =SUM(D17:I17) -> 10 | N17: =((M17/C17)*100) -> 52.631579 | O17: =SUM(D17:K17) -> 18 | P17: =((O17/C17)*100) -> 94.736842
B18: Overall | C18: =SUM(C16:C17) -> 38 | D18: =SUM(D16:D17) -> 1 | E18: =SUM(E16:E17) -> 2 | F18: =SUM(F16:F17) -> 4 | G18: =SUM(G16:G17) -> 5 | H18: =SUM(H16:H17) -> 2 | I18: =SUM(I16:I17) -> 4 | J18: =SUM(J16:J17) -> 11 | K18: =SUM(K16:K17) -> 4 | L18: 3 | M18: =SUM(M16:M17) -> 18 | N18: =((M18/C18)*100) -> 47.368421 | O18: =SUM(O16:O17) -> 33 | P18: =((O18/C18)*100) -> 86.842105
A20: ENGLISH LANGUAGE (1120)
D21: Distinction | G21: Credit | J21: Pass | L21: Fail
A22: Class | B22: Taught By | C22: Total | D22: A* | E22: A2 | F22: B3 | G22: B4 | H22: C5 | I22: C6 | J22: D7 | K22: E8 | L22: U | M22: Total 1-6 | N22: % 1-6 | O22: Total 1-8 | P22: % 1-8
A23: YEAR 10S | B23: CG CHANTELLE | C23: =SUM(D23:L23) -> 20 | D23: ='[2]MASTER '!$T$38 -> 3 | E23: ='[2]MASTER '!$T$39 -> 15 | F23: ='[2]MASTER '!$T$40 -> 0 | G23: ='[2]MASTER '!$T$41 -> 1 | H23: ='[2]MASTER '!$T$42 -> 1 | I23: ='[2]MASTER '!$T$43 -> 0 | J23: ='[2]MASTER '!$T$44 -> 0 | K23: ='[2]MASTER '!$T$45 -> 0 | L23: ='[2]MASTER '!$T$46 -> 0 | M23: =SUM(D23:I23) -> 20 | N23: =((M23/C23)*100) -> 100 | O23: =SUM(D23:K23) -> 20 | P23: =((O23/C23)*100) -> 100
A24: YEAR 10C | B24: CG ASFARINA | C24: =SUM(D24:L24) -> 18 | D24: ='[1]MASTER '!$T$38 -> 0 | E24: ='[1]MASTER '!$T$39 -> 8 | F24: ='[1]MASTER '!$T$40 -> 4 | G24: ='[1]MASTER '!$T$41 -> 4 | H24: ='[1]MASTER '!$T$42 -> 2 | I24: ='[1]MASTER '!$T$43 -> 0 | J24: ='[1]MASTER '!$T$44 -> 0 | K24: ='[1]MASTER '!$T$45 -> 0 | L24: ='[1]MASTER '!$T$46 -> 0 | M24: =SUM(D24:I24) -> 18 | N24: =((M24/C24)*100) -> 100 | O24: =SUM(D24:K24) -> 18 | P24: =((O24/C24)*100) -> 100
A25: YEAR 10H | B25: CG NOR SUZI | C25: =SUM(D25:L25) -> 0 | D25: ='[3]MASTER '!$T$38 -> 0 | E25: ='[3]MASTER '!$T$39 -> 0 | F25: ='[3]MASTER '!$T$40 -> 0 | G25: ='[3]MASTER '!$T$41 -> 0 | H25: ='[3]MASTER '!$T$42 -> 0 | I25: ='[3]MASTER '!$T$43 -> 0 | J25: ='[3]MASTER '!$T$44 -> 0 | K25: ='[3]MASTER '!$T$45 -> 0 | L25: ='[3]MASTER '!$T$46 -> 0 | M25: =SUM(D25:I25) -> 0 | N25: =((M25/C25)*100) -> #DIV/0! | O25: =SUM(D25:K25) -> 0 | P25: =((O25/C25)*100) -> #DIV/0!
A26: YEAR 10O | B26: CG ANA | C26: =SUM(D26:L26) -> 20 | D26: ='[4]MASTER '!$T$38 -> 1 | E26: ='[4]MASTER '!$T$39 -> 0 | F26: ='[4]MASTER '!$T$40 -> 0 | G26: ='[4]MASTER '!$T$41 -> 0 | H26: ='[4]MASTER '!$T$42 -> 1 | I26: ='[4]MASTER '!$T$43 -> 7 | J26: ='[4]MASTER '!$T$44 -> 8 | K26: ='[4]MASTER '!$T$45 -> 3 | L26: ='[4]MASTER '!$T$46 -> 0 | M26: =SUM(D26:I26) -> 9 | N26: =((M26/C26)*100) -> 45 | O26: =SUM(D26:K26) -> 20 | P26: =((O26/C26)*100) -> 100
A27: YEAR 10L | B27: CG ANA | C27: =SUM(D27:L27) -> 23 | D27: ='[5]MASTER '!$T$37 -> 0 | E27: ='[5]MASTER '!$T$38 -> 4 | F27: ='[5]MASTER '!$T$39 -> 0 | G27: ='[5]MASTER '!$T$40 -> 0 | H27: ='[5]MASTER '!$T$41 -> 1 | I27: ='[5]MASTER '!$T$42 -> 5 | J27: ='[5]MASTER '!$T$43 -> 5 | K27: ='[5]MASTER '!$T$44 -> 7 | L27: ='[5]MASTER '!$T$45 -> 1 | M27: =SUM(D27:I27) -> 10 | N27: =((M27/C27)*100) -> 43.478261 | O27: =SUM(D27:K27) -> 22 | P27: =((O27/C27)*100) -> 95.652174
A28: YEAR 10A | B28: CG NOR SUZI | C28: =SUM(D28:L28) -> 0 | D28: ='[6]MASTER '!$T$38 -> 0 | E28: ='[6]MASTER '!$T$39 -> 0 | F28: ='[6]MASTER '!$T$40 -> 0 | G28: ='[6]MASTER '!$T$41 -> 0 | H28: ='[6]MASTER '!$T$42 -> 0 | I28: ='[6]MASTER '!$T$43 -> 0 | J28: ='[6]MASTER '!$T$44 -> 0 | K28: ='[6]MASTER '!$T$45 -> 0 | L28: ='[6]MASTER '!$T$46 -> 0 | M28: =SUM(D28:I28) -> 0 | N28: =((M28/C28)*100) -> #DIV/0! | O28: =SUM(D28:K28) -> 0 | P28: =((O28/C28)*100) -> #DIV/0!
B29: Overall | C29: =SUM(C23:C28) -> 81 | D29: =SUM(D23:D28) -> 4 | E29: =SUM(E23:E28) -> 27 | F29: =SUM(F23:F28) -> 4 | G29: =SUM(G23:G28) -> 5 | H29: =SUM(H23:H28) -> 5 | I29: =SUM(I23:I28) -> 12 | J29: =SUM(J23:J28) -> 13 | ... M29: =SUM(M23:M28) -> 57 | N29: =((M29/C29)*100) -> 70.37037 | O29: =SUM(O23:O28) -> 80 | P29: =((O29/C29)*100) -> 98.765432
A31: IGCSE ENGLISH
D32: Distinction | F32: Credit | J32: Pass | L32: Fail
A33: Class | B33: Taught By | C33: Total | D33: A* | E33: A2 | F33: B3 | G33: B4 | H33: C5 | I33: C6 | J33: D7 | K33: E8 | L33: U | M33: Total 1-6 | N33: % 1-6 | O33: Total 1-8 | P33: % 1-8
A34: YEAR 1OR | B34: CG HJH MARIAH | C34: =SUM(D34:L34) -> 19 | D34: ='[7]MASTER '!$T$37 -> 0 | E34: ='[7]MASTER '!$T$38 -> 3 | F34: ='[7]MASTER '!$T$39 -> 11 | G34: ='[7]MASTER '!$T$40 -> 0 | H34: ='[7]MASTER '!$T$41 -> 0 | I34: ='[7]MASTER '!$T$42 -> 0 | J34: ='[7]MASTER '!$T$43 -> 4 | K34: ='[7]MASTER '!$T$44 -> 0 | L34: ='[7]MASTER '!$T$45 -> 1 | M34: =SUM(D34:I34) -> 14 | N34: =((M34/C34)*100) -> 73.684211 | O34: =SUM(D34:K34) -> 18 | P34: =((O34/C34)*100) -> 94.736842
B35: Overall | C35: =SUM(C34:C34) -> 19 | D35: =SUM(D34:D34) -> 0 | E35: =SUM(E34:E34) -> 3 | F35: =SUM(F34:F34) -> 11 | G35: =SUM(G34:G34) -> 0 | H35: =SUM(H34:H34) -> 0 | I35: =SUM(I34:I34) -> 0 | J35: =SUM(J34:J34) -> 4 | ... M35: =SUM(M34:M34) -> 14 | N35: =((M35/C35)*100) -> 73.684211 | O35: =SUM(O34:O34) -> 18 | P35: =((O35/C35)*100) -> 94.736842
A37: E2L IGCSE Core (0510)
D38: GRADE
A39: Class | B39: Taught By | C39: Total | D39: C | E39: D | F39: E | G39: F | H39: G | I39: U | M39: Total C | N39: % C | O39: Total C - G | P39: % C - G
A40: 10G | M40: =D40 -> 0 | N40: =((M40/C40)*100) -> #DIV/0! | O40: =SUM(D40:H40) -> 0 | P40: =((O40/C40)*100) -> #DIV/0!
A41: 10H | M41: =D41 -> 0 | N41: =((M41/C41)*100) -> #DIV/0! | O41: =SUM(D41:H41) -> 0 | P41: =((O41/C41)*100) -> #DIV/0!
A42: 10T | M42: =D42 -> 0 | N42: =((M42/C42)*100) -> #DIV/0! | O42: =SUM(D42:H42) -> 0 | P42: =((O42/C42)*100) -> #DIV/0!
B43: Overall | C43: =SUM(C40:C42) -> 0 | D43: =SUM(D40:D42) -> 0 | E43: =SUM(E40:E42) -> 0 | F43: =SUM(F40:F42) -> 0 | G43: =SUM(G40:G42) -> 0 | H43: =SUM(H40:H42) -> 0 | I43: =SUM(I42:I42) -> 0 | M43: =SUM(M37:M42) -> 0 | N43: =((M43/C43)*100) -> #DIV/0! | O43: =SUM(O37:O42) -> 0 | P43: =((O43/C43)*100) -> #DIV/0!
A45: MATHEMATICS D (4024)
...

Sheet OVERALL PERFORMANCES
A2: Subjects | B2: % 1-6 | C2: % 1-8
A3: B.Melayu | B3: ='ANALYSIS BY SUBJECTS'!N202 -> 63.380282 | C3: ='ANALYSIS BY SUBJECTS'!P202 -> 99.295775
A4: English Language | B4: ='ANALYSIS BY SUBJECTS'!N203 -> 70.37037 | C4: ='ANALYSIS BY SUBJECTS'!P203 -> 98.765432
A5: IGCSE English | B5: ='ANALYSIS BY SUBJECTS'!N204 -> 73.684211 | C5: ='ANALYSIS BY SUBJECTS'!P204 -> 94.736842
A6: Mathematics D | B6: ='ANALYSIS BY SUBJECTS'!N205 -> 59.615385 | C6: ='ANALYSIS BY SUBJECTS'!P205 -> 85.576923
A7: Physics | B7: ='ANALYSIS BY SUBJECTS'!N207 -> 45.679012 | C7: ='ANALYSIS BY SUBJECTS'!P207 -> 71.604938
A8: Chemistry | B8: ='ANALYSIS BY SUBJECTS'!N208 -> 40.983607 | C8: ='ANALYSIS BY SUBJECTS'!P208 -> 75.409836
A9: Biology | B9: ='ANALYSIS BY SUBJECTS'!N209 -> 18.421053 | C9: ='ANALYSIS BY SUBJECTS'!P209 -> 73.684211
A10: Combined Science | B10: ='ANALYSIS BY SUBJECTS'!N210 -> 10.526316 | C10: ='ANALYSIS BY SUBJECTS'!P210 -> 68.421053
A11: Geography | B11: ='ANALYSIS BY SUBJECTS'!N211 -> 42.857143 | C11: ='ANALYSIS BY SUBJECTS'!P211 -> 73.809524
A12: IRK | B12: ='ANALYSIS BY SUBJECTS'!N212 -> 79.577465 | C12: ='ANALYSIS BY SUBJECTS'!P212 -> 92.253521
A13: History | B13: ='ANALYSIS BY SUBJECTS'!N213 -> 93.023256 | C13: ='ANALYSIS BY SUBJECTS'!P213 -> 100
A14: Commerce | B14: ='ANALYSIS BY SUBJECTS'!N214 -> 56.521739 | C14: ='ANALYSIS BY SUBJECTS'!P214 -> 95.652174
A15: Accounting | B15: ='ANALYSIS BY SUBJECTS'!N215 -> 23.529412 | C15: ='ANALYSIS BY SUBJECTS'!P215 -> 70.588235
A16: Art & Design | B16: ='ANALYSIS BY SUBJECTS'!N216 -> 80.952381 | C16: ='ANALYSIS BY SUBJECTS'!P216 -> 95.238095
A17: Food & Nutrition | B17: ='ANALYSIS BY SUBJECTS'!N217 -> 16.666667 | C17: ='ANALYSIS BY SUBJECTS'!P217 -> 50
A18: Agriculture | B18: ='ANALYSIS BY SUBJECTS'!N218 -> 48.837209 | C18: ='ANALYSIS BY SUBJECTS'!P218 -> 93.023256
... A21: Computer Science | B21: ='ANALYSIS BY SUBJECTS'!N221 -> #DIV/0! | C21: ='ANALYSIS BY SUBJECTS'!P221 -> #DIV/0!

Sheet CLASS AVERAGE
A2: Class + No of stdn | B2: Class Avg
A3: 10Sci2 (26)
A4: 10Sci3 (25)
A5: 10A (31)
A6: 10M (30)
A7: 10B (31)
A8: 10E (32)
A9: 10R (31)

Sheet By Class
A2: Menengah 4A
D3: Distinction | F3: Credit | J3: Pass | L3: Fail
A4: Subjects | B4: Taught By | C4: Total | D4: 1 | E4: 2 | F4: 3 | G4: 4 | H4: 5 | I4: 6 | J4: 7 | K4: 8 | L4: 9 | M4: Total 1-6 | N4: % 1-6 | O4: Total 1-8 | P4: % 1-8
A5: B.Melayu | N5: =((M5/C5)*100) -> #DIV/0! | O5: =SUM(D5:K5) -> 0 | P5: =((O5/C5)*100) -> #DIV/0!
A6: English | N6: =((M6/C6)*100) -> #DIV/0! | O6: =SUM(D6:K6) -> 0 | P6: =((O6/C6)*100) -> #DIV/0!
A7: Maths | N7: =((M7/C7)*100) -> #DIV/0! | O7: =SUM(D7:K7) -> 0 | P7: =((O7/C7)*100) -> #DIV/0!
A8: Add Maths | N8: =((M8/C8)*100) -> #DIV/0! | O8: =SUM(D8:K8) -> 0 | P8: =((O8/C8)*100) -> #DIV/0!
A9: Physics | N9: =((M9/C9)*100) -> #DIV/0! | O9: =SUM(D9:K9) -> 0 | P9: =((O9/C9)*100) -> #DIV/0!
A10: Chemistry | N10: =((M10/C10)*100) -> #DIV/0! | O10: =SUM(D10:K10) -> 0 | P10: =((O10/C10)*100) -> #DIV/0!
A11: Biology | N11: =((M11/C11)*100) -> #DIV/0! | O11: =SUM(D11:K11) -> 0 | P11: =((O11/C11)*100) -> #DIV/0!
A12: Geography | N12: =((M12/C12)*100) -> #DIV/0! | O12: =SUM(D12:K12) -> 0 | P12: =((O12/C12)*100) -> #DIV/0!
A13: Computer | N13: =((M13/C13)*100) -> #DIV/0! | O13: =SUM(D13:K13) -> 0 | P13: =((O13/C13)*100) -> #DIV/0!
N14: =AVERAGE(N5:N13) -> #DIV/0! | P14: =AVERAGE(P5:P13) -> #DIV/0!
A16: Menengah 4B
D17: Distinction | F17: Credit | J17: Pass | L17: Fail
A18: Subjects | B18: Taught By | C18: Total | D18: 1 | E18: 2 | F18: 3 | G18: 4 | H18: 5 | I18: 6 | J18: 7 | K18: 8 | L18: 9 | M18: Total 1-6 | N18: % 1-6 | O18: Total 1-8 | P18: % 1-8
A19: B.Melayu | N19: =((M19/C19)*100) -> #DIV/0! | O19: =SUM(D19:K19) -> 0 | P19: =((O19/C19)*100) -> #DIV/0!
A20: English | N20: =((M20/C20)*100) -> #DIV/0! | O20: =SUM(D20:K20) -> 0 | P20: =((O20/C20)*100) -> #DIV/0!
A21: Maths | N21: =((M21/C21)*100) -> #DIV/0! | O21: =SUM(D21:K21) -> 0 | P21: =((O21/C21)*100) -> #DIV/0!
A22: Physics | N22: =((M22/C22)*100) -> #DIV/0! | O22: 10 | P22: =((O22/C22)*100) -> #DIV/0!
A23: Chemistry | N23: =((M23/C23)*100) -> #DIV/0! | O23: 10 | P23: =((O23/C23)*100) -> #DIV/0!
A24: Biology | N24: =((M24/C24)*100) -> #DIV/0! | O24: 19 | P24: =((O24/C24)*100) -> #DIV/0!
A25: Geography | N25: =((M25/C25)*100) -> #DIV/0! | O25: 19 | P25: =((O25/C25)*100) -> #DIV/0!
A26: Economics | N26: =((M26/C26)*100) -> #DIV/0! | O26: 3 | P26: =((O26/C26)*100) -> #DIV/0!
A27: Computer | N27: =((M27/C27)*100) -> #DIV/0! | O27: 2 | P27: =((O27/C27)*100) -> #DIV/0!
A28: POA | N28: =((M28/C28)*100) -> #DIV/0! | O28: 12 | P28: =((O28/C28)*100) -> #DIV/0!
N29: =AVERAGE(N19:N28) -> #DIV/0! | P29: =AVERAGE(P19:P28) -> #DIV/0!
A31: Menengah 4C
D32: Distinction | F32: Credit | J32: Pass | L32: Fail
A33: Subjects | B33: Taught By | C33: Total | D33: 1 | E33: 2 | F33: 3 | G33: 4 | H33: 5 | I33: 6 | J33: 7 | K33: 8 | L33: 9 | M33: Total 1-6 | N33: % 1-6 | O33: Total 1-8 | P33: % 1-8
A34: B.Melayu | N34: =((M34/C34)*100) -> #DIV/0! | O34: 18 | P34: =((O34/C34)*100) -> #DIV/0!
A35: English | N35: =((M35/C35)*100) -> #DIV/0! | O35: 15 | P35: =((O35/C35)*100) -> #DIV/0!
A36: Maths | N36: =((M36/C36)*100) -> #DIV/0! | O36: 9 | P36: =((O36/C36)*100) -> #DIV/0!
A37: Comb Sc | N37: =((M37/C37)*100) -> #DIV/0! | O37: 6 | P37: =((O37/C37)*100) -> #DIV/0!
A38: Geography | N38: =((M38/C38)*100) -> #DIV/0! | O38: 7 | P38: =((O38/C38)*100) -> #DIV/0!
A39: History | N39: =((M39/C39)*100) -> #DIV/0! | O39: 14 | P39: =((O39/C39)*100) -> #DIV/0!
A40: IRK | N40: =((M40/C40)*100) -> #DIV/0! | O40: 16 | P40: =((O40/C40)*100) -> #DIV/0!
A41: Commerce | N41: =((M41/C41)*100) -> #DIV/0! | O41: 14 | P41: =((O41/C41)*100) -> #DIV/0!
A42: Agr Sc | N42: =((M42/C42)*100) -> #DIV/0! | O42: 2 | P42: =((O42/C42)*100) -> #DIV/0!
N43: =AVERAGE(N34:N42) -> #DIV/0! | P43: =AVERAGE(P34:P42) -> #DIV/0!
...

Sheet IGCSE SUBJECTS
A1: Y10 MID YEAR EXAMINATION 2016
A2: SEKOLAH MENENGAH PG ANAK PUTERI HAJAH MASNA
A4: IGCSE SUBJECTS
C6: NUMBER OF CANDIDATES OBTAINING | O6: PERCENTAGE FOR GRADES
C7: NO. OF CANDIDATE | E7: Distinction | G7: Credit | I7: Pass | M7: Fail | N7: ABSENT | O7: Distinction | P7: Credit | Q7: Pass | R7: Fail | S7: Credit | T7: Pass
A8: Subject | C8: REGISTERED | D8: SAT | E8: A* | F8: A | G8: B | H8: C | I8: D | J8: E | K8: F | L8: G | M8: U | N8: X | O8: A*- A | P8: B-C | Q8: D-G | R8: U | S8: % A* - C | T8: % A* - G
A9: IGCSE English E2L (Core) | C9: ='ANALYSIS BY SUBJECTS'!$C$43 -> 0 | D9: ='ANALYSIS BY SUBJECTS'!$C$43 -> 0 | H9: ='ANALYSIS BY SUBJECTS'!D43 -> 0 | I9: ='ANALYSIS BY SUBJECTS'!E43 -> 0 | J9: ='ANALYSIS BY SUBJECTS'!F43 -> 0 | K9: ='ANALYSIS BY SUBJECTS'!G43 -> 0 | L9: ='ANALYSIS BY SUBJECTS'!H43 -> 0 | M9: ='ANALYSIS BY SUBJECTS'!I43 -> 0 | O9: =((E9+F9)/C9) -> #DIV/0! | P9: =(SUM(G9:H9)/C9) -> #DIV/0! | Q9: =(SUM(I9:L9)/C9) -> #DIV/0! | R9: =M9/C9 -> #DIV/0! | S9: =(SUM(E9:H9)/C9) -> #DIV/0! | T9: =(SUM(E9:L9)/D9) -> #DIV/0!
A10: IGCSE Mathematics (Core) | C10: ='ANALYSIS BY SUBJECTS'!$C$60 -> 38 | D10: ='ANALYSIS BY SUBJECTS'!$C$60 -> 38 | H10: 1 | I10: ='ANALYSIS BY SUBJECTS'!#REF! -> #REF! | J10: 2 | K10: 15 | L10: 38 | M10: 27 | O10: =((E10+F10)/C10) -> 0 | P10: =(SUM(G10:H10)/C10) -> 0.026315789 | Q10: =(SUM(I10:L10)/C10) -> #REF! | R10: =M10/C10 -> 0.71052632 | S10: =(SUM(E10:H10)/C10) -> 0.026315789 | T10: =(SUM(E10:L10)/D10) -> #REF!
A11: IGCSE PE (Extended) | C11: 21 | D11: 21 | E11: ='ANALYSIS BY SUBJECTS'!#REF! -> #REF! | F11: ='ANALYSIS BY SUBJECTS'!#REF! -> #REF! | G11: 2 | H11: 7 | I11: 4 | J11: 1 | K11: 0 | L11: 0 | M11: ='ANALYSIS BY SUBJECTS'!#REF! -> #REF! | O11: =((E11+F11)/C11) -> #REF! | P11: =(SUM(G11:H11)/C11) -> 0.42857143 | Q11: =(SUM(I11:L11)/C11) -> 0.23809524 | R11: =M11/C11 -> #REF! | S11: =(SUM(E11:H11)/C11) -> #REF! | T11: =(SUM(E11:L11)/D11) -> #REF!
A12: IGCSE ICT (Extended) | O12: =((E12+F12)/C12) -> #DIV/0! | P12: =(SUM(G12:H12)/C12) -> #DIV/0! | Q12: =(SUM(I12:L12)/C12) -> #DIV/0! | R12: =M12/C12 -> #DIV/0! | S12: =(SUM(E12:H12)/C12) -> #DIV/0! | T12: =(SUM(E12:L12)/D12) -> #DIV/0!

Sheet OVERALL ANALYSIS
A1: SEKOLAH MENENGAH PG ANAK PUTERI HAJAH MASNA
A2: OVERALL RESULTS - YEAR 10, ASSESSMENT 2 2026
C4: NUMBER OF CANDIDATES OBTAINING | O4: PERCENTAGE FOR GRADES | U4: REMARKS
C5: NO. OF CANDIDATE | E5: Distinction | G5: Credit | K5: Pass | M5: Fail | N5: ABSENT | O5: Distinction | P5: Credit | Q5: Pass | R5: Fail | S5: Credit | T5: Pass
A6: Subject | C6: REGISTERED | D6: SAT | E6: A*1 | F6: A2 | G6: B3 | H6: B4 | I6: C5 | J6: C6 | K6: D7 | L6: E8 | M6: U | N6: X | O6: 1-2 | P6: 3-6 | Q6: 7-8 | R6: 9 | S6: % 1-6 | T6: % 1-8
A7: B.Melayu | C7: ='ANALYSIS BY SUBJECTS'!C202 -> 142 | D7: ='ANALYSIS BY SUBJECTS'!C202 -> 142 | E7: ='ANALYSIS BY SUBJECTS'!D202 -> 2 | F7: ='ANALYSIS BY SUBJECTS'!E202 -> 6 | G7: ='ANALYSIS BY SUBJECTS'!F202 -> 18 | H7: ='ANALYSIS BY SUBJECTS'!G202 -> 16 | I7: ='ANALYSIS BY SUBJECTS'!H202 -> 24 | J7: ='ANALYSIS BY SUBJECTS'!I202 -> 24 | K7: ='ANALYSIS BY SUBJECTS'!J202 -> 42 | ... M7: ='ANALYSIS BY SUBJECTS'!L202 -> 1 | N7: 0 | O7: =((E7+F7)/C7) -> 0.056338028 | P7: =(SUM(G7:J7)/C7) -> 0.57746479 | Q7: =(SUM(K7:L7)/C7) -> 0.35915493 | R7: =M7/C7 -> 0.0070422535 | S7: ='OVERALL PERFORMANCES'!B3 -> 63.380282 | T7: ='OVERALL PERFORMANCES'!C3 -> 99.295775
A8: English Language | C8: ='ANALYSIS BY SUBJECTS'!C203 -> 81 | D8: ='ANALYSIS BY SUBJECTS'!C203 -> 81 | E8: ='ANALYSIS BY SUBJECTS'!D203 -> 4 | F8: ='ANALYSIS BY SUBJECTS'!E203 -> 27 | G8: ='ANALYSIS BY SUBJECTS'!F203 -> 4 | H8: ='ANALYSIS BY SUBJECTS'!G203 -> 5 | I8: ='ANALYSIS BY SUBJECTS'!H203 -> 5 | J8: ='ANALYSIS BY SUBJECTS'!I203 -> 12 | K8: ='ANALYSIS BY SUBJECTS'!J203 -> 13 | ... M8: ='ANALYSIS BY SUBJECTS'!L203 -> 1 | N8: 0 | O8: =((E8+F8)/C8) -> 0.38271605 | P8: =(SUM(G8:J8)/C8) -> 0.32098765 | Q8: =(SUM(K8:L8)/C8) -> 0.28395062 | R8: =M8/C8 -> 0.012345679 | S8: ='OVERALL PERFORMANCES'!B4 -> 70.37037 | T8: ='OVERALL PERFORMANCES'!C4 -> 98.765432
A9: IGCSE English | C9: ='ANALYSIS BY SUBJECTS'!C204 -> 19 | D9: ='ANALYSIS BY SUBJECTS'!C204 -> 19 | E9: ='ANALYSIS BY SUBJECTS'!D204 -> 0 | F9: ='ANALYSIS BY SUBJECTS'!E204 -> 3 | G9: ='ANALYSIS BY SUBJECTS'!F204 -> 11 | H9: ='ANALYSIS BY SUBJECTS'!G204 -> 0 | I9: ='ANALYSIS BY SUBJECTS'!H204 -> 0 | J9: ='ANALYSIS BY SUBJECTS'!I204 -> 0 | K9: ='ANALYSIS BY SUBJECTS'!J204 -> 4 | ... M9: ='ANALYSIS BY SUBJECTS'!L204 -> 1 | N9: 0 | O9: =((E9+F9)/C9) -> 0.15789474 | P9: =(SUM(G9:J9)/C9) -> 0.57894737 | Q9: =(SUM(K9:L9)/C9) -> 0.21052632 | R9: =M9/C9 -> 0.052631579 | S9: ='ANALYSIS BY SUBJECTS'!N204 -> 73.684211 | T9: ='ANALYSIS BY SUBJECTS'!P204 -> 94.736842
A10: Mathematics D | C10: ='ANALYSIS BY SUBJECTS'!C205 -> 104 | D10: ='ANALYSIS BY SUBJECTS'!C205 -> 104 | E10: ='ANALYSIS BY SUBJECTS'!D205 -> 6 | F10: ='ANALYSIS BY SUBJECTS'!E205 -> 22 | G10: ='ANALYSIS BY SUBJECTS'!F205 -> 12 | H10: ='ANALYSIS BY SUBJECTS'!G205 -> 7 | I10: ='ANALYSIS BY SUBJECTS'!H205 -> 8 | J10: ='ANALYSIS BY SUBJECTS'!I205 -> 7 | K10: ='ANALYSIS BY SUBJECTS'!J205 -> 19 | ... M10: ='ANALYSIS BY SUBJECTS'!L205 -> 15 | N10: 0 | O10: =((E10+F10)/C10) -> 0.26923077 | P10: =(SUM(G10:J10)/C10) -> 0.32692308 | Q10: =(SUM(K10:L10)/C10) -> 0.25961538 | R10: =M10/C10 -> 0.14423077 | S10: ='OVERALL PERFORMANCES'!B6 -> 59.615385 | T10: ='OVERALL PERFORMANCES'!C6 -> 85.576923
A11: Physics | C11: ='ANALYSIS BY SUBJECTS'!C207 -> 81 | D11: ='ANALYSIS BY SUBJECTS'!C207 -> 81 | E11: ='ANALYSIS BY SUBJECTS'!D207 -> 4 | F11: ='ANALYSIS BY SUBJECTS'!E207 -> 13 | G11: ='ANALYSIS BY SUBJECTS'!F207 -> 10 | H11: ='ANALYSIS BY SUBJECTS'!G207 -> 5 | I11: ='ANALYSIS BY SUBJECTS'!H207 -> 3 | J11: ='ANALYSIS BY SUBJECTS'!I207 -> 2 | K11: ='ANALYSIS BY SUBJECTS'!J207 -> 14 | ... M11: ='ANALYSIS BY SUBJECTS'!L207 -> 23 | N11: 0 | O11: =((E11+F11)/C11) -> 0.20987654 | P11: =(SUM(G11:J11)/C11) -> 0.24691358 | Q11: =(SUM(K11:L11)/C11) -> 0.25925926 | R11: =M11/C11 -> 0.28395062 | S11: ='OVERALL PERFORMANCES'!B7 -> 45.679012 | T11: ='OVERALL PERFORMANCES'!C7 -> 71.604938
A12: Chemistry | C12: ='ANALYSIS BY SUBJECTS'!C208 -> 61 | D12: ='ANALYSIS BY SUBJECTS'!C208 -> 61 | E12: ='ANALYSIS BY SUBJECTS'!D208 -> 1 | F12: ='ANALYSIS BY SUBJECTS'!E208 -> 4 | G12: ='ANALYSIS BY SUBJECTS'!F208 -> 3 | H12: ='ANALYSIS BY SUBJECTS'!G208 -> 2 | I12: ='ANALYSIS BY SUBJECTS'!H208 -> 8 | J12: ='ANALYSIS BY SUBJECTS'!I208 -> 7 | K12: ='ANALYSIS BY SUBJECTS'!J208 -> 8 | ... M12: ='ANALYSIS BY SUBJECTS'!L208 -> 15 | N12: 0 | O12: =((E12+F12)/C12) -> 0.081967213 | P12: =(SUM(G12:J12)/C12) -> 0.32786885 | Q12: =(SUM(K12:L12)/C12) -> 0.3442623 | R12: =M12/C12 -> 0.24590164 | S12: ='OVERALL PERFORMANCES'!B8 -> 40.983607 | T12: ='OVERALL PERFORMANCES'!C8 -> 75.409836
A13: Biology | C13: ='ANALYSIS BY SUBJECTS'!C209 -> 38 | D13: ='ANALYSIS BY SUBJECTS'!C209 -> 38 | E13: ='ANALYSIS BY SUBJECTS'!D209 -> 1 | F13: ='ANALYSIS BY SUBJECTS'!E209 -> 1 | G13: ='ANALYSIS BY SUBJECTS'!F209 -> 1 | H13: ='ANALYSIS BY SUBJECTS'!G209 -> 2 | I13: ='ANALYSIS BY SUBJECTS'!H209 -> 1 | J13: ='ANALYSIS BY SUBJECTS'!I209 -> 1 | K13: ='ANALYSIS BY SUBJECTS'!J209 -> 11 | ... M13: ='ANALYSIS BY SUBJECTS'!L209 -> 10 | N13: 0 | O13: =((E13+F13)/C13) -> 0.052631579 | P13: =(SUM(G13:J13)/C13) -> 0.13157895 | Q13: =(SUM(K13:L13)/C13) -> 0.55263158 | R13: =M13/C13 -> 0.26315789 | S13: ='OVERALL PERFORMANCES'!B9 -> 18.421053 | T13: ='OVERALL PERFORMANCES'!C9 -> 73.684211
A14: Combined Science | C14: ='ANALYSIS BY SUBJECTS'!C210 -> 38 | D14: ='ANALYSIS BY SUBJECTS'!C210 -> 38 | E14: ='ANALYSIS BY SUBJECTS'!D210 -> 0 | F14: ='ANALYSIS BY SUBJECTS'!E210 -> 0 | G14: ='ANALYSIS BY SUBJECTS'!F210 -> 0 | H14: ='ANALYSIS BY SUBJECTS'!G210 -> 0 | I14: ='ANALYSIS BY SUBJECTS'!H210 -> 0 | J14: ='ANALYSIS BY SUBJECTS'!I210 -> 4 | K14: ='ANALYSIS BY SUBJECTS'!J210 -> 9 | ... M14: ='ANALYSIS BY SUBJECTS'!L210 -> 12 | N14: 0 | O14: =((E14+F14)/C14) -> 0 | P14: =(SUM(G14:J14)/C14) -> 0.10526316 | Q14: =(SUM(K14:L14)/C14) -> 0.57894737 | R14: =M14/C14 -> 0.31578947 | S14: ='OVERALL PERFORMANCES'!B10 -> 10.526316 | T14: ='OVERALL PERFORMANCES'!C10 -> 68.421053
A15: Geography | C15: ='ANALYSIS BY SUBJECTS'!C211 -> 42 | D15: ='ANALYSIS BY SUBJECTS'!C211 -> 42 | E15: ='ANALYSIS BY SUBJECTS'!D211 -> 1 | F15: ='ANALYSIS BY SUBJECTS'!E211 -> 6 | G15: ='ANALYSIS BY SUBJECTS'!F211 -> 1 | H15: ='ANALYSIS BY SUBJECTS'!G211 -> 4 | I15: ='ANALYSIS BY SUBJECTS'!H211 -> 3 | J15: ='ANALYSIS BY SUBJECTS'!I211 -> 3 | K15: ='ANALYSIS BY SUBJECTS'!J211 -> 7 | ... M15: ='ANALYSIS BY SUBJECTS'!L211 -> 11 | N15: 0 | O15: =((E15+F15)/C15) -> 0.16666667 | P15: =(SUM(G15:J15)/C15) -> 0.26190476 | Q15: =(SUM(K15:L15)/C15) -> 0.30952381 | R15: =M15/C15 -> 0.26190476 | S15: ='OVERALL PERFORMANCES'!B11 -> 42.857143 | T15: ='OVERALL PERFORMANCES'!C11 -> 73.809524
A16: IRK | C16: ='ANALYSIS BY SUBJECTS'!C212 -> 142 | D16: ='ANALYSIS BY SUBJECTS'!C212 -> 142 | E16: ='ANALYSIS BY SUBJECTS'!D212 -> 57 | F16: ='ANALYSIS BY SUBJECTS'!E212 -> 20 | G16: ='ANALYSIS BY SUBJECTS'!F212 -> 8 | H16: ='ANALYSIS BY SUBJECTS'!G212 -> 13 | I16: ='ANALYSIS BY SUBJECTS'!H212 -> 12 | J16: ='ANALYSIS BY SUBJECTS'!I212 -> 3 | K16: ='ANALYSIS BY SUBJECTS'!J212 -> 13 | ... M16: ='ANALYSIS BY SUBJECTS'!L212 -> 11 | N16: 0 | O16: =((E16+F16)/C16) -> 0.54225352 | P16: =(SUM(G16:J16)/C16) -> 0.25352113 | Q16: =(SUM(K16:L16)/C16) -> 0.12676056 | R16: =M16/C16 -> 0.077464789 | S16: ='OVERALL PERFORMANCES'!B12 -> 79.577465 | T16: ='OVERALL PERFORMANCES'!C12 -> 92.253521
A17: History | C17: ='ANALYSIS BY SUBJECTS'!C213 -> 43 | D17: ='ANALYSIS BY SUBJECTS'!C213 -> 43 | E17: ='ANALYSIS BY SUBJECTS'!D213 -> 1 | F17: ='ANALYSIS BY SUBJECTS'!E213 -> 19 | G17: ='ANALYSIS BY SUBJECTS'!F213 -> 6 | H17: ='ANALYSIS BY SUBJECTS'!G213 -> 9 | I17: ='ANALYSIS BY SUBJECTS'!H213 -> 3 | J17: ='ANALYSIS BY SUBJECTS'!I213 -> 2 | K17: ='ANALYSIS BY SUBJECTS'!J213 -> 3 | ... M17: ='ANALYSIS BY SUBJECTS'!L213 -> 0 | N17: 0 | O17: =((E17+F17)/C17) -> 0.46511628 | P17: =(SUM(G17:J17)/C17) -> 0.46511628 | Q17: =(SUM(K17:L17)/C17) -> 0.069767442 | R17: =M17/C17 -> 0 | S17: ='OVERALL PERFORMANCES'!B13 -> 93.023256 | T17: ='OVERALL PERFORMANCES'!C13 -> 100
A18: Commerce | C18: ='ANALYSIS BY SUBJECTS'!C214 -> 23 | D18: ='ANALYSIS BY SUBJECTS'!C214 -> 23 | E18: ='ANALYSIS BY SUBJECTS'!D214 -> 0 | F18: ='ANALYSIS BY SUBJECTS'!E214 -> 2 | G18: ='ANALYSIS BY SUBJECTS'!F214 -> 2 | H18: ='ANALYSIS BY SUBJECTS'!G214 -> 3 | I18: ='ANALYSIS BY SUBJECTS'!H214 -> 3 | J18: ='ANALYSIS BY SUBJECTS'!I214 -> 3 | K18: ='ANALYSIS BY SUBJECTS'!J214 -> 9 | ... M18: ='ANALYSIS BY SUBJECTS'!L214 -> 1 | N18: 0 | O18: =((E18+F18)/C18) -> 0.086956522 | P18: =(SUM(G18:J18)/C18) -> 0.47826087 | Q18: =(SUM(K18:L18)/C18) -> 0.39130435 | R18: =M18/C18 -> 0.043478261 | S18: ='OVERALL PERFORMANCES'!B14 -> 56.521739 | T18: ='OVERALL PERFORMANCES'!C14 -> 95.652174
A19: Accounting | C19: ='ANALYSIS BY SUBJECTS'!C215 -> 17 | D19: ='ANALYSIS BY SUBJECTS'!C215 -> 17 | E19: ='ANALYSIS BY SUBJECTS'!D215 -> 0 | F19: ='ANALYSIS BY SUBJECTS'!E215 -> 0 | G19: ='ANALYSIS BY SUBJECTS'!F215 -> 0 | H19: ='ANALYSIS BY SUBJECTS'!G215 -> 2 | I19: ='ANALYSIS BY SUBJECTS'!H215 -> 1 | J19: ='ANALYSIS BY SUBJECTS'!I215 -> 1 | K19: ='ANALYSIS BY SUBJECTS'!J215 -> 3 | ... M19: ='ANALYSIS BY SUBJECTS'!L215 -> 5 | N19: 0 | O19: =((E19+F19)/C19) -> 0 | P19: =(SUM(G19:J19)/C19) -> 0.23529412 | Q19: =(SUM(K19:L19)/C19) -> 0.47058824 | R19: =M19/C19 -> 0.29411765 | S19: ='OVERALL PERFORMANCES'!B15 -> 23.529412 | T19: ='OVERALL PERFORMANCES'!C15 -> 70.588235
A20: Art & Design | C20: ='ANALYSIS BY SUBJECTS'!C216 -> 21 | D20: ='ANALYSIS BY SUBJECTS'!C216 -> 21 | E20: ='ANALYSIS BY SUBJECTS'!D216 -> 0 | F20: ='ANALYSIS BY SUBJECTS'!E216 -> 0 | G20: ='ANALYSIS BY SUBJECTS'!F216 -> 0 | H20: ='ANALYSIS BY SUBJECTS'!G216 -> 1 | I20: ='ANALYSIS BY SUBJECTS'!H216 -> 9 | J20: ='ANALYSIS BY SUBJECTS'!I216 -> 7 | K20: ='ANALYSIS BY SUBJECTS'!J216 -> 3 | ... M20: ='ANALYSIS BY SUBJECTS'!L216 -> 1 | N20: 0 | O20: =((E20+F20)/C20) -> 0 | P20: =(SUM(G20:J20)/C20) -> 0.80952381 | Q20: =(SUM(K20:L20)/C20) -> 0.14285714 | R20: =M20/C20 -> 0.047619048 | S20: ='OVERALL PERFORMANCES'!B16 -> 80.952381 | T20: ='OVERALL PERFORMANCES'!C16 -> 95.238095
A21: Food & Nutrition | C21: ='ANALYSIS BY SUBJECTS'!C217 -> 18 | D21: ='ANALYSIS BY SUBJECTS'!C217 -> 18 | E21: ='ANALYSIS BY SUBJECTS'!D217 -> 0 | F21: ='ANALYSIS BY SUBJECTS'!E217 -> 0 | G21: ='ANALYSIS BY SUBJECTS'!F217 -> 0 | H21: ='ANALYSIS BY SUBJECTS'!G217 -> 0 | I21: ='ANALYSIS BY SUBJECTS'!H217 -> 1 | J21: ='ANALYSIS BY SUBJECTS'!I217 -> 2 | K21: ='ANALYSIS BY SUBJECTS'!J217 -> 3 | ... M21: ='ANALYSIS BY SUBJECTS'!L217 -> 9 | N21: 0 | O21: =((E21+F21)/C21) -> 0 | P21: =(SUM(G21:J21)/C21) -> 0.16666667 | Q21: =(SUM(K21:L21)/C21) -> 0.33333333 | R21: =M21/C21 -> 0.5 | S21: ='OVERALL PERFORMANCES'!B17 -> 16.666667 | T21: ='OVERALL PERFORMANCES'!C17 -> 50
A22: Agriculture | C22: ='ANALYSIS BY SUBJECTS'!C218 -> 43 | D22: ='ANALYSIS BY SUBJECTS'!C218 -> 43 | E22: ='ANALYSIS BY SUBJECTS'!D218 -> 0 | F22: ='ANALYSIS BY SUBJECTS'!E218 -> 3 | G22: ='ANALYSIS BY SUBJECTS'!F218 -> 1 | H22: ='ANALYSIS BY SUBJECTS'!G218 -> 8 | I22: ='ANALYSIS BY SUBJECTS'!H218 -> 6 | J22: ='ANALYSIS BY SUBJECTS'!I218 -> 3 | K22: ='ANALYSIS BY SUBJECTS'!J218 -> 13 | ... M22: ='ANALYSIS BY SUBJECTS'!L218 -> 3 | N22: 0 | O22: =((E22+F22)/C22) -> 0.069767442 | P22: =(SUM(G22:J22)/C22) -> 0.41860465 | Q22: =(SUM(K22:L22)/C22) -> 0.44186047 | R22: =M22/C22 -> 0.069767442 | S22: ='OVERALL PERFORMANCES'!B18 -> 48.837209 | T22: ='OVERALL PERFORMANCES'!C18 -> 93.023256
... A24: Travel and Tourism | C24: ='ANALYSIS BY SUBJECTS'!C220 -> 31 | D24: ='ANALYSIS BY SUBJECTS'!C220 -> 31 | E24: ='ANALYSIS BY SUBJECTS'!D220 -> 1 | F24: ='ANALYSIS BY SUBJECTS'!E220 -> 0 | G24: ='ANALYSIS BY SUBJECTS'!F220 -> 3 | H24: ='ANALYSIS BY SUBJECTS'!G220 -> 5 | I24: ='ANALYSIS BY SUBJECTS'!H220 -> 4 | J24: ='ANALYSIS BY SUBJECTS'!I220 -> 8 | K24: ='ANALYSIS BY SUBJECTS'!J220 -> 6 | ... M24: ='ANALYSIS BY SUBJECTS'!L220 -> 0 | N24: 0 | O24: =((E24+F24)/C24) -> 0.032258065 | P24: =(SUM(G24:J24)/C24) -> 0.64516129 | Q24: =(SUM(K24:L24)/C24) -> 0.32258065 | R24: =M24/C24 -> 0 | S24: ='OVERALL PERFORMANCES'!B20 -> 67.741935 | T24: ='OVERALL PERFORMANCES'!C20 -> 100
A25: Computer Science | C25: ='ANALYSIS BY SUBJECTS'!C182 -> 0 | D25: ='ANALYSIS BY SUBJECTS'!C182 -> 0 | E25: ='ANALYSIS BY SUBJECTS'!D182 -> 0 | F25: ='ANALYSIS BY SUBJECTS'!E182 -> 0 | G25: ='ANALYSIS BY SUBJECTS'!F182 -> 0 | H25: ='ANALYSIS BY SUBJECTS'!G182 -> 0 | I25: ='ANALYSIS BY SUBJECTS'!H182 -> 0 | J25: ='ANALYSIS BY SUBJECTS'!I182 -> 0 | K25: ='ANALYSIS BY SUBJECTS'!J182 -> 0 | ... M25: ='ANALYSIS BY SUBJECTS'!L182 -> 0 | N25: 0 | O25: =((E25+F25)/C25) -> #DIV/0! | P25: =(SUM(G25:J25)/C25) -> #DIV/0! | Q25: =(SUM(K25:L25)/C25) -> #DIV/0! | R25: =M25/C25 -> #DIV/0! | S25: ='OVERALL PERFORMANCES'!B21 -> #DIV/0! | T25: ='OVERALL PERFORMANCES'!C21 -> #DIV/0!
A26: Literature in English | C26: 4 | D26: 4 | E26: 0 | F26: 0 | G26: 1 | H26: 1 | I26: 1 | J26: 1 | K26: ='ANALYSIS BY SUBJECTS'!J221 -> 0 | L26: ='ANALYSIS BY SUBJECTS'!K221 -> 0 | M26: ='ANALYSIS BY SUBJECTS'!L221 -> 0 | N26: 0 | O26: =((E26+F26)/C26) -> 0 | P26: =(SUM(G26:J26)/C26) -> 1 | Q26: =(SUM(K26:L26)/C26) -> 0 | R26: =M26/C26 -> 0 | S26: ='OVERALL PERFORMANCES'!B21 -> #DIV/0! | T26: ='OVERALL PERFORMANCES'!C21 -> #DIV/0!
C28: NUMBER OF CANDIDATES OBTAINING | O28: PERCENTAGE FOR GRADES | U28: REMARKS
C29: NO. OF CANDIDATE | E29: Distinction | G29: Credit | I29: Pass | M29: Fail | N29: ABSENT | O29: Distinction | P29: Credit | Q29: Pass | R29: Fail | S29: Credit | T29: Pass
A30: Subject | C30: REGISTERED | D30: SAT | E30: A* | F30: A | G30: B | H30: C | I30: D | J30: E | K30: F | L30: G | M30: U | N30: X | O30: A*- A | P30: B-C | Q30: D-G | R30: U | S30: % A* - C | T30: % A* - G
A31: IGCSE English E2L (Core) | C31: ='ANALYSIS BY SUBJECTS'!$C$43 -> 0 | D31: ='ANALYSIS BY SUBJECTS'!$C$43 -> 0 | H31: ='ANALYSIS BY SUBJECTS'!D43 -> 0 | I31: ='ANALYSIS BY SUBJECTS'!E43 -> 0 | J31: ='ANALYSIS BY SUBJECTS'!F43 -> 0 | K31: ='ANALYSIS BY SUBJECTS'!G43 -> 0 | L31: ='ANALYSIS BY SUBJECTS'!H43 -> 0 | M31: ='ANALYSIS BY SUBJECTS'!I43 -> 0 | N31: 0 | O31: =((E31+F31)/C31) -> #DIV/0! | P31: =(SUM(G31:H31)/C31) -> #DIV/0! | Q31: =(SUM(I31:L31)/C31) -> #DIV/0! | R31: =M31/C31 -> #DIV/0! | S31: =(SUM(E31:H31)/C31) -> #DIV/0! | T31: =(SUM(E31:L31)/D31) -> #DIV/0!
A32: IGCSE Mathematics (Core) | C32: ='ANALYSIS BY SUBJECTS'!$C$60 -> 38 | D32: ='ANALYSIS BY SUBJECTS'!$C$60 -> 38 | H32: ='ANALYSIS BY SUBJECTS'!D60 -> 17 | I32: ='ANALYSIS BY SUBJECTS'!E60 -> 8 | J32: ='ANALYSIS BY SUBJECTS'!F60 -> 9 | K32: ='ANALYSIS BY SUBJECTS'!G60 -> 3 | L32: ='ANALYSIS BY SUBJECTS'!H60 -> 0 | M32: ='ANALYSIS BY SUBJECTS'!I60 -> 1 | N32: 0 | O32: =((E32+F32)/C32) -> 0 | P32: =(SUM(G32:H32)/C32) -> 0.44736842 | Q32: =(SUM(I32:L32)/C32) -> 0.52631579 | R32: =M32/C32 -> 0.026315789 | S32: =(SUM(E32:H32)/C32) -> 0.44736842 | T32: =(SUM(E32:L32)/D32) -> 0.97368421
A33: ICT | C33: ='ANALYSIS BY SUBJECTS'!$C$197 -> 26 | D33: ='ANALYSIS BY SUBJECTS'!$C$197 -> 26 | E33: ='ANALYSIS BY SUBJECTS'!D197 -> 0 | F33: ='ANALYSIS BY SUBJECTS'!E197 -> 0 | G33: ='ANALYSIS BY SUBJECTS'!F197 -> 0 | H33: ='ANALYSIS BY SUBJECTS'!G197 -> 0 | I33: ='ANALYSIS BY SUBJECTS'!H197 -> 0 | J33: ='ANALYSIS BY SUBJECTS'!I197 -> 0 | K33: ='ANALYSIS BY SUBJECTS'!J197 -> 1 | L33: ='ANALYSIS BY SUBJECTS'!K197 -> 0 | ... N33: ='ANALYSIS BY SUBJECTS'!M197 -> 0 | O33: =((E33+F33)/C33) -> 0 | P33: =(SUM(G33:H33)/C33) -> 0 | Q33: =(SUM(I33:L33)/C33) -> 0.038461538 | R33: =M33/C33 -> 0.96153846 | S33: =(SUM(E33:H33)/C33) -> 0 | T33: =(SUM(E33:L33)/D33) -> 0.038461538

Sheet Sheet1
A1: Y10 MID YEAR EXAMINATION 2016
A2: SEKOLAH MENENGAH PG ANAK PUTERI HAJAH MASNA
A4: No. Of Candidate Registered | E4: 195
A5: No. Of Candidate Sitting | E5: 195
A6: Withdrawn | E6: 0
A8: Credit Attained | B8: No. Of Student | D8: %
A9: 9
A10: 8
A11: 7
A12: 6
A13: 5
A14: 4
A15: 3
A16: 2
A17: 1
A18: 0
A19: Total | B19: 195
C22: No. of Student | D22: %
A23: 4 or more Credits | D23: =C23/B19 -> 0
A24: 5 or more Credits | D24: =C24/B19 -> 0

Sheet Sheet2

Sheet 3'O' and 5'O' & above
A1: YEAR 10, ASSESSMENT 2 2026
B3: No. of Candidates | C3: No. of Credits Obtained | M3: 5 'O' & above | O3: 3 'O' & above
C4: 9 | D4: 8 | E4: 7 | F4: 6 | G4: 5 | H4: 4 | I4: 3 | J4: 2 | K4: 1 | L4: 0 | M4: No. of Candidates | N4: % | O4: No. of Candidates | P4: %
A5: YEAR 10S | B5: =SUM(C5:L5) -> 20 | C5: {=TRANSPOSE('[2]MASTER '!$DW$38:DW47)} -> 0 | D5: 0 | E5: 2 | F5: 4 | G5: 8 | H5: 3 | I5: 2 | J5: 1 | K5: 0 | L5: 0 | M5: =SUM(C5:G5) -> 14 | N5: =M5/B5 -> 0.7 | O5: =SUM(C5:I5) -> 19 | P5: =O5/B5 -> 0.95
A6: YEAR 10C | B6: =SUM(C6:L6) -> 19 | C6: {=TRANSPOSE('[1]MASTER '!$DW$38:DW47)} -> 0 | D6: 2 | E6: 4 | F6: 4 | G6: 4 | H6: 3 | I6: 0 | J6: 1 | K6: 0 | L6: 1 | M6: =SUM(C6:G6) -> 14 | N6: =M6/B6 -> 0.73684211 | O6: =SUM(C6:I6) -> 17 | P6: =O6/B6 -> 0.89473684
A7: YEAR10H | B7: =SUM(C7:L7) -> 23 | C7: {=TRANSPOSE('[3]MASTER '!$DW$38:DW47)} -> 0 | D7: 0 | E7: 0 | F7: 1 | G7: 1 | H7: 7 | I7: 5 | J7: 6 | K7: 3 | L7: 0 | M7: =SUM(C7:G7) -> 2 | N7: =M7/B7 -> 0.086956522 | O7: =SUM(C7:I7) -> 14 | P7: =O7/B7 -> 0.60869565
A8: YEAR10O | B8: =SUM(C8:L8) -> 20 | C8: {=TRANSPOSE('[4]MASTER '!$DW$38:DW47)} -> 0 | D8: 0 | E8: 0 | F8: 1 | G8: 7 | H8: 7 | I8: 4 | J8: 0 | K8: 0 | L8: 1 | M8: =SUM(C8:G8) -> 8 | N8: =M8/B8 -> 0.4 | O8: =SUM(C8:I8) -> 19 | P8: =O8/B8 -> 0.95
A9: YEAR 10L | B9: =SUM(C9:L9) -> 25 | C9: {=TRANSPOSE('[5]MASTER '!$DW$38:DW47)} -> 0 | D9: 1 | E9: 1 | F9: 2 | G9: 3 | H9: 5 | I9: 6 | J9: 4 | K9: 2 | L9: 1 | M9: =SUM(C9:G9) -> 7 | N9: =M9/B9 -> 0.28 | O9: =SUM(C9:I9) -> 18 | P9: =O9/B9 -> 0.72
A10: YEAR 10A | B10: =SUM(C10:L10) -> 19 | C10: {=TRANSPOSE('[6]MASTER '!$DW$38:DW47)} -> 0 | D10: 0 | E10: 0 | F10: 0 | G10: 1 | H10: 6 | I10: 2 | J10: 5 | K10: 5 | L10: 0 | M10: =SUM(C10:G10) -> 1 | N10: =M10/B10 -> 0.052631579 | O10: =SUM(C10:I10) -> 9 | P10: =O10/B10 -> 0.47368421
A11: YEAR 10R | B11: =SUM(C11:L11) -> 18 | C11: ='[7]MASTER '!$DV$37 -> 0 | D11: ='[7]MASTER '!$DV$38 -> 1 | E11: ='[7]MASTER '!$DV$39 -> 8 | F11: ='[7]MASTER '!$DV$40 -> 1 | G11: ='[7]MASTER '!$DV$41 -> 3 | H11: ='[7]MASTER '!$DV$42 -> 1 | I11: ='[7]MASTER '!$DV$43 -> 2 | J11: ='[7]MASTER '!$DV$44 -> 2 | K11: ='[7]MASTER '!$DV$45 -> 0 | L11: ='[7]MASTER '!$DV$46 -> 0 | M11: =SUM(C11:G11) -> 13 | N11: =M11/B11 -> 0.72222222 | O11: =SUM(C11:I11) -> 16 | P11: =O11/B11 -> 0.88888889
A12: Total No. of Candidates | B12: =SUM(C12:L12) -> 144 | C12: =SUM(C5:C11) -> 0 | D12: =SUM(D5:D11) -> 4 | E12: =SUM(E5:E11) -> 15 | F12: =SUM(F5:F11) -> 13 | G12: =SUM(G5:G11) -> 27 | H12: =SUM(H5:H11) -> 32 | I12: =SUM(I5:I11) -> 21 | J12: =SUM(J5:J11) -> 19 | ... M12: =SUM(M5:M11) -> 59 | N12: =M12/B12 -> 0.40972222 | O12: =SUM(O5:O11) -> 112 | P12: =O12/B12 -> 0.77777778
A14: % obtained 5'O' & above | B14: =$N$12 -> 0.40972222
A15: % obtained 3'O' & above | B15: =$P$12 -> 0.77777778

Sheet No.of Credits Attained
A1: YEAR 9, ASSESSMENT 1 2025
A2: SEKOLAH MENENGAH PG ANAK PUTERI HAJAH MASNA
A4: No. Of Candidate Registered | E4: 200
A5: No. Of Candidate Sitting | E5: =$B$19 -> 144 | AC5: 29
A6: Withdrawn | E6: 0
A8: Credit Attained | B8: No. Of Student | D8: %
A9: 9 | B9: ='3''O'' and 5''O'' & above'!$C$12 -> 0 | D9: =B9/B19 -> 0
A10: 8 | B10: ='3''O'' and 5''O'' & above'!$D$12 -> 4 | D10: =B10/B19 -> 0.027777778
A11: 7 | B11: ='3''O'' and 5''O'' & above'!$E$12 -> 15 | D11: =B11/B19 -> 0.10416667
A12: 6 | B12: ='3''O'' and 5''O'' & above'!$F$12 -> 13 | D12: =B12/B19 -> 0.090277778
A13: 5 | B13: ='3''O'' and 5''O'' & above'!$G$12 -> 27 | D13: =B13/B19 -> 0.1875
A14: 4 | B14: ='3''O'' and 5''O'' & above'!$H$12 -> 32 | D14: =B14/B19 -> 0.22222222
A15: 3 | B15: ='3''O'' and 5''O'' & above'!$I$12 -> 21 | D15: =B15/B19 -> 0.14583333
A16: 2 | B16: ='3''O'' and 5''O'' & above'!$J$12 -> 19 | D16: =B16/B19 -> 0.13194444
A17: 1 | B17: ='3''O'' and 5''O'' & above'!$K$12 -> 10 | D17: =B17/B19 -> 0.069444444
A18: 0 | B18: ='3''O'' and 5''O'' & above'!$L$12 -> 3 | D18: =B18/B19 -> 0.020833333
A19: Total | B19: =SUM(B9:C18) -> 144
C22: No. of Student | D22: %
A23: 3 or more Credits | C23: =SUM(B9:C15) -> 112 | D23: =C23/B19 -> 0.77777778
A24: 4 or more Credits | C24: =SUM(B9:C14) -> 91 | D24: =C24/B19 -> 0.63194444
A25: 5 or more Credits | C25: =SUM(B9:C13) -> 59 | D25: =C25/B19 -> 0.40972222
