Workbook

Sheet ANALYSIS BY SUBJECTS
A1: BAHASA MELAYU (1201)
D2: Distinction | F2: Credit | J2: Pass | L2: Fail
A3: Class | B3: Taught By | C3: Total | D3: A* | E3: A2 | F3: B3 | G3: B4 | H3: C5 | I3: C6 | J3: D7 | K3: E8 | L3: U | M3: Total 1-6 | N3: % 1-6 | O3: Total 1-8 | P3: % 1-8
A4: 11D | B4: CG HAJI HABIL | C4: =SUM(D4:L4) -> 17 | D4: ='[1]MASTER '!$J$38 -> 0 | E4: ='[1]MASTER '!$J$39 -> 10 | F4: ='[1]MASTER '!$J$40 -> 5 | G4: ='[1]MASTER '!$J$41 -> 2 | H4: ='[1]MASTER '!$J$42 -> 0 | I4: ='[1]MASTER '!$J$43 -> 0 | J4: ='[1]MASTER '!$J$44 -> 0 | K4: ='[1]MASTER '!$J$45 -> 0 | L4: ='[1]MASTER '!$J$46 -> 0 | M4: =SUM(D4:I4) -> 17 | N4: =((M4/C4)*100) -> 100 | O4: =SUM(D4:K4) -> 17 | P4: =((O4/C4)*100) -> 100
A5: 11I | B5: CG AMALINA | C5: =SUM(D5:L5) -> 21 | D5: ='[2]MASTER '!$J$38 -> 0 | E5: ='[2]MASTER '!$J$39 -> 3 | F5: ='[2]MASTER '!$J$40 -> 5 | G5: ='[2]MASTER '!$J$41 -> 5 | H5: ='[2]MASTER '!$J$42 -> 3 | I5: ='[2]MASTER '!$J$43 -> 5 | J5: ='[2]MASTER '!$J$44 -> 0 | K5: ='[2]MASTER '!$J$45 -> 0 | L5: ='[2]MASTER '!$J$46 -> 0 | M5: =SUM(D5:I5) -> 21 | N5: =((M5/C5)*100) -> 100 | O5: =SUM(D5:K5) -> 21 | P5: =((O5/C5)*100) -> 100
A6: 11S | B6: CG HAJI HABIL | C6: =SUM(D6:L6) -> 15 | D6: ='[3]MASTER '!$J$38 -> 0 | E6: ='[3]MASTER '!$J$39 -> 4 | F6: ='[3]MASTER '!$J$40 -> 8 | G6: ='[3]MASTER '!$J$41 -> 2 | H6: ='[3]MASTER '!$J$42 -> 1 | I6: ='[3]MASTER '!$J$43 -> 0 | J6: ='[3]MASTER '!$J$44 -> 0 | K6: ='[3]MASTER '!$J$45 -> 0 | L6: ='[3]MASTER '!$J$46 -> 0 | M6: =SUM(D6:I6) -> 15 | N6: =((M6/C6)*100) -> 100 | O6: =SUM(D6:K6) -> 15 | P6: =((O6/C6)*100) -> 100
A7: 11C | B7: CG AMALINA | C7: =SUM(D7:L7) -> 24 | D7: ='[4]MASTER '!$J$38 -> 0 | E7: ='[4]MASTER '!$J$39 -> 2 | F7: ='[4]MASTER '!$J$40 -> 2 | G7: ='[4]MASTER '!$J$41 -> 3 | H7: ='[4]MASTER '!$J$42 -> 7 | I7: ='[4]MASTER '!$J$43 -> 5 | J7: ='[4]MASTER '!$J$44 -> 2 | K7: ='[4]MASTER '!$J$45 -> 3 | L7: ='[4]MASTER '!$J$46 -> 0 | M7: =SUM(D7:I7) -> 19 | N7: =((M7/C7)*100) -> 79.166667 | O7: =SUM(D7:K7) -> 24 | P7: =((O7/C7)*100) -> 100
A8: 11O | B8: CG HAJI HABIL; | C8: =SUM(D8:L8) -> 24 | D8: ='[5]MASTER '!$J$38 -> 0 | E8: ='[5]MASTER '!$J$39 -> 5 | F8: ='[5]MASTER '!$J$40 -> 10 | G8: ='[5]MASTER '!$J$41 -> 5 | H8: ='[5]MASTER '!$J$42 -> 2 | I8: ='[5]MASTER '!$J$43 -> 2 | J8: ='[5]MASTER '!$J$44 -> 0 | K8: ='[5]MASTER '!$J$45 -> 0 | L8: ='[5]MASTER '!$J$46 -> 0 | M8: =SUM(D8:I8) -> 24 | N8: =((M8/C8)*100) -> 100 | O8: =SUM(D8:K8) -> 24 | P8: =((O8/C8)*100) -> 100
A9: 11V | B9: CG HAJAH NOORAINI | C9: =SUM(D9:L9) -> 25 | D9: ='[6]MASTER '!$J$38 -> 0 | E9: ='[6]MASTER '!$J$39 -> 1 | F9: ='[6]MASTER '!$J$40 -> 3 | G9: ='[6]MASTER '!$J$41 -> 6 | H9: ='[6]MASTER '!$J$42 -> 5 | I9: ='[6]MASTER '!$J$43 -> 3 | J9: ='[6]MASTER '!$J$44 -> 6 | K9: ='[6]MASTER '!$J$45 -> 1 | L9: ='[6]MASTER '!$J$46 -> 0 | M9: =SUM(D9:I9) -> 18 | N9: =((M9/C9)*100) -> 72 | O9: =SUM(D9:K9) -> 25 | P9: =((O9/C9)*100) -> 100
A10: 11E | B10: CG HAJAH NOORAINI | C10: =SUM(D10:L10) -> 21 | D10: ='[7]MASTER '!$J$38 -> 0 | E10: ='[7]MASTER '!$J$39 -> 0 | F10: ='[7]MASTER '!$J$40 -> 0 | G10: ='[7]MASTER '!$J$41 -> 3 | H10: ='[7]MASTER '!$J$42 -> 3 | I10: ='[7]MASTER '!$J$43 -> 3 | J10: ='[7]MASTER '!$J$44 -> 4 | K10: ='[7]MASTER '!$J$45 -> 4 | L10: ='[7]MASTER '!$J$46 -> 4 | M10: =SUM(D10:I10) -> 9 | N10: =((M10/C10)*100) -> 42.857143 | O10: =SUM(D10:K10) -> 17 | P10: =((O10/C10)*100) -> 80.952381
A11: 11R | B11: CG HAJAH NOORAINI | C11: =SUM(D11:L11) -> 18 | D11: ='[8]MASTER '!$J$36 -> 0 | E11: ='[8]MASTER '!$J$37 -> 0 | F11: ='[8]MASTER '!$J$38 -> 2 | G11: ='[8]MASTER '!$J$39 -> 0 | H11: ='[8]MASTER '!$J$42 -> 4 | I11: ='[8]MASTER '!$J$41 -> 3 | J11: ='[8]MASTER '!$J$42 -> 4 | K11: ='[8]MASTER '!$J$43 -> 3 | L11: ='[8]MASTER '!$J$44 -> 2 | M11: =SUM(D11:I11) -> 9 | N11: =((M11/C11)*100) -> 50 | O11: =SUM(D11:K11) -> 16 | P11: =((O11/C11)*100) -> 88.888889
B12: Overall | C12: =SUM(C4:C11) -> 165 | D12: =SUM(D4:D11) -> 0 | E12: =SUM(E4:E11) -> 25 | F12: =SUM(F4:F11) -> 35 | G12: =SUM(G4:G11) -> 26 | H12: =SUM(H4:H11) -> 25 | I12: =SUM(I4:I11) -> 21 | J12: =SUM(J4:J11) -> 16 | ... M12: =SUM(M4:M11) -> 132 | N12: =((M12/C12)*100) -> 80 | O12: =SUM(D12:K12) -> 159 | P12: =((O12/C12)*100) -> 96.363636
A14: SASTERA (2023)
D15: Distinction | G15: Credit | J15: Pass | L15: Fail
A16: Class | B16: Taught By | C16: Total | D16: A* | E16: A2 | F16: B3 | G16: B4 | H16: C5 | I16: C6 | J16: D7 | K16: E8 | L16: U | M16: Total 1-6 | N16: % 1-6 | O16: Total 1-8 | P16: % 1-8
A17: 11E | B17: CG UMMI SAHIRAH | C17: =SUM(D17:L17) -> 21 | D17: ='[7]MASTER '!$BI$38 -> 0 | E17: ='[7]MASTER '!$BI$39 -> 0 | F17: ='[7]MASTER '!$BI$40 -> 0 | G17: ='[7]MASTER '!$BI$41 -> 3 | H17: ='[7]MASTER '!$BI$42 -> 3 | I17: ='[7]MASTER '!$BI$43 -> 2 | J17: ='[7]MASTER '!$BI$44 -> 3 | K17: ='[7]MASTER '!$BI$45 -> 7 | L17: ='[7]MASTER '!$BI$46 -> 3 | M17: =SUM(D17:I17) -> 8 | N17: =((M17/C17)*100) -> 38.095238 | O17: =SUM(D17:K17) -> 18 | P17: =((O17/C17)*100) -> 85.714286
A18: 11R | B18: CG UMMI SAHIRAH | C18: =SUM(D18:L18) -> 18 | D18: ='[8]MASTER '!$BI$36 -> 0 | E18: ='[8]MASTER '!$BI$37 -> 0 | F18: ='[8]MASTER '!$BI$38 -> 0 | G18: ='[8]MASTER '!$BI$39 -> 0 | H18: ='[8]MASTER '!$BI$40 -> 0 | I18: ='[8]MASTER '!$BI$41 -> 2 | J18: ='[8]MASTER '!$BI$42 -> 3 | K18: ='[8]MASTER '!$BI$43 -> 7 | L18: ='[8]MASTER '!$BI$44 -> 6 | M18: =SUM(D18:I18) -> 2 | N18: =((M18/C18)*100) -> 11.111111 | O18: =SUM(D18:K18) -> 12 | P18: =((O18/C18)*100) -> 66.666667
B19: Overall | C19: =SUM(C17:C18) -> 39 | D19: =SUM(D17:D18) -> 0 | E19: =SUM(E17:E18) -> 0 | F19: =SUM(F17:F18) -> 0 | G19: =SUM(G17:G18) -> 3 | H19: =SUM(H17:H18) -> 3 | I19: =SUM(I17:I18) -> 4 | J19: =SUM(J17:J18) -> 6 | ... M19: =SUM(M17:M18) -> 10 | N19: =((M19/C19)*100) -> 25.641026 | O19: =SUM(D19:K19) -> 30 | P19: =((O19/C19)*100) -> 76.923077
A21: ENGLISH LANGUAGE (1120)
D22: Distinction | G22: Credit | J22: Pass | L22: Fail
A23: Class | B23: Taught By | C23: Total | D23: A* | E23: A2 | F23: B3 | G23: B4 | H23: C5 | I23: C6 | J23: D7 | K23: E8 | L23: U | M23: Total 1-6 | N23: % 1-6 | O23: Total 1-8 | P23: % 1-8
A24: 11D | B24: CG ASFARINA | C24: =SUM(D24:L24) -> 17 | D24: ='[1]MASTER '!$T$38 -> 0 | E24: ='[1]MASTER '!$T$39 -> 8 | F24: ='[1]MASTER '!$T$40 -> 8 | G24: ='[1]MASTER '!$T$41 -> 0 | H24: ='[1]MASTER '!$T$42 -> 1 | I24: ='[1]MASTER '!$T$43 -> 0 | J24: ='[1]MASTER '!$T$44 -> 0 | K24: ='[1]MASTER '!$T$45 -> 0 | L24: ='[1]MASTER '!$T$46 -> 0 | M24: =SUM(D24:I24) -> 17 | N24: =((M24/C24)*100) -> 100 | O24: =SUM(D24:K24) -> 17 | P24: =((O24/C24)*100) -> 100
A25: 11I | B25: CG CHANTELLE | C25: =SUM(D25:L25) -> 21 | D25: ='[2]MASTER '!$T$38 -> 0 | E25: ='[2]MASTER '!$T$39 -> 7 | F25: ='[2]MASTER '!$T$40 -> 10 | G25: ='[2]MASTER '!$T$41 -> 4 | H25: ='[2]MASTER '!$T$42 -> 0 | I25: ='[2]MASTER '!$T$43 -> 0 | J25: ='[2]MASTER '!$T$44 -> 0 | K25: ='[2]MASTER '!$T$45 -> 0 | L25: ='[2]MASTER '!$T$46 -> 0 | M25: =SUM(D25:I25) -> 21 | N25: =((M25/C25)*100) -> 100 | O25: =SUM(D25:K25) -> 21 | P25: =((O25/C25)*100) -> 100
A26: 11S | B26: CG HAJAH MARIAH | C26: =SUM(D26:L26) -> 15 | D26: ='[3]MASTER '!$T$38 -> 1 | E26: ='[3]MASTER '!$T$39 -> 2 | F26: ='[3]MASTER '!$T$40 -> 1 | G26: ='[3]MASTER '!$T$41 -> 4 | H26: ='[3]MASTER '!$T$42 -> 1 | I26: ='[3]MASTER '!$T$43 -> 3 | J26: ='[3]MASTER '!$T$44 -> 3 | K26: ='[3]MASTER '!$T$45 -> 0 | L26: ='[3]MASTER '!$T$46 -> 0 | M26: =SUM(D26:I26) -> 12 | N26: =((M26/C26)*100) -> 80 | O26: =SUM(D26:K26) -> 15 | P26: =((O26/C26)*100) -> 100
A27: 11C | B27: CG CHANTELLE | C27: =SUM(D27:L27) -> 24 | D27: ='[4]MASTER '!$T$38 -> 0 | E27: ='[4]MASTER '!$T$39 -> 6 | F27: ='[4]MASTER '!$T$40 -> 5 | G27: ='[4]MASTER '!$T$41 -> 7 | H27: ='[4]MASTER '!$T$42 -> 3 | I27: ='[4]MASTER '!$T$43 -> 2 | J27: ='[4]MASTER '!$T$44 -> 1 | K27: ='[4]MASTER '!$T$45 -> 0 | L27: ='[4]MASTER '!$T$46 -> 0 | M27: =SUM(D27:I27) -> 23 | N27: =((M27/C27)*100) -> 95.833333 | O27: =SUM(D27:K27) -> 24 | P27: =((O27/C27)*100) -> 100
A28: 11O | B28: CG CHANTELLE | C28: =SUM(D28:L28) -> 24 | D28: ='[5]MASTER '!$T$38 -> 0 | E28: ='[5]MASTER '!$T$39 -> 3 | F28: ='[5]MASTER '!$T$40 -> 4 | G28: ='[5]MASTER '!$T$41 -> 11 | H28: ='[5]MASTER '!$T$42 -> 5 | I28: ='[5]MASTER '!$T$43 -> 1 | J28: ='[5]MASTER '!$T$44 -> 0 | K28: ='[5]MASTER '!$T$45 -> 0 | L28: ='[5]MASTER '!$T$46 -> 0 | M28: =SUM(D28:I28) -> 24 | N28: =((M28/C28)*100) -> 100 | O28: =SUM(D28:K28) -> 24 | P28: =((O28/C28)*100) -> 100
A29: 11V | B29: CG CHANTELLE | C29: =SUM(D29:L29) -> 25 | D29: ='[6]MASTER '!$T$38 -> 0 | E29: ='[6]MASTER '!$T$39 -> 6 | F29: ='[6]MASTER '!$T$40 -> 3 | G29: ='[6]MASTER '!$T$41 -> 7 | H29: ='[6]MASTER '!$T$42 -> 4 | I29: ='[6]MASTER '!$T$43 -> 5 | J29: ='[6]MASTER '!$T$44 -> 0 | K29: ='[6]MASTER '!$T$45 -> 0 | L29: ='[6]MASTER '!$T$46 -> 0 | M29: =SUM(D29:I29) -> 25 | N29: =((M29/C29)*100) -> 100 | O29: =SUM(D29:K29) -> 25 | P29: =((O29/C29)*100) -> 100
A30: 11E | B30: CG ASFARINA | C30: =SUM(D30:L30) -> 21 | D30: ='[7]MASTER '!$T$38 -> 0 | E30: ='[7]MASTER '!$T$39 -> 1 | F30: ='[7]MASTER '!$T$40 -> 0 | G30: ='[7]MASTER '!$T$41 -> 2 | H30: ='[7]MASTER '!$T$42 -> 3 | I30: ='[7]MASTER '!$T$43 -> 5 | J30: ='[7]MASTER '!$T$44 -> 2 | K30: ='[7]MASTER '!$T$45 -> 4 | L30: ='[7]MASTER '!$T$46 -> 4 | M30: =SUM(D30:I30) -> 11 | N30: =((M30/C30)*100) -> 52.380952 | O30: =SUM(D30:K30) -> 17 | P30: =((O30/C30)*100) -> 80.952381
A31: 11R | B31: CG ASFARINA | C31: =SUM(D31:L31) -> 18 | D31: ='[8]MASTER '!$T$36 -> 0 | E31: ='[8]MASTER '!$T$37 -> 0 | F31: ='[8]MASTER '!$T$38 -> 0 | G31: ='[8]MASTER '!$T$39 -> 1 | H31: ='[8]MASTER '!$T$40 -> 0 | I31: ='[8]MASTER '!$T$41 -> 2 | J31: ='[8]MASTER '!$T$42 -> 4 | K31: ='[8]MASTER '!$T$43 -> 4 | L31: ='[8]MASTER '!$T$44 -> 7 | M31: =SUM(D31:I31) -> 3 | N31: =((M31/C31)*100) -> 16.666667 | O31: =SUM(D31:K31) -> 11 | P31: =((O31/C31)*100) -> 61.111111
B32: Overall | C32: =SUM(C24:C31) -> 165 | D32: =SUM(D24:D31) -> 1 | E32: =SUM(E24:E31) -> 33 | F32: =SUM(F24:F31) -> 31 | G32: =SUM(G24:G31) -> 36 | H32: =SUM(H24:H31) -> 17 | I32: =SUM(I24:I31) -> 18 | J32: =SUM(J24:J31) -> 10 | ... M32: =SUM(M24:M31) -> 136 | N32: =((M32/C32)*100) -> 82.424242 | O32: =SUM(O24:O31) -> 154 | P32: =((O32/C32)*100) -> 93.333333
A34: IG ICT
D35: GRADE
A36: Class | B36: Taught By | C36: Total | D36: A* | E36: A | F36: B | G36: C | H36: D | I36: E | J36: F | K36: G | L36: U | M36: Total C | N36: % C | O36: Total C - G | P36: % C - G
C37: =SUM(D37:L37) -> 0 | M37: =SUM(D37:G37) -> 0 | N37: =((M37/C37)*100) -> #DIV/0! | O37: =SUM(D37:K37) -> 0 | P37: =((O37/C37)*100) -> #DIV/0!
C38: =SUM(D38:L38) -> 0 | M38: =SUM(D38:G38) -> 0 | N38: =((M38/C38)*100) -> #DIV/0! | O38: =SUM(D38:K38) -> 0 | P38: =((O38/C38)*100) -> #DIV/0!
B40: Overall | C40: =SUM(C37:C39) -> 0 | D40: =SUM(D37:D39) -> 0 | E40: =SUM(E37:E39) -> 0 | F40: =SUM(F37:F39) -> 0 | G40: =SUM(G37:G39) -> 0 | H40: =SUM(H37:H39) -> 0 | I40: =SUM(I39:I39) -> 0 | J40: =SUM(J39:J39) -> 0 | K40: =SUM(K39:K39) -> 0 | L40: =SUM(L39:L39) -> 0 | M40: =SUM(M34:M39) -> 0 | N40: =((M40/C40)*100) -> #DIV/0! | O40: =SUM(O34:O39) -> 0 | P40: =((O40/C40)*100) -> #DIV/0!
A41: MATHEMATICS D (4024)
D42: Distinction | F42: Credit | J42: Pass | L42: Fail
A43: Class | B43: Taught By | C43: Total | D43: A* | E43: A2 | F43: B3 | G43: B4 | H43: C5 | I43: C6 | J43: D7 | K43: E8 | L43: U | M43: Total 1-6 | N43: % 1-6 | O43: Total 1-8 | P43: % 1-8
A44: 11D | B44: CG ANI AFIFAH | C44: =SUM(D44:L44) -> 17 | D44: ='[1]MASTER '!$AE$38 -> 2 | E44: ='[1]MASTER '!$AE$39 -> 3 | F44: ='[1]MASTER '!$AE$40 -> 4 | G44: ='[1]MASTER '!$AE$41 -> 0 | H44: ='[1]MASTER '!$AE$42 -> 3 | I44: ='[1]MASTER '!$AE$43 -> 3 | J44: ='[1]MASTER '!$AE$44 -> 2 | K44: ='[1]MASTER '!$AE$45 -> 0 | L44: ='[1]MASTER '!$AE$46 -> 0 | M44: =SUM(D44:I44) -> 15 | N44: =((M44/C44)*100) -> 88.235294 | O44: =SUM(D44:K44) -> 17 | P44: =((O44/C44)*100) -> 100
...

Sheet OVERALL PERFORMANCES
A2: Subjects | B2: % 1-6 | C2: % 1-8
A3: B.Melayu | B3: ='ANALYSIS BY SUBJECTS'!N201 -> 80 | C3: ='ANALYSIS BY SUBJECTS'!P201 -> 96.363636
A4: English Language | B4: ='ANALYSIS BY SUBJECTS'!N202 -> 82.424242 | C4: ='ANALYSIS BY SUBJECTS'!P202 -> 93.333333
A5: Mathematics D | B5: ='ANALYSIS BY SUBJECTS'!N203 -> 27.777778 | C5: ='ANALYSIS BY SUBJECTS'!P203 -> 50.793651
A6: ='ANALYSIS BY SUBJECTS'!A204 -> Mathematics IGCSE (Core) | B6: ='ANALYSIS BY SUBJECTS'!N204 -> 2.5641026 | C6: ='ANALYSIS BY SUBJECTS'!P204 -> 87.179487
A7: Additional Maths | B7: ='ANALYSIS BY SUBJECTS'!N205 -> 5.8823529 | C7: ='ANALYSIS BY SUBJECTS'!P205 -> 52.941176
A8: Physics | B8: ='ANALYSIS BY SUBJECTS'!N206 -> 61.111111 | C8: ='ANALYSIS BY SUBJECTS'!P206 -> 93.055556
A9: Chemistry | B9: ='ANALYSIS BY SUBJECTS'!N207 -> 37.179487 | C9: ='ANALYSIS BY SUBJECTS'!P207 -> 73.076923
A10: Biology | B10: ='ANALYSIS BY SUBJECTS'!N208 -> 53.246753 | C10: ='ANALYSIS BY SUBJECTS'!P208 -> 93.506494
A11: Combined Science | B11: ='ANALYSIS BY SUBJECTS'!N209 -> 5.1282051 | C11: ='ANALYSIS BY SUBJECTS'!P209 -> 41.025641
A12: Geography | B12: ='ANALYSIS BY SUBJECTS'!N210 -> 18.75 | C12: ='ANALYSIS BY SUBJECTS'!P210 -> 70.3125
A13: IRK | B13: ='ANALYSIS BY SUBJECTS'!N211 -> 58.181818 | C13: ='ANALYSIS BY SUBJECTS'!P211 -> 85.454545
A14: History | B14: ='ANALYSIS BY SUBJECTS'!N212 -> 21.73913 | C14: ='ANALYSIS BY SUBJECTS'!P212 -> 69.565217
A15: Commerce | B15: ='ANALYSIS BY SUBJECTS'!N213 -> 63.636364 | C15: ='ANALYSIS BY SUBJECTS'!P213 -> 90.909091
A16: Economics | B16: ='ANALYSIS BY SUBJECTS'!N214 -> 79.310345 | C16: ='ANALYSIS BY SUBJECTS'!P214 -> 100
A17: Accounting | B17: ='ANALYSIS BY SUBJECTS'!N215 -> 2.739726 | C17: ='ANALYSIS BY SUBJECTS'!P215 -> 41.09589
A18: Art & Design | B18: ='ANALYSIS BY SUBJECTS'!N216 -> 69 | C18: ='ANALYSIS BY SUBJECTS'!P216 -> 95
... A22: IG ICT | B22: ='ANALYSIS BY SUBJECTS'!N220 -> 33.333333 | C22: ='ANALYSIS BY SUBJECTS'!P220 -> 55.555556
A23: Computer Science | B23: 15 | C23: 45

Sheet CLASS AVERAGE
A2: Class + No of stdn | B2: Class Avg
A3: 10Sci2 (26)
A4: 10Sci3 (25)
A5: 10A (31)
A6: 10M (30)
A7: 10B (31)
A8: 10E (32)
A9: 10R (31)

Sheet By Class
A2: Menengah 4A
D3: Distinction | F3: Credit | J3: Pass | L3: Fail
A4: Subjects | B4: Taught By | C4: Total | D4: 1 | E4: 2 | F4: 3 | G4: 4 | H4: 5 | I4: 6 | J4: 7 | K4: 8 | L4: 9 | M4: Total 1-6 | N4: % 1-6 | O4: Total 1-8 | P4: % 1-8
A5: B.Melayu | N5: =((M5/C5)*100) -> #DIV/0! | O5: =SUM(D5:K5) -> 0 | P5: =((O5/C5)*100) -> #DIV/0!
A6: English | N6: =((M6/C6)*100) -> #DIV/0! | O6: =SUM(D6:K6) -> 0 | P6: =((O6/C6)*100) -> #DIV/0!
A7: Maths | N7: =((M7/C7)*100) -> #DIV/0! | O7: =SUM(D7:K7) -> 0 | P7: =((O7/C7)*100) -> #DIV/0!
A8: Add Maths | N8: =((M8/C8)*100) -> #DIV/0! | O8: =SUM(D8:K8) -> 0 | P8: =((O8/C8)*100) -> #DIV/0!
A9: Physics | N9: =((M9/C9)*100) -> #DIV/0! | O9: =SUM(D9:K9) -> 0 | P9: =((O9/C9)*100) -> #DIV/0!
A10: Chemistry | N10: =((M10/C10)*100) -> #DIV/0! | O10: =SUM(D10:K10) -> 0 | P10: =((O10/C10)*100) -> #DIV/0!
A11: Biology | N11: =((M11/C11)*100) -> #DIV/0! | O11: =SUM(D11:K11) -> 0 | P11: =((O11/C11)*100) -> #DIV/0!
A12: Geography | N12: =((M12/C12)*100) -> #DIV/0! | O12: =SUM(D12:K12) -> 0 | P12: =((O12/C12)*100) -> #DIV/0!
A13: Computer | N13: =((M13/C13)*100) -> #DIV/0! | O13: =SUM(D13:K13) -> 0 | P13: =((O13/C13)*100) -> #DIV/0!
N14: =AVERAGE(N5:N13) -> #DIV/0! | P14: =AVERAGE(P5:P13) -> #DIV/0!
A16: Menengah 4B
D17: Distinction | F17: Credit | J17: Pass | L17: Fail
A18: Subjects | B18: Taught By | C18: Total | D18: 1 | E18: 2 | F18: 3 | G18: 4 | H18: 5 | I18: 6 | J18: 7 | K18: 8 | L18: 9 | M18: Total 1-6 | N18: % 1-6 | O18: Total 1-8 | P18: % 1-8
A19: B.Melayu | N19: =((M19/C19)*100) -> #DIV/0! | O19: =SUM(D19:K19) -> 0 | P19: =((O19/C19)*100) -> #DIV/0!
A20: English | N20: =((M20/C20)*100) -> #DIV/0! | O20: =SUM(D20:K20) -> 0 | P20: =((O20/C20)*100) -> #DIV/0!
A21: Maths | N21: =((M21/C21)*100) -> #DIV/0! | O21: =SUM(D21:K21) -> 0 | P21: =((O21/C21)*100) -> #DIV/0!
A22: Physics | N22: =((M22/C22)*100) -> #DIV/0! | O22: 10 | P22: =((O22/C22)*100) -> #DIV/0!
A23: Chemistry | N23: =((M23/C23)*100) -> #DIV/0! | O23: 10 | P23: =((O23/C23)*100) -> #DIV/0!
A24: Biology | N24: =((M24/C24)*100) -> #DIV/0! | O24: 19 | P24: =((O24/C24)*100) -> #DIV/0!
A25: Geography | N25: =((M25/C25)*100) -> #DIV/0! | O25: 19 | P25: =((O25/C25)*100) -> #DIV/0!
A26: Economics | N26: =((M26/C26)*100) -> #DIV/0! | O26: 3 | P26: =((O26/C26)*100) -> #DIV/0!
A27: Computer | N27: =((M27/C27)*100) -> #DIV/0! | O27: 2 | P27: =((O27/C27)*100) -> #DIV/0!
A28: POA | N28: =((M28/C28)*100) -> #DIV/0! | O28: 12 | P28: =((O28/C28)*100) -> #DIV/0!
N29: =AVERAGE(N19:N28) -> #DIV/0! | P29: =AVERAGE(P19:P28) -> #DIV/0!
A31: Menengah 4C
D32: Distinction | F32: Credit | J32: Pass | L32: Fail
A33: Subjects | B33: Taught By | C33: Total | D33: 1 | E33: 2 | F33: 3 | G33: 4 | H33: 5 | I33: 6 | J33: 7 | K33: 8 | L33: 9 | M33: Total 1-6 | N33: % 1-6 | O33: Total 1-8 | P33: % 1-8
A34: B.Melayu | N34: =((M34/C34)*100) -> #DIV/0! | O34: 18 | P34: =((O34/C34)*100) -> #DIV/0!
A35: English | N35: =((M35/C35)*100) -> #DIV/0! | O35: 15 | P35: =((O35/C35)*100) -> #DIV/0!
A36: Maths | N36: =((M36/C36)*100) -> #DIV/0! | O36: 9 | P36: =((O36/C36)*100) -> #DIV/0!
A37: Comb Sc | N37: =((M37/C37)*100) -> #DIV/0! | O37: 6 | P37: =((O37/C37)*100) -> #DIV/0!
A38: Geography | N38: =((M38/C38)*100) -> #DIV/0! | O38: 7 | P38: =((O38/C38)*100) -> #DIV/0!
A39: History | N39: =((M39/C39)*100) -> #DIV/0! | O39: 14 | P39: =((O39/C39)*100) -> #DIV/0!
A40: IRK | N40: =((M40/C40)*100) -> #DIV/0! | O40: 16 | P40: =((O40/C40)*100) -> #DIV/0!
A41: Commerce | N41: =((M41/C41)*100) -> #DIV/0! | O41: 14 | P41: =((O41/C41)*100) -> #DIV/0!
A42: Agr Sc | N42: =((M42/C42)*100) -> #DIV/0! | O42: 2 | P42: =((O42/C42)*100) -> #DIV/0!
N43: =AVERAGE(N34:N42) -> #DIV/0! | P43: =AVERAGE(P34:P42) -> #DIV/0!
...

Sheet IGCSE SUBJECTS
A1: Y10 MID YEAR EXAMINATION 2016
A2: SEKOLAH MENENGAH PG ANAK PUTERI HAJAH MASNA
A4: IGCSE SUBJECTS
C6: NUMBER OF CANDIDATES OBTAINING | O6: PERCENTAGE FOR GRADES
C7: NO. OF CANDIDATE | E7: Distinction | G7: Credit | I7: Pass | M7: Fail | N7: ABSENT | O7: Distinction | P7: Credit | Q7: Pass | R7: Fail | S7: Credit | T7: Pass
A8: Subject | C8: REGISTERED | D8: SAT | E8: A* | F8: A | G8: B | H8: C | I8: D | J8: E | K8: F | L8: G | M8: U | N8: X | O8: A*- A | P8: B-C | Q8: D-G | R8: U | S8: % A* - C | T8: % A* - G
A9: IGCSE English E2L (Core) | C9: ='ANALYSIS BY SUBJECTS'!$C$40 -> 0 | D9: ='ANALYSIS BY SUBJECTS'!$C$40 -> 0 | H9: ='ANALYSIS BY SUBJECTS'!D40 -> 0 | I9: ='ANALYSIS BY SUBJECTS'!E40 -> 0 | J9: ='ANALYSIS BY SUBJECTS'!F40 -> 0 | K9: ='ANALYSIS BY SUBJECTS'!G40 -> 0 | L9: ='ANALYSIS BY SUBJECTS'!H40 -> 0 | M9: ='ANALYSIS BY SUBJECTS'!I40 -> 0 | O9: =((E9+F9)/C9) -> #DIV/0! | P9: =(SUM(G9:H9)/C9) -> #DIV/0! | Q9: =(SUM(I9:L9)/C9) -> #DIV/0! | R9: =M9/C9 -> #DIV/0! | S9: =(SUM(E9:H9)/C9) -> #DIV/0! | T9: =(SUM(E9:L9)/D9) -> #DIV/0!
A10: IGCSE Mathematics (Core) | C10: ='ANALYSIS BY SUBJECTS'!$C$57 -> 39 | D10: ='ANALYSIS BY SUBJECTS'!$C$57 -> 39 | H10: 1 | I10: ='ANALYSIS BY SUBJECTS'!#REF! -> #REF! | J10: 2 | K10: 15 | L10: 38 | M10: 27 | O10: =((E10+F10)/C10) -> 0 | P10: =(SUM(G10:H10)/C10) -> 0.025641026 | Q10: =(SUM(I10:L10)/C10) -> #REF! | R10: =M10/C10 -> 0.69230769 | S10: =(SUM(E10:H10)/C10) -> 0.025641026 | T10: =(SUM(E10:L10)/D10) -> #REF!
A11: IGCSE PE (Extended) | C11: 21 | D11: 21 | E11: ='ANALYSIS BY SUBJECTS'!#REF! -> #REF! | F11: ='ANALYSIS BY SUBJECTS'!#REF! -> #REF! | G11: 2 | H11: 7 | I11: 4 | J11: 1 | K11: 0 | L11: 0 | M11: ='ANALYSIS BY SUBJECTS'!#REF! -> #REF! | O11: =((E11+F11)/C11) -> #REF! | P11: =(SUM(G11:H11)/C11) -> 0.42857143 | Q11: =(SUM(I11:L11)/C11) -> 0.23809524 | R11: =M11/C11 -> #REF! | S11: =(SUM(E11:H11)/C11) -> #REF! | T11: =(SUM(E11:L11)/D11) -> #REF!
A12: IGCSE ICT (Extended) | O12: =((E12+F12)/C12) -> #DIV/0! | P12: =(SUM(G12:H12)/C12) -> #DIV/0! | Q12: =(SUM(I12:L12)/C12) -> #DIV/0! | R12: =M12/C12 -> #DIV/0! | S12: =(SUM(E12:H12)/C12) -> #DIV/0! | T12: =(SUM(E12:L12)/D12) -> #DIV/0!

Sheet OVERALL ANALYSIS
A1: SEKOLAH MENENGAH PG ANAK PUTERI HAJAH MASNA
A2: OVERALL RESULTS - YEAR 11 QUALIFYING EXAMINATION 2026
C4: NUMBER OF CANDIDATES OBTAINING | O4: PERCENTAGE FOR GRADES | U4: REMARKS
C5: NO. OF CANDIDATES | E5: Distinction | G5: Credit | K5: Pass | M5: Fail | N5: ABSENT | O5: Distinction | P5: Credit | Q5: Pass | R5: Fail | S5: Credit | T5: Pass
A6: Subject | C6: REGISTERED | D6: SAT | E6: A*1 | F6: A2 | G6: B3 | H6: B4 | I6: C5 | J6: C6 | K6: D7 | L6: E8 | M6: U | N6: X | O6: 1-2 | P6: 3-6 | Q6: 7-8 | R6: 9 | S6: % 1-6 | T6: % 1-8
A7: ='ANALYSIS BY SUBJECTS'!A201 -> B.Melayu | C7: ='ANALYSIS BY SUBJECTS'!C201 -> 165 | D7: ='ANALYSIS BY SUBJECTS'!C201 -> 165 | E7: ='ANALYSIS BY SUBJECTS'!D201 -> 0 | F7: ='ANALYSIS BY SUBJECTS'!E201 -> 25 | G7: ='ANALYSIS BY SUBJECTS'!F201 -> 35 | H7: ='ANALYSIS BY SUBJECTS'!G201 -> 26 | I7: ='ANALYSIS BY SUBJECTS'!H201 -> 25 | J7: ='ANALYSIS BY SUBJECTS'!I201 -> 21 | K7: ='ANALYSIS BY SUBJECTS'!J201 -> 16 | ... M7: ='ANALYSIS BY SUBJECTS'!L201 -> 6 | N7: 0 | O7: =((E7+F7)/C7) -> 0.15151515 | P7: =(SUM(G7:J7)/C7) -> 0.64848485 | Q7: =(SUM(K7:L7)/C7) -> 0.16363636 | R7: =M7/C7 -> 0.036363636 | S7: ='OVERALL PERFORMANCES'!B3 -> 80 | T7: ='OVERALL PERFORMANCES'!C3 -> 96.363636
A8: ='ANALYSIS BY SUBJECTS'!A202 -> English Language | C8: ='ANALYSIS BY SUBJECTS'!C202 -> 165 | D8: ='ANALYSIS BY SUBJECTS'!C202 -> 165 | E8: ='ANALYSIS BY SUBJECTS'!D202 -> 1 | F8: ='ANALYSIS BY SUBJECTS'!E202 -> 33 | G8: ='ANALYSIS BY SUBJECTS'!F202 -> 31 | H8: ='ANALYSIS BY SUBJECTS'!G202 -> 36 | I8: ='ANALYSIS BY SUBJECTS'!H202 -> 17 | J8: ='ANALYSIS BY SUBJECTS'!I202 -> 18 | K8: ='ANALYSIS BY SUBJECTS'!J202 -> 10 | ... M8: ='ANALYSIS BY SUBJECTS'!L202 -> 11 | N8: 0 | O8: =((E8+F8)/C8) -> 0.20606061 | P8: =(SUM(G8:J8)/C8) -> 0.61818182 | Q8: =(SUM(K8:L8)/C8) -> 0.10909091 | R8: =M8/C8 -> 0.066666667 | S8: ='OVERALL PERFORMANCES'!B4 -> 82.424242 | T8: ='OVERALL PERFORMANCES'!C4 -> 93.333333
A9: ='ANALYSIS BY SUBJECTS'!A203 -> Mathematics D | C9: ='ANALYSIS BY SUBJECTS'!C203 -> 126 | D9: ='ANALYSIS BY SUBJECTS'!C203 -> 126 | E9: ='ANALYSIS BY SUBJECTS'!D203 -> 2 | F9: ='ANALYSIS BY SUBJECTS'!E203 -> 7 | G9: ='ANALYSIS BY SUBJECTS'!F203 -> 7 | H9: ='ANALYSIS BY SUBJECTS'!G203 -> 2 | I9: ='ANALYSIS BY SUBJECTS'!H203 -> 7 | J9: ='ANALYSIS BY SUBJECTS'!I203 -> 10 | K9: ='ANALYSIS BY SUBJECTS'!J203 -> 10 | ... M9: ='ANALYSIS BY SUBJECTS'!L203 -> 62 | N9: 0 | O9: =((E9+F9)/C9) -> 0.071428571 | P9: =(SUM(G9:J9)/C9) -> 0.20634921 | Q9: =(SUM(K9:L9)/C9) -> 0.23015873 | R9: =M9/C9 -> 0.49206349 | S9: ='OVERALL PERFORMANCES'!B5 -> 27.777778 | T9: ='OVERALL PERFORMANCES'!C5 -> 50.793651
A10: ='ANALYSIS BY SUBJECTS'!A204 -> Mathematics IGCSE (Core) | C10: ='ANALYSIS BY SUBJECTS'!C204 -> 39 | D10: ='ANALYSIS BY SUBJECTS'!C204 -> 39 | E10: ='ANALYSIS BY SUBJECTS'!D204 -> 1 | F10: ='ANALYSIS BY SUBJECTS'!E204 -> 4 | G10: ='ANALYSIS BY SUBJECTS'!F204 -> 9 | H10: ='ANALYSIS BY SUBJECTS'!G204 -> 12 | I10: ='ANALYSIS BY SUBJECTS'!H204 -> 8 | J10: ='ANALYSIS BY SUBJECTS'!I204 -> 5 | K10: ='ANALYSIS BY SUBJECTS'!J204 -> 0 | ... M10: ='ANALYSIS BY SUBJECTS'!L204 -> 0 | N10: 0 | O10: =((E10+F10)/C10) -> 0.12820513 | P10: =(SUM(G10:J10)/C10) -> 0.87179487 | Q10: =(SUM(K10:L10)/C10) -> 0 | R10: =M10/C10 -> 0 | S10: ='OVERALL PERFORMANCES'!B6 -> 2.5641026 | T10: ='OVERALL PERFORMANCES'!C6 -> 87.179487
A11: ='ANALYSIS BY SUBJECTS'!A205 -> Additional Maths | C11: ='ANALYSIS BY SUBJECTS'!C205 -> 17 | D11: ='ANALYSIS BY SUBJECTS'!C205 -> 17 | E11: ='ANALYSIS BY SUBJECTS'!D205 -> 0 | F11: ='ANALYSIS BY SUBJECTS'!E205 -> 0 | G11: ='ANALYSIS BY SUBJECTS'!F205 -> 0 | H11: ='ANALYSIS BY SUBJECTS'!G205 -> 0 | I11: ='ANALYSIS BY SUBJECTS'!H205 -> 1 | J11: ='ANALYSIS BY SUBJECTS'!I205 -> 0 | K11: ='ANALYSIS BY SUBJECTS'!J205 -> 6 | ... M11: ='ANALYSIS BY SUBJECTS'!L205 -> 8 | N11: 0 | O11: =((E11+F11)/C11) -> 0 | P11: =(SUM(G11:J11)/C11) -> 0.058823529 | Q11: =(SUM(K11:L11)/C11) -> 0.47058824 | R11: =M11/C11 -> 0.47058824 | S11: ='OVERALL PERFORMANCES'!B7 -> 5.8823529 | T11: ='OVERALL PERFORMANCES'!C7 -> 52.941176
A12: ='ANALYSIS BY SUBJECTS'!A206 -> Physics | C12: ='ANALYSIS BY SUBJECTS'!C206 -> 72 | D12: ='ANALYSIS BY SUBJECTS'!C206 -> 72 | E12: ='ANALYSIS BY SUBJECTS'!D206 -> 1 | F12: ='ANALYSIS BY SUBJECTS'!E206 -> 8 | G12: ='ANALYSIS BY SUBJECTS'!F206 -> 8 | H12: ='ANALYSIS BY SUBJECTS'!G206 -> 6 | I12: ='ANALYSIS BY SUBJECTS'!H206 -> 11 | J12: ='ANALYSIS BY SUBJECTS'!I206 -> 10 | K12: ='ANALYSIS BY SUBJECTS'!J206 -> 15 | ... M12: ='ANALYSIS BY SUBJECTS'!L206 -> 5 | N12: 0 | O12: =((E12+F12)/C12) -> 0.125 | P12: =(SUM(G12:J12)/C12) -> 0.48611111 | Q12: =(SUM(K12:L12)/C12) -> 0.31944444 | R12: =M12/C12 -> 0.069444444 | S12: ='OVERALL PERFORMANCES'!B8 -> 61.111111 | T12: ='OVERALL PERFORMANCES'!C8 -> 93.055556
A13: ='ANALYSIS BY SUBJECTS'!A207 -> Chemistry | C13: ='ANALYSIS BY SUBJECTS'!C207 -> 78 | D13: ='ANALYSIS BY SUBJECTS'!C207 -> 78 | E13: ='ANALYSIS BY SUBJECTS'!D207 -> 0 | F13: ='ANALYSIS BY SUBJECTS'!E207 -> 4 | G13: ='ANALYSIS BY SUBJECTS'!F207 -> 4 | H13: ='ANALYSIS BY SUBJECTS'!G207 -> 4 | I13: ='ANALYSIS BY SUBJECTS'!H207 -> 5 | J13: ='ANALYSIS BY SUBJECTS'!I207 -> 12 | K13: ='ANALYSIS BY SUBJECTS'!J207 -> 17 | ... M13: ='ANALYSIS BY SUBJECTS'!L207 -> 21 | N13: 0 | O13: =((E13+F13)/C13) -> 0.051282051 | P13: =(SUM(G13:J13)/C13) -> 0.32051282 | Q13: =(SUM(K13:L13)/C13) -> 0.35897436 | R13: =M13/C13 -> 0.26923077 | S13: ='OVERALL PERFORMANCES'!B9 -> 37.179487 | T13: ='OVERALL PERFORMANCES'!C9 -> 73.076923
A14: ='ANALYSIS BY SUBJECTS'!A208 -> Biology | C14: ='ANALYSIS BY SUBJECTS'!C208 -> 77 | D14: ='ANALYSIS BY SUBJECTS'!C208 -> 77 | E14: ='ANALYSIS BY SUBJECTS'!D208 -> 0 | F14: ='ANALYSIS BY SUBJECTS'!E208 -> 1 | G14: ='ANALYSIS BY SUBJECTS'!F208 -> 7 | H14: ='ANALYSIS BY SUBJECTS'!G208 -> 9 | I14: ='ANALYSIS BY SUBJECTS'!H208 -> 12 | J14: ='ANALYSIS BY SUBJECTS'!I208 -> 12 | K14: ='ANALYSIS BY SUBJECTS'!J208 -> 17 | ... M14: ='ANALYSIS BY SUBJECTS'!L208 -> 5 | N14: 0 | O14: =((E14+F14)/C14) -> 0.012987013 | P14: =(SUM(G14:J14)/C14) -> 0.51948052 | Q14: =(SUM(K14:L14)/C14) -> 0.4025974 | R14: =M14/C14 -> 0.064935065 | S14: ='OVERALL PERFORMANCES'!B10 -> 53.246753 | T14: ='OVERALL PERFORMANCES'!C10 -> 93.506494
A15: ='ANALYSIS BY SUBJECTS'!A209 -> Combined Science | C15: ='ANALYSIS BY SUBJECTS'!C209 -> 39 | D15: ='ANALYSIS BY SUBJECTS'!C209 -> 39 | E15: ='ANALYSIS BY SUBJECTS'!D209 -> 0 | F15: ='ANALYSIS BY SUBJECTS'!E209 -> 0 | G15: ='ANALYSIS BY SUBJECTS'!F209 -> 0 | H15: ='ANALYSIS BY SUBJECTS'!G209 -> 0 | I15: ='ANALYSIS BY SUBJECTS'!H209 -> 1 | J15: ='ANALYSIS BY SUBJECTS'!I209 -> 1 | K15: ='ANALYSIS BY SUBJECTS'!J209 -> 3 | ... M15: ='ANALYSIS BY SUBJECTS'!L209 -> 23 | N15: 0 | O15: =((E15+F15)/C15) -> 0 | P15: =(SUM(G15:J15)/C15) -> 0.051282051 | Q15: =(SUM(K15:L15)/C15) -> 0.35897436 | R15: =M15/C15 -> 0.58974359 | S15: ='OVERALL PERFORMANCES'!B11 -> 5.1282051 | T15: ='OVERALL PERFORMANCES'!C11 -> 41.025641
A16: ='ANALYSIS BY SUBJECTS'!A210 -> Geography | C16: ='ANALYSIS BY SUBJECTS'!C210 -> 64 | D16: ='ANALYSIS BY SUBJECTS'!C210 -> 64 | E16: ='ANALYSIS BY SUBJECTS'!D210 -> 0 | F16: ='ANALYSIS BY SUBJECTS'!E210 -> 0 | G16: ='ANALYSIS BY SUBJECTS'!F210 -> 4 | H16: ='ANALYSIS BY SUBJECTS'!G210 -> 2 | I16: ='ANALYSIS BY SUBJECTS'!H210 -> 1 | J16: ='ANALYSIS BY SUBJECTS'!I210 -> 5 | K16: ='ANALYSIS BY SUBJECTS'!J210 -> 13 | ... M16: ='ANALYSIS BY SUBJECTS'!L210 -> 19 | N16: 0 | O16: =((E16+F16)/C16) -> 0 | P16: =(SUM(G16:J16)/C16) -> 0.1875 | Q16: =(SUM(K16:L16)/C16) -> 0.515625 | R16: =M16/C16 -> 0.296875 | S16: ='OVERALL PERFORMANCES'!B12 -> 18.75 | T16: ='OVERALL PERFORMANCES'!C12 -> 70.3125
A17: ='ANALYSIS BY SUBJECTS'!A211 -> IRK | C17: ='ANALYSIS BY SUBJECTS'!C211 -> 165 | D17: ='ANALYSIS BY SUBJECTS'!C211 -> 165 | E17: ='ANALYSIS BY SUBJECTS'!D211 -> 13 | F17: ='ANALYSIS BY SUBJECTS'!E211 -> 19 | G17: ='ANALYSIS BY SUBJECTS'!F211 -> 15 | H17: ='ANALYSIS BY SUBJECTS'!G211 -> 17 | I17: ='ANALYSIS BY SUBJECTS'!H211 -> 17 | J17: ='ANALYSIS BY SUBJECTS'!I211 -> 15 | K17: ='ANALYSIS BY SUBJECTS'!J211 -> 20 | ... M17: ='ANALYSIS BY SUBJECTS'!L211 -> 24 | N17: 0 | O17: =((E17+F17)/C17) -> 0.19393939 | P17: =(SUM(G17:J17)/C17) -> 0.38787879 | Q17: =(SUM(K17:L17)/C17) -> 0.27272727 | R17: =M17/C17 -> 0.14545455 | S17: ='OVERALL PERFORMANCES'!B13 -> 58.181818 | T17: ='OVERALL PERFORMANCES'!C13 -> 85.454545
A18: ='ANALYSIS BY SUBJECTS'!A212 -> History | C18: ='ANALYSIS BY SUBJECTS'!C212 -> 23 | D18: ='ANALYSIS BY SUBJECTS'!C212 -> 23 | E18: ='ANALYSIS BY SUBJECTS'!D212 -> 0 | F18: ='ANALYSIS BY SUBJECTS'!E212 -> 0 | G18: ='ANALYSIS BY SUBJECTS'!F212 -> 1 | H18: ='ANALYSIS BY SUBJECTS'!G212 -> 1 | I18: ='ANALYSIS BY SUBJECTS'!H212 -> 2 | J18: ='ANALYSIS BY SUBJECTS'!I212 -> 1 | K18: ='ANALYSIS BY SUBJECTS'!J212 -> 4 | ... M18: ='ANALYSIS BY SUBJECTS'!L212 -> 7 | N18: 0 | O18: =((E18+F18)/C18) -> 0 | P18: =(SUM(G18:J18)/C18) -> 0.2173913 | Q18: =(SUM(K18:L18)/C18) -> 0.47826087 | R18: =M18/C18 -> 0.30434783 | S18: ='OVERALL PERFORMANCES'!B14 -> 21.73913 | T18: ='OVERALL PERFORMANCES'!C14 -> 69.565217
... A25: ='ANALYSIS BY SUBJECTS'!A219 -> Sastera | C25: ='ANALYSIS BY SUBJECTS'!C219 -> 39 | D25: ='ANALYSIS BY SUBJECTS'!C219 -> 39 | E25: ='ANALYSIS BY SUBJECTS'!D219 -> 0 | F25: ='ANALYSIS BY SUBJECTS'!E219 -> 0 | G25: ='ANALYSIS BY SUBJECTS'!F219 -> 0 | H25: ='ANALYSIS BY SUBJECTS'!G219 -> 3 | I25: ='ANALYSIS BY SUBJECTS'!H219 -> 3 | J25: ='ANALYSIS BY SUBJECTS'!I219 -> 4 | K25: ='ANALYSIS BY SUBJECTS'!J219 -> 6 | ... M25: ='ANALYSIS BY SUBJECTS'!L219 -> 9 | N25: 0 | O25: =((E25+F25)/C25) -> 0 | P25: =(SUM(G25:J25)/C25) -> 0.25641026 | Q25: =(SUM(K25:L25)/C25) -> 0.51282051 | R25: =M25/C25 -> 0.23076923 | S25: ='OVERALL PERFORMANCES'!B21 -> 25.641026 | T25: ='OVERALL PERFORMANCES'!C21 -> 76.923077
A26: IG ICT | C26: ='ANALYSIS BY SUBJECTS'!C220 -> 9 | D26: ='ANALYSIS BY SUBJECTS'!C220 -> 9 | E26: ='ANALYSIS BY SUBJECTS'!D220 -> 0 | F26: ='ANALYSIS BY SUBJECTS'!E220 -> 0 | G26: ='ANALYSIS BY SUBJECTS'!F220 -> 0 | H26: ='ANALYSIS BY SUBJECTS'!G220 -> 1 | I26: ='ANALYSIS BY SUBJECTS'!H220 -> 0 | J26: ='ANALYSIS BY SUBJECTS'!I220 -> 2 | K26: ='ANALYSIS BY SUBJECTS'!J220 -> 2 | ... M26: ='ANALYSIS BY SUBJECTS'!L220 -> 4 | N26: 0 | O26: =((E26+F26)/C26) -> 0 | P26: =(SUM(G26:J26)/C26) -> 0.33333333 | Q26: =(SUM(K26:L26)/C26) -> 0.22222222 | R26: =M26/C26 -> 0.44444444 | S26: ='OVERALL PERFORMANCES'!B22 -> 33.333333 | T26: ='OVERALL PERFORMANCES'!C22 -> 55.555556
A27: ='ANALYSIS BY SUBJECTS'!A221 -> Computer Science | C27: ='ANALYSIS BY SUBJECTS'!C221 -> 20 | D27: ='ANALYSIS BY SUBJECTS'!C221 -> 20 | E27: ='ANALYSIS BY SUBJECTS'!D221 -> 0 | F27: ='ANALYSIS BY SUBJECTS'!E221 -> 0 | G27: ='ANALYSIS BY SUBJECTS'!F221 -> 0 | H27: ='ANALYSIS BY SUBJECTS'!G221 -> 0 | I27: ='ANALYSIS BY SUBJECTS'!H221 -> 1 | J27: ='ANALYSIS BY SUBJECTS'!I221 -> 2 | K27: ='ANALYSIS BY SUBJECTS'!J221 -> 2 | ... M27: ='ANALYSIS BY SUBJECTS'!L221 -> 11 | N27: 0 | O27: =((E27+F27)/C27) -> 0 | P27: =(SUM(G27:J27)/C27) -> 0.15 | Q27: =(SUM(K27:L27)/C27) -> 0.3 | R27: =M27/C27 -> 0.55 | S27: ='OVERALL PERFORMANCES'!B23 -> 15 | T27: ='OVERALL PERFORMANCES'!C23 -> 45
C29: NUMBER OF CANDIDATES OBTAINING | O29: PERCENTAGE FOR GRADES | U29: REMARKS
C30: NO. OF CANDIDATE | E30: Distinction | G30: Credit | I30: Pass | M30: Fail | N30: ABSENT | O30: Distinction | P30: Credit | Q30: Pass | R30: Fail | S30: Credit | T30: Pass
A31: Subject | C31: REGISTERED | D31: SAT | E31: A* | F31: A | G31: B | H31: C | I31: D | J31: E | K31: F | L31: G | M31: U | N31: X | O31: A*- A | P31: B-C | Q31: D-G | R31: U | S31: % A* - C | T31: % A* - G
A32: IGCSE English E2L (Core) | C32: ='ANALYSIS BY SUBJECTS'!$C$40 -> 0 | D32: ='ANALYSIS BY SUBJECTS'!$C$40 -> 0 | H32: ='ANALYSIS BY SUBJECTS'!D40 -> 0 | I32: ='ANALYSIS BY SUBJECTS'!E40 -> 0 | J32: ='ANALYSIS BY SUBJECTS'!F40 -> 0 | K32: ='ANALYSIS BY SUBJECTS'!G40 -> 0 | L32: ='ANALYSIS BY SUBJECTS'!H40 -> 0 | M32: ='ANALYSIS BY SUBJECTS'!I40 -> 0 | N32: 0 | O32: =((E32+F32)/C32) -> #DIV/0! | P32: =(SUM(G32:H32)/C32) -> #DIV/0! | Q32: =(SUM(I32:L32)/C32) -> #DIV/0! | R32: =M32/C32 -> #DIV/0! | S32: =(SUM(E32:H32)/C32) -> #DIV/0! | T32: =(SUM(E32:L32)/D32) -> #DIV/0!
A33: IGCSE Mathematics (Core) | C33: ='ANALYSIS BY SUBJECTS'!$C$57 -> 39 | D33: ='ANALYSIS BY SUBJECTS'!$C$57 -> 39 | H33: ='ANALYSIS BY SUBJECTS'!D57 -> 1 | I33: ='ANALYSIS BY SUBJECTS'!E57 -> 4 | J33: ='ANALYSIS BY SUBJECTS'!F57 -> 9 | K33: ='ANALYSIS BY SUBJECTS'!G57 -> 12 | L33: ='ANALYSIS BY SUBJECTS'!H57 -> 8 | M33: ='ANALYSIS BY SUBJECTS'!I57 -> 5 | N33: 0 | O33: =((E33+F33)/C33) -> 0 | P33: =(SUM(G33:H33)/C33) -> 0.025641026 | Q33: =(SUM(I33:L33)/C33) -> 0.84615385 | R33: =M33/C33 -> 0.12820513 | S33: =(SUM(E33:H33)/C33) -> 0.025641026 | T33: =(SUM(E33:L33)/D33) -> 0.87179487
C35: NUMBER OF CANDIDATES OBTAINING | O35: PERCENTAGE FOR GRADES | U35: REMARKS
C36: NO. OF CANDIDATE | E36: Distinction | G36: Credit | I36: Pass | M36: Fail | N36: ABSENT | O36: Distinction | P36: Credit | Q36: Pass | R36: Fail | S36: Credit | T36: Pass
A37: Subject | C37: REGISTERED | D37: SAT | E37: A* | F37: A | G37: B | H37: C | I37: D | J37: E | K37: F | L37: G | M37: U | N37: X | O37: A*- A | P37: B-C | Q37: D-G | R37: U | S37: % A* - C | T37: % A* - G
A38: IGCSE English E2L (Core) | C38: ='ANALYSIS BY SUBJECTS'!$C$40 -> 0 | D38: ='ANALYSIS BY SUBJECTS'!$C$40 -> 0 | E38: ='ANALYSIS BY SUBJECTS'!D40 -> 0 | F38: ='ANALYSIS BY SUBJECTS'!E40 -> 0 | G38: ='ANALYSIS BY SUBJECTS'!F40 -> 0 | H38: ='ANALYSIS BY SUBJECTS'!G40 -> 0 | I38: ='ANALYSIS BY SUBJECTS'!H40 -> 0 | J38: ='ANALYSIS BY SUBJECTS'!I40 -> 0 | K38: ='ANALYSIS BY SUBJECTS'!J40 -> 0 | L38: ='ANALYSIS BY SUBJECTS'!K40 -> 0 | M38: ='ANALYSIS BY SUBJECTS'!L40 -> 0 | N38: 0 | O38: =((E38+F38)/C38) -> #DIV/0! | P38: =(SUM(G38:H38)/C38) -> #DIV/0! | Q38: =(SUM(I38:L38)/C38) -> #DIV/0! | R38: =M38/C38 -> #DIV/0! | S38: =(SUM(E38:H38)/C38) -> #DIV/0! | T38: =(SUM(E38:L38)/D38) -> #DIV/0!

Sheet Sheet1
A1: Y10 MID YEAR EXAMINATION 2016
A2: SEKOLAH MENENGAH PG ANAK PUTERI HAJAH MASNA
A4: No. Of Candidate Registered | E4: 195
A5: No. Of Candidate Sitting | E5: 195
A6: Withdrawn | E6: 0
A8: Credit Attained | B8: No. Of Student | D8: %
A9: 9
A10: 8
A11: 7
A12: 6
A13: 5
A14: 4
A15: 3
A16: 2
A17: 1
A18: 0
A19: Total | B19: 195
C22: No. of Student | D22: %
A23: 4 or more Credits | D23: =C23/B19 -> 0
A24: 5 or more Credits | D24: =C24/B19 -> 0

Sheet Sheet2

Sheet 3'O' and 5'O' & above
A1: YEAR 11 QUALIFYING EXAMINATION 2026
B3: No. of Candidates | C3: No. of Credits Obtained | M3: 5 'O' & above | O3: 3 'O' & above
C4: 9 | D4: 8 | E4: 7 | F4: 6 | G4: 5 | H4: 4 | I4: 3 | J4: 2 | K4: 1 | L4: 0 | M4: No. of Candidates | N4: % | O4: No. of Candidates | P4: %
A5: 11D | B5: =SUM(C5:L5) -> 17 | C5: ='[1]MASTER '!$DW$38 -> 1 | D5: ='[1]MASTER '!$DW$39 -> 6 | E5: ='[1]MASTER '!$DW$40 -> 5 | F5: ='[1]MASTER '!$DW$41 -> 3 | G5: ='[1]MASTER '!$DW$42 -> 1 | H5: ='[1]MASTER '!$DW$43 -> 1 | I5: ='[1]MASTER '!$DW$44 -> 0 | J5: ='[1]MASTER '!$DW$45 -> 0 | K5: ='[1]MASTER '!$DW$46 -> 0 | L5: ='[1]MASTER '!$DW$47 -> 0 | M5: =SUM(C5:G5) -> 16 | N5: =M5/B5 -> 0.94117647 | O5: =SUM(C5:I5) -> 17 | P5: =O5/B5 -> 1
A6: 11I | B6: =SUM(C6:L6) -> 21 | C6: ='[2]MASTER '!$DW$38 -> 3 | D6: ='[2]MASTER '!$DW$39 -> 2 | E6: ='[2]MASTER '!$DW$40 -> 3 | F6: ='[2]MASTER '!$DW$41 -> 2 | G6: ='[2]MASTER '!$DW$42 -> 3 | H6: ='[2]MASTER '!$DW$43 -> 3 | I6: ='[2]MASTER '!$DW$44 -> 2 | J6: ='[2]MASTER '!$DW$45 -> 3 | K6: ='[2]MASTER '!$DW$46 -> 0 | L6: ='[2]MASTER '!$DW$47 -> 0 | M6: =SUM(C6:G6) -> 13 | N6: =M6/B6 -> 0.61904762 | O6: =SUM(C6:I6) -> 18 | P6: =O6/B6 -> 0.85714286
A7: 11S | B7: =SUM(C7:L7) -> 15 | C7: ='[3]MASTER '!$DW$38 -> 2 | D7: ='[3]MASTER '!$DW$39 -> 4 | E7: ='[3]MASTER '!$DW$40 -> 2 | F7: ='[3]MASTER '!$DW$41 -> 0 | G7: ='[3]MASTER '!$DW$42 -> 3 | H7: ='[3]MASTER '!$DW$43 -> 2 | I7: ='[3]MASTER '!$DW$44 -> 1 | J7: ='[3]MASTER '!$DW$45 -> 1 | K7: ='[3]MASTER '!$DW$46 -> 0 | L7: ='[3]MASTER '!$DW$47 -> 0 | M7: =SUM(C7:G7) -> 11 | N7: =M7/B7 -> 0.73333333 | O7: =SUM(C7:I7) -> 14 | P7: =O7/B7 -> 0.93333333
A8: 11C | B8: =SUM(C8:L8) -> 24 | C8: ='[4]MASTER '!$DW$38 -> 0 | D8: ='[4]MASTER '!$DW$39 -> 0 | E8: ='[4]MASTER '!$DW$40 -> 1 | F8: ='[4]MASTER '!$DW$41 -> 4 | G8: ='[4]MASTER '!$DW$42 -> 8 | H8: ='[4]MASTER '!$DW$43 -> 3 | I8: ='[4]MASTER '!$DW$44 -> 3 | J8: ='[4]MASTER '!$DW$45 -> 5 | K8: ='[4]MASTER '!$DW$46 -> 0 | L8: ='[4]MASTER '!$DW$47 -> 0 | M8: =SUM(C8:G8) -> 13 | N8: =M8/B8 -> 0.54166667 | O8: =SUM(C8:I8) -> 19 | P8: =O8/B8 -> 0.79166667
A9: 11O | B9: =SUM(C9:L9) -> 24 | C9: ='[5]MASTER '!$DW$38 -> 0 | D9: ='[5]MASTER '!$DW$39 -> 0 | E9: ='[5]MASTER '!$DW$40 -> 0 | F9: ='[5]MASTER '!$DW$41 -> 0 | G9: ='[5]MASTER '!$DW$42 -> 1 | H9: ='[5]MASTER '!$DW$43 -> 12 | I9: ='[5]MASTER '!$DW$44 -> 6 | J9: ='[5]MASTER '!$DW$45 -> 5 | K9: ='[5]MASTER '!$DW$46 -> 0 | L9: ='[5]MASTER '!$DW$47 -> 0 | M9: =SUM(C9:G9) -> 1 | N9: =M9/B9 -> 0.041666667 | O9: =SUM(C9:I9) -> 19 | P9: =O9/B9 -> 0.79166667
A10: 11V | B10: =SUM(C10:L10) -> 25 | C10: ='[6]MASTER '!$DW$38 -> 0 | D10: ='[6]MASTER '!$DW$39 -> 0 | E10: ='[6]MASTER '!$DW$40 -> 0 | F10: ='[6]MASTER '!$DW$41 -> 0 | G10: ='[6]MASTER '!$DW$42 -> 1 | H10: ='[6]MASTER '!$DW$43 -> 5 | I10: ='[6]MASTER '!$DW$44 -> 10 | J10: ='[6]MASTER '!$DW$45 -> 3 | K10: ='[6]MASTER '!$DW$46 -> 6 | L10: ='[6]MASTER '!$DW$47 -> 0 | M10: =SUM(C10:G10) -> 1 | N10: =M10/B10 -> 0.04 | O10: =SUM(C10:I10) -> 16 | P10: =O10/B10 -> 0.64
A11: 11E | B11: =SUM(C11:L11) -> 21 | C11: ='[7]MASTER '!$DW$38 -> 0 | D11: ='[7]MASTER '!$DW$39 -> 0 | E11: ='[7]MASTER '!$DW$40 -> 0 | F11: ='[7]MASTER '!$DW$41 -> 1 | G11: ='[7]MASTER '!$DW$42 -> 1 | H11: ='[7]MASTER '!$DW$43 -> 1 | I11: ='[7]MASTER '!$DW$44 -> 4 | J11: ='[7]MASTER '!$DW$45 -> 5 | K11: ='[7]MASTER '!$DW$46 -> 6 | L11: ='[7]MASTER '!$DW$47 -> 3 | M11: =SUM(C11:G11) -> 2 | N11: =M11/B11 -> 0.095238095 | O11: =SUM(C11:I11) -> 7 | P11: =O11/B11 -> 0.33333333
A12: 11R | B12: =SUM(C12:L12) -> 18 | C12: ='[8]MASTER '!$DW$36 -> 0 | D12: ='[8]MASTER '!$DW$37 -> 0 | E12: ='[8]MASTER '!$DW$38 -> 0 | F12: ='[8]MASTER '!$DW$39 -> 0 | G12: ='[8]MASTER '!$DW$40 -> 1 | H12: ='[8]MASTER '!$DW$41 -> 2 | I12: ='[8]MASTER '!$DW$42 -> 2 | J12: ='[8]MASTER '!$DW$43 -> 7 | K12: ='[8]MASTER '!$DW$44 -> 4 | L12: ='[8]MASTER '!$DW$45 -> 2 | M12: =SUM(C12:G12) -> 1 | N12: =M12/B12 -> 0.055555556 | O12: =SUM(C12:I12) -> 5 | P12: =O12/B12 -> 0.27777778
A13: Total No. of Candidates | B13: =SUM(B5:B12) -> 165 | C13: =SUM(C5:C12) -> 6 | D13: =SUM(D5:D12) -> 12 | E13: =SUM(E5:E12) -> 11 | F13: =SUM(F5:F12) -> 10 | G13: =SUM(G5:G12) -> 19 | H13: =SUM(H5:H12) -> 29 | I13: =SUM(I5:I12) -> 28 | ... L13: =SUM(L5:L12) -> 5 | M13: =SUM(C13:G13) -> 58 | N13: =M13/B13 -> 0.35151515 | O13: =SUM(O5:O12) -> 115 | P13: =O13/B13 -> 0.6969697
A15: % obtained 5'O' & above | B15: =$N$13 -> 0.35151515
A16: % obtained 3'O' & above | B16: =$P$13 -> 0.6969697

Sheet No.of Credits Attained
A1: YEAR 11 QUALIFYING EXAMINATION 2026
A2: SEKOLAH MENENGAH PG ANAK PUTERI HAJAH MASNA
A4: No. Of Candidate Registered | E4: 200
A5: No. Of Candidate Sitting | E5: =$B$19 -> 155
A6: Withdrawn | E6: 0
A8: Credit Attained | B8: No. Of Students | D8: %
A9: 9 | B9: 6 | D9: =B9/B19 -> 0.038709677
A10: 8 | B10: 12 | D10: =B10/B19 -> 0.077419355
A11: 7 | B11: 9 | D11: =B11/B19 -> 0.058064516
A12: 6 | B12: 10 | D12: =B12/B19 -> 0.064516129
A13: 5 | B13: 17 | D13: =B13/B19 -> 0.10967742
A14: 4 | B14: 27 | D14: =B14/B19 -> 0.17419355
A15: 3 | B15: 26 | D15: =B15/B19 -> 0.16774194
A16: 2 | B16: 26 | D16: =B16/B19 -> 0.16774194
A17: 1 | B17: 16 | D17: =B17/B19 -> 0.10322581
A18: 0 | B18: 6 | D18: =B18/B19 -> 0.038709677
A19: Total | B19: =SUM(B9:C18) -> 155
C22: No. of Student | D22: %
A23: 3 or more Credits | C23: =SUM(B9:C15) -> 107 | D23: =C23/B19 -> 0.69032258
A24: 4 or more Credits | C24: =SUM(B9:C14) -> 81 | D24: =C24/B19 -> 0.52258065
A25: 5 or more Credits | C25: =SUM(B9:C13) -> 54 | D25: =C25/B19 -> 0.3483871
