Workbook

Sheet YEAR 8
A1: BAHASA MELAYU
D2: Distinction | F2: Credit | J2: Pass | L2: Fail
A3: Class | B3: Taught By | C3: Total | D3: A* | E3: A2 | F3: B3 | G3: B4 | H3: C5 | I3: C6 | J3: D7 | K3: E8 | L3: U | M3: Total 1-6 | N3: % 1-6 | O3: Total 1-8 | P3: % 1-8
A4: YEAR 7H | B4: CG SITI IZYAN | C4: =SUM(D4:L4) -> 23 | D4: ='[1]MASTER '!$J$38 -> 0 | E4: ='[1]MASTER '!$J$39 -> 2 | F4: ='[1]MASTER '!$J$40 -> 4 | G4: ='[1]MASTER '!$J$41 -> 4 | H4: ='[1]MASTER '!$J$42 -> 2 | I4: ='[1]MASTER '!$J$43 -> 6 | J4: ='[1]MASTER '!$J$44 -> 5 | K4: ='[1]MASTER '!$J$45 -> 0 | L4: ='[1]MASTER '!$J$46 -> 0 | M4: =SUM(D4:I4) -> 18 | N4: =((M4/C4)*100) -> 78.26087 | O4: =SUM(D4:K4) -> 23 | P4: =((O4/C4)*100) -> 100
A5: YEAR 7A | B5: CG NONI RATINA | C5: =SUM(D5:L5) -> 19 | D5: ='[2]MASTER '!$J$38 -> 0 | E5: ='[2]MASTER '!$CW$39 -> 6 | F5: ='[2]MASTER '!$CW$40 -> 1 | G5: ='[2]MASTER '!$CW$41 -> 2 | H5: ='[2]MASTER '!$CW$42 -> 3 | I5: ='[2]MASTER '!$CW$43 -> 3 | J5: ='[2]MASTER '!$CW$44 -> 2 | K5: ='[2]MASTER '!$CW$45 -> 1 | L5: ='[2]MASTER '!$CW$46 -> 1 | M5: =SUM(D5:I5) -> 15 | N5: =((M5/C5)*100) -> 78.947368 | O5: =SUM(D5:K5) -> 18 | P5: =((O5/C5)*100) -> 94.736842
A6: YEAR 7R | B6: CG ERMAWATI | C6: =SUM(D6:L6) -> 27 | D6: ='[3]MASTER '!$J$38 -> 0 | E6: ='[3]MASTER '!$J$39 -> 0 | F6: ='[3]MASTER '!$J$40 -> 0 | G6: ='[3]MASTER '!$J$41 -> 1 | H6: ='[3]MASTER '!$J$42 -> 9 | I6: ='[3]MASTER '!$J$43 -> 6 | J6: ='[3]MASTER '!$J$44 -> 10 | K6: ='[3]MASTER '!$J$45 -> 1 | L6: ='[3]MASTER '!$J$46 -> 0 | M6: =SUM(D6:I6) -> 16 | N6: =((M6/C6)*100) -> 59.259259 | O6: =SUM(D6:K6) -> 27 | P6: =((O6/C6)*100) -> 100
A7: YEAR 7M | B7: CG ERMAWATI | C7: =SUM(D7:L7) -> 26 | D7: {=TRANSPOSE('[4]MASTER '!$J$38:$J$46)} -> 0 | E7: 1 | F7: 2 | G7: 6 | H7: 6 | I7: 6 | J7: 3 | K7: 1 | L7: 1 | M7: =SUM(D7:I7) -> 21 | N7: =((M7/C7)*100) -> 80.769231 | O7: =SUM(D7:K7) -> 25 | P7: =((O7/C7)*100) -> 96.153846
A8: YEAR 7O | B8: CG ERMAWATI | C8: =SUM(D8:L8) -> 24 | D8: {=TRANSPOSE('[5]MASTER '!$J$38:J46)} -> 0 | E8: 0 | F8: 5 | G8: 4 | H8: 3 | I8: 6 | J8: 6 | K8: 0 | L8: 0 | M8: =SUM(D8:I8) -> 18 | N8: =((M8/C8)*100) -> 75 | O8: =SUM(D8:K8) -> 24 | P8: =((O8/C8)*100) -> 100
A9: YEAR 7N | B9: CG NONI RATINA | C9: =SUM(D9:L9) -> 21 | D9: {=TRANSPOSE('[6]MASTER '!$J$38:J46)} -> 0 | E9: 0 | F9: 0 | G9: 0 | H9: 0 | I9: 3 | J9: 12 | K9: 4 | L9: 2 | M9: =SUM(D9:I9) -> 3 | N9: =((M9/C9)*100) -> 14.285714 | O9: =SUM(D9:K9) -> 19 | P9: =((O9/C9)*100) -> 90.47619
A10: YEAR 7Y | B10: CG SITI NOOR RAHAYU | C10: =SUM(D10:L10) -> 19 | D10: ='[7]MASTER '!$J$38 -> 0 | E10: ='[7]MASTER '!$J$39 -> 0 | F10: ='[7]MASTER '!$J$40 -> 0 | G10: ='[7]MASTER '!$J$41 -> 2 | H10: ='[7]MASTER '!$J$42 -> 1 | I10: ='[7]MASTER '!$J$43 -> 0 | J10: ='[7]MASTER '!$J$44 -> 5 | K10: ='[7]MASTER '!$J$45 -> 8 | L10: ='[7]MASTER '!$J$46 -> 3 | M10: =SUM(D10:I10) -> 3 | N10: =((M10/C10)*100) -> 15.789474 | O10: =SUM(D10:K10) -> 16 | P10: =((O10/C10)*100) -> 84.210526
A11: Overall | C11: =SUM(C4:C10) -> 159 | D11: =SUM(D4:D10) -> 0 | E11: =SUM(E4:E10) -> 9 | F11: =SUM(F4:F10) -> 12 | G11: =SUM(G4:G10) -> 19 | H11: =SUM(H4:H10) -> 24 | I11: =SUM(I4:I10) -> 30 | J11: =SUM(J4:J10) -> 43 | ... L11: =SUM(L4:L10) -> 7 | M11: =SUM(D11:I11) -> 94 | N11: =((M11/C11)*100) -> 59.119497 | O11: =SUM(D11:K11) -> 152 | P11: =((O11/C11)*100) -> 95.597484
A12: ENGLISH LANGUAGE
D13: Distinction | F13: Credit | J13: Pass | L13: Fail
A14: Class | B14: Taught By | C14: Total | D14: A* | E14: A2 | F14: B3 | G14: B4 | H14: C5 | I14: C6 | J14: D7 | K14: E8 | L14: U | M14: Total 1-6 | N14: % 1-6 | O14: Total 1-8 | P14: % 1-8
A15: YEAR 7H | B15: CG AIMI LIYANA | C15: =SUM(D15:L15) -> 23 | D15: ='[1]MASTER '!$T$38 -> 6 | E15: ='[1]MASTER '!$T$39 -> 11 | F15: ='[1]MASTER '!$T$40 -> 5 | G15: ='[1]MASTER '!$T$41 -> 0 | H15: ='[1]MASTER '!$T$42 -> 0 | I15: ='[1]MASTER '!$T$43 -> 1 | J15: ='[1]MASTER '!$T$44 -> 0 | K15: ='[1]MASTER '!$T$45 -> 0 | L15: ='[1]MASTER '!$T$46 -> 0 | M15: =SUM(D15:I15) -> 23 | N15: =((M15/C15)*100) -> 100 | O15: =SUM(D15:K15) -> 23 | P15: =((O15/C15)*100) -> 100
A16: YEAR 7A | B16: CG DEREK | C16: =SUM(D16:L16) -> 21 | D16: ='[2]MASTER '!$T$38 -> 11 | E16: ='[2]MASTER '!$T$39 -> 6 | F16: ='[2]MASTER '!$T$40 -> 2 | G16: ='[2]MASTER '!$T$41 -> 1 | H16: ='[2]MASTER '!$T$42 -> 0 | I16: ='[2]MASTER '!$T$43 -> 0 | J16: ='[2]MASTER '!$T$44 -> 1 | K16: ='[2]MASTER '!$T$45 -> 0 | L16: ='[2]MASTER '!$T$46 -> 0 | M16: =SUM(D16:I16) -> 20 | N16: =((M16/C16)*100) -> 95.238095 | O16: =SUM(D16:K16) -> 21 | P16: =((O16/C16)*100) -> 100
A17: YEAR 7R | B17: CG AIMI LIYANA | C17: =SUM(D17:L17) -> 27 | D17: ='[3]MASTER '!$T$38 -> 16 | E17: ='[3]MASTER '!$T$39 -> 8 | F17: ='[3]MASTER '!$T$40 -> 0 | G17: ='[3]MASTER '!$T$41 -> 2 | H17: ='[3]MASTER '!$T$42 -> 1 | I17: ='[3]MASTER '!$T$43 -> 0 | J17: ='[3]MASTER '!$T$44 -> 0 | K17: ='[3]MASTER '!$T$45 -> 0 | L17: ='[3]MASTER '!$T$46 -> 0 | M17: =SUM(D17:I17) -> 27 | N17: =((M17/C17)*100) -> 100 | O17: =SUM(D17:K17) -> 27 | P17: =((O17/C17)*100) -> 100
A18: YEAR 7M | B18: CG DEREK | C18: =SUM(D18:L18) -> 26 | D18: ='[4]MASTER '!$T$38 -> 14 | E18: ='[4]MASTER '!$T$39 -> 6 | F18: ='[4]MASTER '!$T$40 -> 4 | G18: ='[4]MASTER '!$T$41 -> 1 | H18: ='[1]MASTER '!$T$42 -> 0 | I18: ='[1]MASTER '!$T$43 -> 1 | J18: ='[1]MASTER '!$T$44 -> 0 | K18: ='[1]MASTER '!$T$45 -> 0 | L18: ='[1]MASTER '!$T$46 -> 0 | M18: =SUM(D18:I18) -> 26 | N18: =((M18/C18)*100) -> 100 | O18: =SUM(D18:K18) -> 26 | P18: =((O18/C18)*100) -> 100
A19: YEAR 7O | B19: CG AIMI LIYANA | C19: =SUM(D19:L19) -> 24 | D19: ='[5]MASTER '!$T$38 -> 0 | E19: ='[5]MASTER '!$T$39 -> 9 | F19: ='[5]MASTER '!$T$40 -> 4 | G19: ='[5]MASTER '!$T$41 -> 5 | H19: ='[5]MASTER '!$T$42 -> 1 | I19: ='[5]MASTER '!$T$43 -> 4 | J19: ='[5]MASTER '!$T$44 -> 1 | K19: ='[5]MASTER '!$T$45 -> 0 | L19: ='[5]MASTER '!$T$46 -> 0 | M19: =SUM(D19:I19) -> 23 | N19: =((M19/C19)*100) -> 95.833333 | O19: =SUM(D19:K19) -> 24 | P19: =((O19/C19)*100) -> 100
A20: YEAR 7N | B20: CG DEREK | C20: =SUM(D20:L20) -> 22 | D20: ='[6]MASTER '!$T$38 -> 2 | E20: ='[6]MASTER '!$T$39 -> 6 | F20: ='[6]MASTER '!$T$40 -> 3 | G20: ='[6]MASTER '!$T$41 -> 1 | H20: ='[6]MASTER '!$T$42 -> 1 | I20: ='[6]MASTER '!$T$43 -> 2 | J20: ='[6]MASTER '!$T$44 -> 6 | K20: ='[6]MASTER '!$T$45 -> 0 | L20: ='[6]MASTER '!$T$46 -> 1 | M20: =SUM(D20:I20) -> 15 | N20: =((M20/C20)*100) -> 68.181818 | O20: =SUM(D20:K20) -> 21 | P20: =((O20/C20)*100) -> 95.454545
A21: YEAR 7Y | B21: CG AIMI LIYANA | C21: =SUM(D21:L21) -> 19 | D21: ='[7]MASTER '!$T$38 -> 4 | E21: ='[7]MASTER '!$T$39 -> 2 | F21: ='[7]MASTER '!$T$40 -> 1 | G21: ='[7]MASTER '!$T$41 -> 1 | H21: ='[7]MASTER '!$T$42 -> 2 | I21: ='[7]MASTER '!$T$43 -> 3 | J21: ='[7]MASTER '!$T$44 -> 1 | K21: ='[7]MASTER '!$T$45 -> 3 | L21: ='[7]MASTER '!$T$46 -> 2 | M21: =SUM(D21:I21) -> 13 | N21: =((M21/C21)*100) -> 68.421053 | O21: =SUM(D21:K21) -> 17 | P21: =((O21/C21)*100) -> 89.473684
B22: Overall | C22: =SUM(C15:C21) -> 162 | D22: =SUM(D15:D21) -> 53 | E22: =SUM(E15:E21) -> 48 | F22: =SUM(F15:F21) -> 19 | G22: =SUM(G15:G21) -> 11 | H22: =SUM(H15:H21) -> 5 | I22: =SUM(I15:I21) -> 11 | J22: =SUM(J15:J21) -> 9 | ... L22: =SUM(L15:L21) -> 3 | M22: =SUM(D22:I22) -> 147 | N22: =((M22/C22)*100) -> 90.740741 | O22: =SUM(D22:K22) -> 159 | P22: =((O22/C22)*100) -> 98.148148
A23: ISLAMIC RELIGIOUS KNOWLEDGE
D24: Distinction | F24: Credit | J24: Pass | L24: Fail
A25: Class | B25: Taught By | C25: Total | D25: A* | E25: A2 | F25: B3 | G25: B4 | H25: C5 | I25: C6 | J25: D7 | K25: E8 | L25: U | M25: Total 1-6 | N25: % 1-6 | O25: Total 1-8 | P25: % 1-8
A26: YEAR 7H | B26: CG HJH FAUZIAHWATI | C26: =SUM(D26:L26) -> 23 | D26: ='[1]MASTER '!$AO$38 -> 15 | E26: ='[1]MASTER '!$AO$39 -> 4 | F26: ='[1]MASTER '!$AO$40 -> 3 | G26: ='[1]MASTER '!$AO$41 -> 1 | H26: ='[1]MASTER '!$AO$42 -> 0 | I26: ='[1]MASTER '!$AO$43 -> 0 | J26: ='[1]MASTER '!$AO$44 -> 0 | K26: ='[1]MASTER '!$AO$45 -> 0 | L26: ='[1]MASTER '!$AO$46 -> 0 | M26: =SUM(D26:I26) -> 23 | N26: =((M26/C26)*100) -> 100 | O26: =SUM(D26:K26) -> 23 | P26: =((O26/C26)*100) -> 100
A27: YEAR 7A | B27: CG HAJI MOHAMMAD AZMI | C27: =SUM(D27:L27) -> 21 | D27: ='[2]MASTER '!$AO$38 -> 5 | E27: ='[2]MASTER '!$AO$39 -> 5 | F27: ='[2]MASTER '!$AO$40 -> 3 | G27: ='[2]MASTER '!$AO$41 -> 3 | H27: ='[2]MASTER '!$AO$42 -> 2 | I27: ='[2]MASTER '!$AO$43 -> 1 | J27: ='[2]MASTER '!$AO$44 -> 1 | K27: ='[2]MASTER '!$AO$45 -> 1 | L27: ='[2]MASTER '!$AO$465 -> 0 | M27: =SUM(D27:I27) -> 19 | N27: =((M27/C27)*100) -> 90.47619 | O27: =SUM(D27:K27) -> 21 | P27: =((O27/C27)*100) -> 100
A28: YEAR 7R | B28: CG HJH FAUZIAHWATI | C28: =SUM(D28:L28) -> 27 | D28: ='[3]MASTER '!$AO$38 -> 4 | E28: ='[3]MASTER '!$AO$39 -> 6 | F28: ='[3]MASTER '!$AO$40 -> 1 | G28: ='[3]MASTER '!$AO$41 -> 3 | H28: ='[3]MASTER '!$AO$42 -> 4 | I28: ='[3]MASTER '!$AO$43 -> 1 | J28: ='[3]MASTER '!$AO$44 -> 6 | K28: ='[3]MASTER '!$AO$45 -> 1 | L28: ='[3]MASTER '!$AO$46 -> 1 | M28: =SUM(D28:I28) -> 19 | N28: =((M28/C28)*100) -> 70.37037 | O28: =SUM(D28:K28) -> 26 | P28: =((O28/C28)*100) -> 96.296296
A29: YEAR 7M | B29: CG HAJI MOHAMMAD AZMI | C29: =SUM(D29:L29) -> 26 | D29: ='[4]MASTER '!$AO$38 -> 11 | E29: ='[4]MASTER '!$AO$39 -> 7 | F29: ='[4]MASTER '!$AO$40 -> 0 | G29: ='[4]MASTER '!$AO$41 -> 5 | H29: ='[4]MASTER '!$AO$42 -> 1 | I29: ='[4]MASTER '!$AO$43 -> 0 | J29: ='[4]MASTER '!$AO$44 -> 2 | K29: ='[4]MASTER '!$AO$45 -> 0 | L29: ='[4]MASTER '!$AO$46 -> 0 | M29: =SUM(D29:I29) -> 24 | N29: =((M29/C29)*100) -> 92.307692 | O29: =SUM(D29:K29) -> 26 | P29: =((O29/C29)*100) -> 100
A30: YEAR 7O | B30: CG HAJI MOHAMMAD AZMI | C30: =SUM(D30:L30) -> 24 | D30: ='[5]MASTER '!$AO$38 -> 5 | E30: ='[5]MASTER '!$AO$39 -> 3 | F30: ='[5]MASTER '!$AO$40 -> 0 | G30: ='[5]MASTER '!$AO$41 -> 3 | H30: ='[5]MASTER '!$AO$42 -> 3 | I30: ='[5]MASTER '!$AO$43 -> 2 | J30: ='[5]MASTER '!$AO$44 -> 2 | K30: ='[5]MASTER '!$AO$45 -> 1 | L30: ='[5]MASTER '!$AO$46 -> 5 | M30: =SUM(D30:I30) -> 16 | N30: =((M30/C30)*100) -> 66.666667 | O30: =SUM(D30:K30) -> 19 | P30: =((O30/C30)*100) -> 79.166667
A31: YEAR 7N | B31: CG HJH FAUZIAHWATI | C31: =SUM(D31:L31) -> 23 | D31: ='[6]MASTER '!$AO$38 -> 3 | E31: ='[6]MASTER '!$AO$39 -> 11 | F31: ='[6]MASTER '!$AO$40 -> 1 | G31: ='[6]MASTER '!$AO$41 -> 2 | H31: ='[6]MASTER '!$AO$42 -> 1 | I31: ='[6]MASTER '!$AO$43 -> 1 | J31: ='[6]MASTER '!$AO$44 -> 1 | K31: ='[6]MASTER '!$AO$45 -> 2 | L31: ='[6]MASTER '!$AO$46 -> 1 | M31: =SUM(D31:I31) -> 19 | N31: =((M31/C31)*100) -> 82.608696 | O31: =SUM(D31:K31) -> 22 | P31: =((O31/C31)*100) -> 95.652174
A32: YEAR 7Y | B32: CG HJH FAUZIAHWATI | C32: =SUM(D32:L32) -> 19 | D32: ='[7]MASTER '!$AO$38 -> 0 | E32: ='[7]MASTER '!$AO$39 -> 1 | F32: ='[7]MASTER '!$AO$40 -> 1 | G32: ='[7]MASTER '!$AO$41 -> 1 | H32: ='[7]MASTER '!$AO$42 -> 0 | I32: ='[7]MASTER '!$AO$43 -> 0 | J32: ='[7]MASTER '!$AO$44 -> 4 | K32: ='[7]MASTER '!$AO$45 -> 3 | L32: ='[7]MASTER '!$AO$46 -> 9 | M32: =SUM(D32:I32) -> 3 | N32: =((M32/C32)*100) -> 15.789474 | O32: =SUM(D32:K32) -> 10 | P32: =((O32/C32)*100) -> 52.631579
B33: Overall | C33: =SUM(C26:C32) -> 163 | D33: =SUM(D26:D32) -> 43 | E33: =SUM(E26:E32) -> 37 | F33: =SUM(F26:F32) -> 9 | G33: =SUM(G26:G32) -> 18 | H33: =SUM(H26:H32) -> 11 | I33: =SUM(I26:I32) -> 5 | J33: =SUM(J26:J32) -> 16 | ... L33: =SUM(L26:L32) -> 16 | M33: =SUM(D33:I33) -> 123 | N33: =((M33/C33)*100) -> 75.460123 | O33: =SUM(D33:K33) -> 147 | P33: =((O33/C33)*100) -> 90.184049
A34: SOCIAL STUDIES
D35: Distinction | F35: Credit | J35: Pass | L35: Fail
A36: Class | B36: Taught By | C36: Total | D36: A* | E36: A2 | F36: B3 | G36: B4 | H36: C5 | I36: C6 | J36: D7 | K36: E8 | L36: U | M36: Total 1-6 | N36: % 1-6 | O36: Total 1-8 | P36: % 1-8
A37: YEAR 7H | B37: CG PG HJH MARLINAWATI | C37: =SUM(D37:L37) -> 23 | D37: ='[1]MASTER '!$BI$38 -> 18 | E37: ='[1]MASTER '!$BI$39 -> 4 | F37: ='[1]MASTER '!$BI$40 -> 0 | G37: ='[1]MASTER '!$BI$41 -> 1 | H37: ='[1]MASTER '!$BI$42 -> 0 | I37: ='[1]MASTER '!$BI$43 -> 0 | J37: ='[1]MASTER '!$BI$44 -> 0 | K37: ='[1]MASTER '!$BI$45 -> 0 | L37: ='[1]MASTER '!$BI$46 -> 0 | M37: =SUM(D37:I37) -> 23 | N37: =((M37/C37)*100) -> 100 | O37: =SUM(D37:K37) -> 23 | P37: =((O37/C37)*100) -> 100
A38: YEAR 7A | B38: CG SUNARDI | C38: =SUM(D38:L38) -> 21 | D38: ='[2]MASTER '!$BI$38 -> 0 | E38: ='[2]MASTER '!$BI$39 -> 3 | F38: ='[2]MASTER '!$BI$40 -> 0 | G38: ='[2]MASTER '!$BI$41 -> 0 | H38: ='[2]MASTER '!$BI$42 -> 3 | I38: ='[2]MASTER '!$BI$43 -> 8 | J38: ='[2]MASTER '!$BI$44 -> 6 | K38: ='[2]MASTER '!$BI$45 -> 1 | L38: ='[2]MASTER '!$BI$46 -> 0 | M38: =SUM(D38:I38) -> 14 | N38: =((M38/C38)*100) -> 66.666667 | O38: =SUM(D38:K38) -> 21 | P38: =((O38/C38)*100) -> 100
A39: YEAR 7R | B39: CG PG HJH MARLINAWATI | C39: =SUM(D39:L39) -> 27 | D39: ='[3]MASTER '!$BI$38 -> 2 | E39: ='[3]MASTER '!$BI$39 -> 9 | F39: ='[3]MASTER '!$BI$40 -> 6 | G39: ='[3]MASTER '!$BI$41 -> 2 | H39: ='[3]MASTER '!$BI$42 -> 3 | I39: ='[3]MASTER '!$BI$43 -> 2 | J39: ='[3]MASTER '!$BI$44 -> 2 | K39: ='[3]MASTER '!$BI$45 -> 1 | L39: ='[3]MASTER '!$BI$46 -> 0 | M39: =SUM(D39:I39) -> 24 | N39: =((M39/C39)*100) -> 88.888889 | O39: =SUM(D39:K39) -> 27 | P39: =((O39/C39)*100) -> 100
A40: YEAR 7M | B40: CG SUNARDI | C40: =SUM(D40:L40) -> 26 | D40: ='[4]MASTER '!$BI$38 -> 0 | E40: ='[4]MASTER '!$BI$39 -> 3 | F40: ='[4]MASTER '!$BI$40 -> 1 | G40: ='[4]MASTER '!$BI$41 -> 2 | H40: ='[4]MASTER '!$BI$42 -> 4 | I40: ='[4]MASTER '!$BI$43 -> 3 | J40: ='[4]MASTER '!$BI$44 -> 11 | K40: ='[4]MASTER '!$BI$45 -> 2 | L40: ='[4]MASTER '!$BI$46 -> 0 | M40: =SUM(D40:I40) -> 13 | N40: =((M40/C40)*100) -> 50 | O40: =SUM(D40:K40) -> 26 | P40: =((O40/C40)*100) -> 100
...

Sheet CHART
A2: Subjects | B2: % 1-6 | C2: % 1-8
A3: Bahasa Melayu | B3: ='YEAR 8'!N95 -> 59.119497 | C3: ='YEAR 8'!P95 -> 95.597484
A4: English Language | B4: ='YEAR 8'!N96 -> 90.740741 | C4: ='YEAR 8'!P96 -> 98.148148
A5: I.R.K | B5: ='YEAR 8'!N97 -> 75.460123 | C5: ='YEAR 8'!P97 -> 90.184049
A6: Social Studies | B6: ='YEAR 8'!N98 -> 68.944099 | C6: ='YEAR 8'!P98 -> 94.409938
A7: Mathematics | B7: ='YEAR 8'!N99 -> 54.320988 | C7: ='YEAR 8'!P99 -> 85.802469
A8: Science | B8: ='YEAR 8'!N100 -> 19.875776 | C8: ='YEAR 8'!P100 -> 68.322981
A9: Bahasa Arab | B9: ='YEAR 8'!N101 -> 56.198347 | C9: ='YEAR 8'!P101 -> 83.471074
A10: Melayu Islam Beraja | B10: ='YEAR 8'!N102 -> 87.974684 | C10: ='YEAR 8'!P102 -> 94.936709

Sheet 3'O' and 5'O' & above
A1: YEAR 7, ASSESSMENT 2 2026
B3: No. of Candidates | C3: No. of Credits Obtained | L3: 5 'O' & above | N3: 3 'O' & above
C4: 8 | D4: 7 | E4: 6 | F4: 5 | G4: 4 | H4: 3 | I4: 2 | J4: 1 | K4: 0 | L4: No. of Candidates | M4: % | N4: No. of Candidates | O4: %
A5: 7H | B5: =SUM(C5:K5) -> 23 | C5: ='[1]MASTER '!$DQ$39 -> 7 | D5: ='[1]MASTER '!$DQ$40 -> 10 | E5: ='[1]MASTER '!$DQ$41 -> 5 | F5: ='[1]MASTER '!$DQ$42 -> 1 | G5: ='[1]MASTER '!$DQ$43 -> 0 | H5: ='[1]MASTER '!$DQ$44 -> 0 | I5: ='[1]MASTER '!$DQ$45 -> 0 | J5: ='[1]MASTER '!$DQ$46 -> 0 | K5: ='[1]MASTER '!$DQ$47 -> 0 | L5: =SUM(C5:F5) -> 23 | M5: =L5/B5 -> 1 | N5: =SUM(C5:H5) -> 23 | O5: =N5/B5 -> 1
A6: 7A | B6: =SUM(C6:K6) -> 21 | C6: ='[2]MASTER '!$DQ$39 -> 0 | D6: ='[2]MASTER '!$DQ$40 -> 7 | E6: ='[2]MASTER '!$DQ$41 -> 6 | F6: ='[2]MASTER '!$DQ$42 -> 4 | G6: ='[2]MASTER '!$DQ$43 -> 3 | H6: ='[3]MASTER '!$DQ$44 -> 1 | I6: ='[2]MASTER '!$DQ$45 -> 0 | J6: ='[2]MASTER '!$DQ$46 -> 0 | K6: ='[2]MASTER '!$DQ$47 -> 0 | L6: =SUM(C6:F6) -> 17 | M6: =L6/B6 -> 0.80952381 | N6: =SUM(C6:H6) -> 21 | O6: =N6/B6 -> 1
A7: 7R | B7: =SUM(C7:K7) -> 28 | C7: ='[3]MASTER '!$DQ$39 -> 2 | D7: ='[3]MASTER '!$DQ$40 -> 6 | E7: ='[3]MASTER '!$DQ$41 -> 6 | F7: ='[3]MASTER '!$DQ$42 -> 4 | G7: ='[3]MASTER '!$DQ$43 -> 8 | H7: ='[4]MASTER '!$DQ$44 -> 2 | I7: ='[3]MASTER '!$DQ$45 -> 0 | J7: ='[3]MASTER '!$DQ$46 -> 0 | K7: ='[3]MASTER '!$DQ$47 -> 0 | L7: =SUM(C7:F7) -> 18 | M7: =L7/B7 -> 0.64285714 | N7: =SUM(C7:H7) -> 28 | O7: =N7/B7 -> 1
A8: 7M | B8: =SUM(C8:K8) -> 26 | C8: ='[4]MASTER '!$DQ$39 -> 0 | D8: ='[4]MASTER '!$DQ$40 -> 3 | E8: ='[4]MASTER '!$DQ$41 -> 9 | F8: ='[4]MASTER '!$DQ$42 -> 8 | G8: ='[4]MASTER '!$DQ$43 -> 2 | H8: ='[5]MASTER '!$DQ$44 -> 2 | I8: ='[4]MASTER '!$DQ$45 -> 1 | J8: ='[4]MASTER '!$DQ$46 -> 1 | K8: ='[4]MASTER '!$DQ$47 -> 0 | L8: =SUM(C8:F8) -> 20 | M8: =L8/B8 -> 0.76923077 | N8: =SUM(C8:H8) -> 24 | O8: =N8/B8 -> 0.92307692
A9: 7O | B9: =SUM(C9:K9) -> 25 | C9: ='[5]MASTER '!$DQ$39 -> 0 | D9: ='[5]MASTER '!$DQ$40 -> 1 | E9: ='[5]MASTER '!$DQ$41 -> 2 | F9: ='[5]MASTER '!$DQ$42 -> 11 | G9: ='[5]MASTER '!$DQ$43 -> 6 | H9: ='[6]MASTER '!$DQ$44 -> 3 | I9: ='[5]MASTER '!$DQ$45 -> 1 | J9: ='[5]MASTER '!$DQ$46 -> 0 | K9: ='[5]MASTER '!$DQ$47 -> 1 | L9: =SUM(C9:F9) -> 14 | M9: =L9/B9 -> 0.56 | N9: =SUM(C9:H9) -> 23 | O9: =N9/B9 -> 0.92
A10: 7N | B10: =SUM(C10:K10) -> 20 | C10: ='[6]MASTER '!$DQ$39 -> 0 | D10: ='[6]MASTER '!$DQ$40 -> 0 | E10: ='[6]MASTER '!$DQ$41 -> 0 | F10: ='[6]MASTER '!$DQ$42 -> 6 | G10: ='[6]MASTER '!$DQ$43 -> 10 | H10: ='[7]MASTER '!$DQ$44 -> 0 | I10: ='[6]MASTER '!$DQ$45 -> 2 | J10: ='[6]MASTER '!$DQ$46 -> 2 | K10: ='[6]MASTER '!$DQ$47 -> 0 | L10: =SUM(C10:F10) -> 6 | M10: =L10/B10 -> 0.3 | N10: =SUM(C10:H10) -> 16 | O10: =N10/B10 -> 0.8
A11: 7Y | B11: =SUM(C11:K11) -> 19 | C11: ='[7]MASTER '!$DQ$39 -> 0 | D11: ='[7]MASTER '!$DQ$40 -> 0 | E11: ='[7]MASTER '!$DQ$41 -> 0 | F11: ='[7]MASTER '!$DQ$42 -> 0 | G11: ='[7]MASTER '!$DQ$43 -> 3 | H11: ='[1]MASTER '!$DQ$44 -> 0 | I11: ='[7]MASTER '!$DQ$45 -> 7 | J11: ='[7]MASTER '!$DQ$46 -> 6 | K11: ='[7]MASTER '!$DQ$47 -> 3 | L11: =SUM(C11:F11) -> 0 | M11: =L11/B11 -> 0 | N11: =SUM(C11:H11) -> 3 | O11: =N11/B11 -> 0.15789474
A12: Total No. of Candidates | B12: =SUM(B5:B11) -> 162 | C12: =SUM(C5:C11) -> 9 | D12: =SUM(D5:D11) -> 27 | E12: =SUM(E5:E11) -> 28 | F12: =SUM(F5:F11) -> 34 | G12: =SUM(G5:G11) -> 32 | H12: =SUM(H5:H11) -> 8 | I12: =SUM(I5:I11) -> 11 | ... L12: =SUM(L5:L11) -> 98 | M12: =L12/B12 -> 0.60493827 | N12: =SUM(N5:N11) -> 138 | O12: =N12/B12 -> 0.85185185
A15: % obtained 5'O' & above | B15: =$M$12 -> 0.60493827
A16: % obtained 3'O' & above | B16: =$O$12 -> 0.85185185

Sheet No.of Credits Attained
A1: YEAR 7, ASSESSMENT 2 2026
A3: No. Of Candidate Registered | E3: 200
A4: No. Of Candidate Sitting | E4: 163
A5: Withdrawn | E5: 0
A7: Credit Attained | B7: No. Of Student | D7: %
A8: 8 | B8: ='3''O'' and 5''O'' & above'!$C$12 -> 9 | D8: =B8/B17 -> 0.055555556
A9: 7 | B9: ='3''O'' and 5''O'' & above'!$D$12 -> 27 | D9: =B9/B17 -> 0.16666667
A10: 6 | B10: ='3''O'' and 5''O'' & above'!$E$12 -> 28 | D10: =B10/B17 -> 0.17283951
A11: 5 | B11: ='3''O'' and 5''O'' & above'!$F$12 -> 34 | D11: =B11/B17 -> 0.20987654
A12: 4 | B12: ='3''O'' and 5''O'' & above'!$G$12 -> 32 | D12: =B12/B17 -> 0.19753086
A13: 3 | B13: ='3''O'' and 5''O'' & above'!$H$12 -> 8 | D13: =B13/B17 -> 0.049382716
A14: 2 | B14: ='3''O'' and 5''O'' & above'!$I$12 -> 11 | D14: =B14/B17 -> 0.067901235
A15: 1 | B15: ='3''O'' and 5''O'' & above'!$J$12 -> 9 | D15: =B15/B17 -> 0.055555556
A16: 0 | B16: ='3''O'' and 5''O'' & above'!$K$12 -> 4 | D16: =B16/B17 -> 0.024691358
A17: Total | B17: =SUM(B8:C16) -> 162
C20: No. of Student | D20: %
A21: 3 or more Credits | C21: =SUM(B8:C13) -> 138 | D21: =C21/B17 -> 0.85185185
A22: 4 or more Credits | C22: =SUM(B8:C12) -> 130 | D22: =C22/B17 -> 0.80246914
A23: 5 or more Credits | C23: =SUM(B8:C11) -> 98 | D23: =C23/B17 -> 0.60493827

Sheet class avg
A2: Class + No of stdn | B2: Class Avg
A3: 10Sci1
A4: 11Sci2
A5: 11Sci3
A6: 11P
A7: 11E
A8: 11A
A9: 11R
A10: 11L

Sheet By Class
A2: Menengah 4A
D3: Distinction | F3: Credit | J3: Pass | L3: Fail
A4: Subjects | B4: Taught By | C4: Total | D4: 1 | E4: 2 | F4: 3 | G4: 4 | H4: 5 | I4: 6 | J4: 7 | K4: 8 | L4: 9 | M4: Total 1-6 | N4: % 1-6 | O4: Total 1-8 | P4: % 1-8
A5: B.Melayu | N5: =((M5/C5)*100) -> #DIV/0! | O5: =SUM(D5:K5) -> 0 | P5: =((O5/C5)*100) -> #DIV/0!
A6: English | N6: =((M6/C6)*100) -> #DIV/0! | O6: =SUM(D6:K6) -> 0 | P6: =((O6/C6)*100) -> #DIV/0!
A7: Maths | N7: =((M7/C7)*100) -> #DIV/0! | O7: =SUM(D7:K7) -> 0 | P7: =((O7/C7)*100) -> #DIV/0!
A8: Add Maths | N8: =((M8/C8)*100) -> #DIV/0! | O8: =SUM(D8:K8) -> 0 | P8: =((O8/C8)*100) -> #DIV/0!
A9: Physics | N9: =((M9/C9)*100) -> #DIV/0! | O9: =SUM(D9:K9) -> 0 | P9: =((O9/C9)*100) -> #DIV/0!
A10: Chemistry | N10: =((M10/C10)*100) -> #DIV/0! | O10: =SUM(D10:K10) -> 0 | P10: =((O10/C10)*100) -> #DIV/0!
A11: Biology | N11: =((M11/C11)*100) -> #DIV/0! | O11: =SUM(D11:K11) -> 0 | P11: =((O11/C11)*100) -> #DIV/0!
A12: Geography | N12: =((M12/C12)*100) -> #DIV/0! | O12: =SUM(D12:K12) -> 0 | P12: =((O12/C12)*100) -> #DIV/0!
A13: Computer | N13: =((M13/C13)*100) -> #DIV/0! | O13: =SUM(D13:K13) -> 0 | P13: =((O13/C13)*100) -> #DIV/0!
N14: =AVERAGE(N5:N13) -> #DIV/0! | P14: =AVERAGE(P5:P13) -> #DIV/0!
A16: Menengah 4B
D17: Distinction | F17: Credit | J17: Pass | L17: Fail
A18: Subjects | B18: Taught By | C18: Total | D18: 1 | E18: 2 | F18: 3 | G18: 4 | H18: 5 | I18: 6 | J18: 7 | K18: 8 | L18: 9 | M18: Total 1-6 | N18: % 1-6 | O18: Total 1-8 | P18: % 1-8
A19: B.Melayu | N19: =((M19/C19)*100) -> #DIV/0! | O19: =SUM(D19:K19) -> 0 | P19: =((O19/C19)*100) -> #DIV/0!
A20: English | N20: =((M20/C20)*100) -> #DIV/0! | O20: =SUM(D20:K20) -> 0 | P20: =((O20/C20)*100) -> #DIV/0!
A21: Maths | N21: =((M21/C21)*100) -> #DIV/0! | O21: =SUM(D21:K21) -> 0 | P21: =((O21/C21)*100) -> #DIV/0!
A22: Physics | N22: =((M22/C22)*100) -> #DIV/0! | O22: 10 | P22: =((O22/C22)*100) -> #DIV/0!
A23: Chemistry | N23: =((M23/C23)*100) -> #DIV/0! | O23: 10 | P23: =((O23/C23)*100) -> #DIV/0!
A24: Biology | N24: =((M24/C24)*100) -> #DIV/0! | O24: 19 | P24: =((O24/C24)*100) -> #DIV/0!
A25: Geography | N25: =((M25/C25)*100) -> #DIV/0! | O25: 19 | P25: =((O25/C25)*100) -> #DIV/0!
A26: Economics | N26: =((M26/C26)*100) -> #DIV/0! | O26: 3 | P26: =((O26/C26)*100) -> #DIV/0!
A27: Computer | N27: =((M27/C27)*100) -> #DIV/0! | O27: 2 | P27: =((O27/C27)*100) -> #DIV/0!
A28: POA | N28: =((M28/C28)*100) -> #DIV/0! | O28: 12 | P28: =((O28/C28)*100) -> #DIV/0!
N29: =AVERAGE(N19:N28) -> #DIV/0! | P29: =AVERAGE(P19:P28) -> #DIV/0!
A31: Menengah 4C
D32: Distinction | F32: Credit | J32: Pass | L32: Fail
A33: Subjects | B33: Taught By | C33: Total | D33: 1 | E33: 2 | F33: 3 | G33: 4 | H33: 5 | I33: 6 | J33: 7 | K33: 8 | L33: 9 | M33: Total 1-6 | N33: % 1-6 | O33: Total 1-8 | P33: % 1-8
A34: B.Melayu | N34: =((M34/C34)*100) -> #DIV/0! | O34: 18 | P34: =((O34/C34)*100) -> #DIV/0!
A35: English | N35: =((M35/C35)*100) -> #DIV/0! | O35: 15 | P35: =((O35/C35)*100) -> #DIV/0!
A36: Maths | N36: =((M36/C36)*100) -> #DIV/0! | O36: 9 | P36: =((O36/C36)*100) -> #DIV/0!
A37: Comb Sc | N37: =((M37/C37)*100) -> #DIV/0! | O37: 6 | P37: =((O37/C37)*100) -> #DIV/0!
A38: Geography | N38: =((M38/C38)*100) -> #DIV/0! | O38: 7 | P38: =((O38/C38)*100) -> #DIV/0!
A39: History | N39: =((M39/C39)*100) -> #DIV/0! | O39: 14 | P39: =((O39/C39)*100) -> #DIV/0!
A40: IRK | N40: =((M40/C40)*100) -> #DIV/0! | O40: 16 | P40: =((O40/C40)*100) -> #DIV/0!
A41: Commerce | N41: =((M41/C41)*100) -> #DIV/0! | O41: 14 | P41: =((O41/C41)*100) -> #DIV/0!
A42: Agr Sc | N42: =((M42/C42)*100) -> #DIV/0! | O42: 2 | P42: =((O42/C42)*100) -> #DIV/0!
N43: =AVERAGE(N34:N42) -> #DIV/0! | P43: =AVERAGE(P34:P42) -> #DIV/0!
...
