Workbook

Sheet ANALYSIS BY SUBJECTS
A1: BAHASA MELAYU (1201)
D2: Distinction | F2: Credit | J2: Pass | L2: Fail
A3: Class | B3: Taught By | C3: Total | D3: A* | E3: A2 | F3: B3 | G3: B4 | H3: C5 | I3: C6 | J3: D7 | K3: E8 | L3: U | M3: Total 1-6 | N3: % 1-6 | O3: Total 1-8 | P3: % 1-8
A4: 9EXP | B4: Cg Haji Habil | C4: 18 | D4: =[1]Master!$J$47 -> 0 | E4: =[1]Master!$J$48 -> 0 | F4: =[1]Master!$J$49 -> 3 | G4: =[1]Master!$J$50 -> 9 | H4: =[1]Master!$J$51 -> 4 | I4: =[1]Master!$J$52 -> 2 | J4: =[1]Master!$J$53 -> 0 | K4: =[1]Master!$J$54 -> 0 | L4: =[1]Master!$J$55 -> 0 | M4: =SUM(D4:I4) -> 18 | N4: =((M4/C4)*100) -> 100 | O4: =SUM(D4:K4) -> 18 | P4: =((O4/C4)*100) -> 100
A5: 9SCI2 | B5: Cg Salmiah | C5: 20 | D5: {=TRANSPOSE([2]Master!$J$47:$J$55)} -> 0 | E5: 0 | F5: 1 | G5: 5 | H5: 8 | I5: 4 | J5: 2 | K5: 0 | L5: 0 | M5: =SUM(D5:I5) -> 18 | N5: =((M5/C5)*100) -> 90 | O5: =SUM(D5:K5) -> 20 | P5: =((O5/C5)*100) -> 100
A6: 9SCI3 | B6: Cg Dyg Rafidah | C6: 19 | D6: {=TRANSPOSE([3]Master!$J$47:$J$55)} -> 0 | E6: 0 | F6: 0 | G6: 2 | H6: 4 | I6: 6 | J6: 7 | K6: 0 | L6: 0 | M6: =SUM(D6:I6) -> 12 | N6: =((M6/C6)*100) -> 63.157895 | O6: =SUM(D6:K6) -> 19 | P6: =((O6/C6)*100) -> 100
A7: 9S | B7: Cg Noor Zurina | C7: 24 | D7: {=TRANSPOSE([4]Master!$J$47:$J$55)} -> 0 | E7: 1 | F7: 5 | G7: 7 | H7: 1 | I7: 3 | J7: 7 | K7: 0 | L7: 0 | M7: =SUM(D7:I7) -> 17 | N7: =((M7/C7)*100) -> 70.833333 | O7: =SUM(D7:K7) -> 24 | P7: =((O7/C7)*100) -> 100
A8: 9H | B8: Cg Salmiah | C8: 19 | D8: {=TRANSPOSE([5]Master!$J$47:$J$55)} -> 0 | E8: 0 | F8: 0 | G8: 1 | H8: 3 | I8: 3 | J8: 10 | K8: 2 | L8: 0 | M8: =SUM(D8:I8) -> 7 | N8: =((M8/C8)*100) -> 36.842105 | O8: =SUM(D8:K8) -> 19 | P8: =((O8/C8)*100) -> 100
A9: 9I | B9: Cg Salmiah | C9: 26 | D9: {=TRANSPOSE([6]Master!$J$45:$J$53)} -> 0 | E9: 0 | F9: 1 | G9: 1 | H9: 4 | I9: 6 | J9: 7 | K9: 5 | L9: 0 | M9: =SUM(D9:I9) -> 12 | N9: =((M9/C9)*100) -> 46.153846 | O9: =SUM(D9:K9) -> 24 | P9: =((O9/C9)*100) -> 92.307692
A10: 9N | B10: Cg Dyg Rafidah | C10: 21 | D10: {=TRANSPOSE([7]Master!$J$45:$J$53)} -> 0 | E10: 0 | F10: 0 | G10: 0 | H10: 4 | I10: 4 | J10: 10 | K10: 1 | L10: 0 | M10: =SUM(D10:I10) -> 8 | N10: =((M10/C10)*100) -> 38.095238 | O10: =SUM(D10:K10) -> 19 | P10: =((O10/C10)*100) -> 90.47619
A11: 9E | B11: Cg Salmiah | C11: 18 | D11: {=TRANSPOSE([8]Master!$J$47:$J$55)} -> 0 | E11: 0 | F11: 0 | G11: 0 | H11: 1 | I11: 4 | J11: 9 | K11: 4 | L11: 1 | M11: =SUM(D11:I11) -> 5 | N11: =((M11/C11)*100) -> 27.777778 | O11: =SUM(D11:K11) -> 18 | P11: =((O11/C11)*100) -> 100
B12: Overall | C12: =SUM(C4:C11) -> 165 | D12: =SUM(D4:D11) -> 0 | E12: =SUM(E4:E11) -> 1 | F12: =SUM(F4:F11) -> 10 | G12: =SUM(G4:G11) -> 25 | H12: =SUM(H4:H11) -> 29 | I12: =SUM(I4:I11) -> 32 | J12: =SUM(J4:J11) -> 52 | ... M12: =SUM(M4:M11) -> 97 | N12: =((M12/C12)*100) -> 58.787879 | O12: =SUM(O4:O11) -> 161 | P12: =((O12/C12)*100) -> 97.575758
A14: SASTERA (2023)
D15: Distinction | G15: Credit | J15: Pass | L15: Fail
A16: Class | B16: Taught By | C16: Total | D16: A* | E16: A2 | F16: B3 | G16: B4 | H16: C5 | I16: C6 | J16: D7 | K16: E8 | L16: U | M16: Total 1-6 | N16: % 1-6 | O16: Total 1-8 | P16: % 1-8
A17: 9N | B17: Cg Yuli Rabiatul | C17: 20 | D17: {=TRANSPOSE([7]Master!$Y$45:$Y$53)} -> 1 | E17: 1 | F17: 3 | G17: 1 | H17: 2 | I17: 3 | J17: 5 | K17: 2 | L17: 1 | M17: =SUM(D17:I17) -> 11 | N17: =((M17/C17)*100) -> 55 | O17: =SUM(D17:K17) -> 18 | P17: =((O17/C17)*100) -> 90
A18: 9E | B18: Cg Yuli Rabiatul | C18: 18 | D18: 0 | E18: 7 | F18: 2 | G18: 1 | H18: 2 | J18: 1 | K18: 1 | L18: 0 | M18: =SUM(D18:I18) -> 12 | N18: =((M18/C18)*100) -> 66.666667 | O18: =SUM(D18:K18) -> 14 | P18: =((O18/C18)*100) -> 77.777778
B19: Overall | C19: =SUM(C17:C18) -> 38 | D19: =SUM(D17:D18) -> 1 | E19: =SUM(E17:E18) -> 8 | F19: =SUM(F17:F18) -> 5 | G19: =SUM(G17:G18) -> 2 | H19: =SUM(H17:H18) -> 4 | I19: =SUM(I17:I18) -> 3 | J19: =SUM(J17:J18) -> 6 | K19: =SUM(K17:K18) -> 3 | L19: 3 | M19: =SUM(M17:M18) -> 23 | N19: =((M19/C19)*100) -> 60.526316 | O19: =SUM(O17:O18) -> 32 | P19: =((O19/C19)*100) -> 84.210526
A21: ENGLISH LANGUAGE (1120)
D22: Distinction | G22: Credit | J22: Pass | L22: Fail
A23: Class | B23: Taught By | C23: Total | D23: A* | E23: A2 | F23: B3 | G23: B4 | H23: C5 | I23: C6 | J23: D7 | K23: E8 | L23: U | M23: Total 1-6 | N23: % 1-6 | O23: Total 1-8 | P23: % 1-8
A24: 9EXP | B24: Asfarina | C24: 18 | D24: {=TRANSPOSE([1]Master!$M$47:$M$55)} -> 0 | E24: 9 | F24: 4 | G24: 4 | H24: 1 | I24: 0 | J24: 0 | K24: 0 | L24: 0 | M24: =SUM(D24:I24) -> 18 | N24: =((M24/C24)*100) -> 100 | O24: =SUM(D24:K24) -> 18 | P24: =((O24/C24)*100) -> 100
A25: 9SCI2 | B25: Chantelle | C25: 20 | D25: {=TRANSPOSE([2]Master!$M$47:$M$55)} -> 0 | E25: 3 | F25: 8 | G25: 5 | H25: 4 | I25: 0 | J25: 0 | K25: 0 | L25: 0 | M25: =SUM(D25:I25) -> 20 | N25: =((M25/C25)*100) -> 100 | O25: =SUM(D25:K25) -> 20 | P25: =((O25/C25)*100) -> 100
A26: 9SCI3 | B26: Asfarina | C26: 19 | D26: {=TRANSPOSE([3]Master!$M$47:$M$55)} -> 0 | E26: 3 | F26: 2 | G26: 6 | H26: 3 | I26: 4 | J26: 1 | K26: 0 | L26: 0 | M26: =SUM(D26:I26) -> 18 | N26: =((M26/C26)*100) -> 94.736842 | O26: =SUM(D26:K26) -> 19 | P26: =((O26/C26)*100) -> 100
A27: 9S | B27: Chantelle | C27: 24 | D27: {=TRANSPOSE([4]Master!$M$47:$M$55)} -> 0 | E27: 0 | F27: 3 | G27: 7 | H27: 7 | I27: 5 | J27: 2 | K27: 0 | L27: 0 | M27: =SUM(D27:I27) -> 22 | N27: =((M27/C27)*100) -> 91.666667 | O27: =SUM(D27:K27) -> 24 | P27: =((O27/C27)*100) -> 100
A28: 9H | B28: Chantelle | C28: 19 | D28: {=TRANSPOSE([5]Master!$M$47:$M$55)} -> 0 | E28: 0 | F28: 2 | G28: 3 | H28: 5 | I28: 5 | J28: 4 | K28: 0 | L28: 0 | M28: =SUM(D28:I28) -> 15 | N28: =((M28/C28)*100) -> 78.947368 | O28: =SUM(D28:K28) -> 19 | P28: =((O28/C28)*100) -> 100
A29: 9I | B29: Cg Nurátikah Hj Saiful Ashura | C29: 25 | D29: {=TRANSPOSE([7]Master!$M$45:$M$53)} -> 0 | E29: 0 | F29: 0 | G29: 0 | H29: 1 | I29: 1 | J29: 7 | K29: 8 | L29: 2 | M29: =SUM(D29:I29) -> 2 | N29: =((M29/C29)*100) -> 8 | O29: =SUM(D29:K29) -> 17 | P29: =((O29/C29)*100) -> 68
A30: 9N | B30: Ana Zaianiza Jasmi | C30: 20 | D30: 0 | E30: 0 | F30: 0 | G30: 0 | H30: 0 | I30: 1 | J30: 4 | K30: 8 | L30: 7 | M30: =SUM(D30:I30) -> 1 | N30: =((M30/C30)*100) -> 5 | O30: =SUM(D30:K30) -> 13 | P30: =((O30/C30)*100) -> 65
B31: Overall | C31: =SUM(C24:C30) -> 145 | D31: =SUM(D24:D30) -> 0 | E31: =SUM(E24:E30) -> 15 | F31: =SUM(F24:F30) -> 19 | G31: =SUM(G24:G30) -> 25 | H31: =SUM(H24:H30) -> 21 | I31: =SUM(I24:I30) -> 16 | J31: =SUM(J24:J30) -> 18 | ... M31: =SUM(M24:M30) -> 96 | N31: =((M31/C31)*100) -> 66.206897 | O31: =SUM(O24:O30) -> 130 | P31: =((O31/C31)*100) -> 89.655172
A33: IGCSE ENGLISH
D34: Distinction | F34: Credit | H34: Pass | L34: Fail
A35: Class | B35: Taught By | C35: Total | D35: A* | E35: A | F35: B | G35: C | H35: D | I35: E | J35: F | K35: G | L35: U | M35: Total 1-6 | N35: % 1-6 | O35: Total 1-8 | P35: % 1-8
A36: 9E | B36: Cg Mariah | C36: 16 | D36: {=TRANSPOSE([8]Master!$M$47:$M$55)} -> 0 | E36: 5 | F36: 2 | G36: 0 | H36: 1 | I36: 2 | J36: 2 | K36: 4 | L36: 3 | M36: =SUM(D36:I36) -> 10 | N36: =((M36/C36)*100) -> 62.5 | O36: =SUM(D36:K36) -> 16 | P36: =((O36/C36)*100) -> 100
B37: Overall | C37: =SUM(C36:C36) -> 16 | D37: =SUM(D36:D36) -> 0 | E37: =SUM(E36:E36) -> 5 | F37: =SUM(F36:F36) -> 2 | G37: =SUM(G36:G36) -> 0 | H37: =SUM(H36:H36) -> 1 | I37: =SUM(I36:I36) -> 2 | J37: =SUM(J36:J36) -> 2 | ... M37: =SUM(M36:M36) -> 10 | N37: =((M37/C37)*100) -> 62.5 | O37: =SUM(O36:O36) -> 16 | P37: =((O37/C37)*100) -> 100
A39: E2L IGCSE Core (0510)
D40: GRADE
A41: Class | B41: Taught By | C41: Total | D41: C | E41: D | F41: E | G41: F | H41: G | I41: U | M41: Total C | N41: % C | O41: Total C - G | P41: % C - G
A42: 10G | M42: =D42 -> 0 | N42: =((M42/C42)*100) -> #DIV/0! | O42: =SUM(D42:H42) -> 0 | P42: =((O42/C42)*100) -> #DIV/0!
A43: 10H | M43: =D43 -> 0 | N43: =((M43/C43)*100) -> #DIV/0! | O43: =SUM(D43:H43) -> 0 | P43: =((O43/C43)*100) -> #DIV/0!
A44: 10T | M44: =D44 -> 0 | N44: =((M44/C44)*100) -> #DIV/0! | O44: =SUM(D44:H44) -> 0 | P44: =((O44/C44)*100) -> #DIV/0!
...

Sheet OVERALL PERFORMANCES
A2: Subjects | B2: % 1-6 | C2: % 1-8
A3: B.Melayu | B3: ='ANALYSIS BY SUBJECTS'!N210 -> 59.876543 | C3: ='ANALYSIS BY SUBJECTS'!P210 -> 99.382716
A4: English Language | B4: ='ANALYSIS BY SUBJECTS'!N211 -> 69.064748 | C4: ='ANALYSIS BY SUBJECTS'!P211 -> 93.52518
A5: IGCSE English | B5: ='ANALYSIS BY SUBJECTS'!N212 -> 52.631579 | C5: ='ANALYSIS BY SUBJECTS'!P212 -> 84.210526
A6: Mathematics D | B6: ='ANALYSIS BY SUBJECTS'!N213 -> 36.290323 | C6: ='ANALYSIS BY SUBJECTS'!P213 -> 71.774194
A7: Additional Maths | B7: ='ANALYSIS BY SUBJECTS'!N214 -> 16.666667 | C7: ='ANALYSIS BY SUBJECTS'!P214 -> 50
A8: Physics | B8: ='ANALYSIS BY SUBJECTS'!N215 -> 25 | C8: ='ANALYSIS BY SUBJECTS'!P215 -> 73
A9: Chemistry | B9: ='ANALYSIS BY SUBJECTS'!N216 -> 17.283951 | C9: ='ANALYSIS BY SUBJECTS'!P216 -> 75.308642
A10: Biology | B10: ='ANALYSIS BY SUBJECTS'!N217 -> 5.2631579 | C10: ='ANALYSIS BY SUBJECTS'!P217 -> 52.631579
A11: Combined Science | B11: ='ANALYSIS BY SUBJECTS'!N218 -> 5.2631579 | C11: ='ANALYSIS BY SUBJECTS'!P218 -> 52.631579
A12: Geography | B12: ='ANALYSIS BY SUBJECTS'!N219 -> 11.111111 | C12: ='ANALYSIS BY SUBJECTS'!P219 -> 44.444444
A13: IRK | B13: ='ANALYSIS BY SUBJECTS'!N220 -> 63.580247 | C13: ='ANALYSIS BY SUBJECTS'!P220 -> 84.567901
A14: History | B14: ='ANALYSIS BY SUBJECTS'!N221 -> 49.206349 | C14: ='ANALYSIS BY SUBJECTS'!P221 -> 65.079365
... A24: ICT (IGCSE) | B24: ='ANALYSIS BY SUBJECTS'!N231 -> 50 | C24: ='ANALYSIS BY SUBJECTS'!P231 -> 50

Sheet CLASS AVERAGE
A2: Class + No of stdn | B2: Class Avg
A3: 10Sci2 (26)
A4: 10Sci3 (25)
A5: 10A (31)
A6: 10M (30)
A7: 10B (31)
A8: 10E (32)
A9: 10R (31)

Sheet By Class
A2: Menengah 4A
D3: Distinction | F3: Credit | J3: Pass | L3: Fail
A4: Subjects | B4: Taught By | C4: Total | D4: 1 | E4: 2 | F4: 3 | G4: 4 | H4: 5 | I4: 6 | J4: 7 | K4: 8 | L4: 9 | M4: Total 1-6 | N4: % 1-6 | O4: Total 1-8 | P4: % 1-8
A5: B.Melayu | N5: =((M5/C5)*100) -> #DIV/0! | O5: =SUM(D5:K5) -> 0 | P5: =((O5/C5)*100) -> #DIV/0!
A6: English | N6: =((M6/C6)*100) -> #DIV/0! | O6: =SUM(D6:K6) -> 0 | P6: =((O6/C6)*100) -> #DIV/0!
A7: Maths | N7: =((M7/C7)*100) -> #DIV/0! | O7: =SUM(D7:K7) -> 0 | P7: =((O7/C7)*100) -> #DIV/0!
A8: Add Maths | N8: =((M8/C8)*100) -> #DIV/0! | O8: =SUM(D8:K8) -> 0 | P8: =((O8/C8)*100) -> #DIV/0!
A9: Physics | N9: =((M9/C9)*100) -> #DIV/0! | O9: =SUM(D9:K9) -> 0 | P9: =((O9/C9)*100) -> #DIV/0!
A10: Chemistry | N10: =((M10/C10)*100) -> #DIV/0! | O10: =SUM(D10:K10) -> 0 | P10: =((O10/C10)*100) -> #DIV/0!
A11: Biology | N11: =((M11/C11)*100) -> #DIV/0! | O11: =SUM(D11:K11) -> 0 | P11: =((O11/C11)*100) -> #DIV/0!
A12: Geography | N12: =((M12/C12)*100) -> #DIV/0! | O12: =SUM(D12:K12) -> 0 | P12: =((O12/C12)*100) -> #DIV/0!
A13: Computer | N13: =((M13/C13)*100) -> #DIV/0! | O13: =SUM(D13:K13) -> 0 | P13: =((O13/C13)*100) -> #DIV/0!
N14: =AVERAGE(N5:N13) -> #DIV/0! | P14: =AVERAGE(P5:P13) -> #DIV/0!
A16: Menengah 4B
D17: Distinction | F17: Credit | J17: Pass | L17: Fail
A18: Subjects | B18: Taught By | C18: Total | D18: 1 | E18: 2 | F18: 3 | G18: 4 | H18: 5 | I18: 6 | J18: 7 | K18: 8 | L18: 9 | M18: Total 1-6 | N18: % 1-6 | O18: Total 1-8 | P18: % 1-8
A19: B.Melayu | N19: =((M19/C19)*100) -> #DIV/0! | O19: =SUM(D19:K19) -> 0 | P19: =((O19/C19)*100) -> #DIV/0!
A20: English | N20: =((M20/C20)*100) -> #DIV/0! | O20: =SUM(D20:K20) -> 0 | P20: =((O20/C20)*100) -> #DIV/0!
A21: Maths | N21: =((M21/C21)*100) -> #DIV/0! | O21: =SUM(D21:K21) -> 0 | P21: =((O21/C21)*100) -> #DIV/0!
A22: Physics | N22: =((M22/C22)*100) -> #DIV/0! | O22: 10 | P22: =((O22/C22)*100) -> #DIV/0!
A23: Chemistry | N23: =((M23/C23)*100) -> #DIV/0! | O23: 10 | P23: =((O23/C23)*100) -> #DIV/0!
A24: Biology | N24: =((M24/C24)*100) -> #DIV/0! | O24: 19 | P24: =((O24/C24)*100) -> #DIV/0!
A25: Geography | N25: =((M25/C25)*100) -> #DIV/0! | O25: 19 | P25: =((O25/C25)*100) -> #DIV/0!
A26: Economics | N26: =((M26/C26)*100) -> #DIV/0! | O26: 3 | P26: =((O26/C26)*100) -> #DIV/0!
A27: Computer | N27: =((M27/C27)*100) -> #DIV/0! | O27: 2 | P27: =((O27/C27)*100) -> #DIV/0!
A28: POA | N28: =((M28/C28)*100) -> #DIV/0! | O28: 12 | P28: =((O28/C28)*100) -> #DIV/0!
N29: =AVERAGE(N19:N28) -> #DIV/0! | P29: =AVERAGE(P19:P28) -> #DIV/0!
A31: Menengah 4C
D32: Distinction | F32: Credit | J32: Pass | L32: Fail
A33: Subjects | B33: Taught By | C33: Total | D33: 1 | E33: 2 | F33: 3 | G33: 4 | H33: 5 | I33: 6 | J33: 7 | K33: 8 | L33: 9 | M33: Total 1-6 | N33: % 1-6 | O33: Total 1-8 | P33: % 1-8
A34: B.Melayu | N34: =((M34/C34)*100) -> #DIV/0! | O34: 18 | P34: =((O34/C34)*100) -> #DIV/0!
A35: English | N35: =((M35/C35)*100) -> #DIV/0! | O35: 15 | P35: =((O35/C35)*100) -> #DIV/0!
A36: Maths | N36: =((M36/C36)*100) -> #DIV/0! | O36: 9 | P36: =((O36/C36)*100) -> #DIV/0!
A37: Comb Sc | N37: =((M37/C37)*100) -> #DIV/0! | O37: 6 | P37: =((O37/C37)*100) -> #DIV/0!
A38: Geography | N38: =((M38/C38)*100) -> #DIV/0! | O38: 7 | P38: =((O38/C38)*100) -> #DIV/0!
A39: History | N39: =((M39/C39)*100) -> #DIV/0! | O39: 14 | P39: =((O39/C39)*100) -> #DIV/0!
A40: IRK | N40: =((M40/C40)*100) -> #DIV/0! | O40: 16 | P40: =((O40/C40)*100) -> #DIV/0!
A41: Commerce | N41: =((M41/C41)*100) -> #DIV/0! | O41: 14 | P41: =((O41/C41)*100) -> #DIV/0!
A42: Agr Sc | N42: =((M42/C42)*100) -> #DIV/0! | O42: 2 | P42: =((O42/C42)*100) -> #DIV/0!
N43: =AVERAGE(N34:N42) -> #DIV/0! | P43: =AVERAGE(P34:P42) -> #DIV/0!
...

Sheet IGCSE SUBJECTS
A1: Y10 MID YEAR EXAMINATION 2016
A2: SEKOLAH MENENGAH PG ANAK PUTERI HAJAH MASNA
A4: IGCSE SUBJECTS
C6: NUMBER OF CANDIDATES OBTAINING | O6: PERCENTAGE FOR GRADES
C7: NO. OF CANDIDATE | E7: Distinction | G7: Credit | I7: Pass | M7: Fail | N7: ABSENT | O7: Distinction | P7: Credit | Q7: Pass | R7: Fail | S7: Credit | T7: Pass
A8: Subject | C8: REGISTERED | D8: SAT | E8: A* | F8: A | G8: B | H8: C | I8: D | J8: E | K8: F | L8: G | M8: U | N8: X | O8: A*- A | P8: B-C | Q8: D-G | R8: U | S8: % A* - C | T8: % A* - G
A9: IGCSE English E2L (Core) | C9: ='ANALYSIS BY SUBJECTS'!$C$45 -> 0 | D9: ='ANALYSIS BY SUBJECTS'!$C$45 -> 0 | H9: ='ANALYSIS BY SUBJECTS'!D45 -> 0 | I9: ='ANALYSIS BY SUBJECTS'!E45 -> 0 | J9: ='ANALYSIS BY SUBJECTS'!F45 -> 0 | K9: ='ANALYSIS BY SUBJECTS'!G45 -> 0 | L9: ='ANALYSIS BY SUBJECTS'!H45 -> 0 | M9: ='ANALYSIS BY SUBJECTS'!I45 -> 0 | O9: =((E9+F9)/C9) -> #DIV/0! | P9: =(SUM(G9:H9)/C9) -> #DIV/0! | Q9: =(SUM(I9:L9)/C9) -> #DIV/0! | R9: =M9/C9 -> #DIV/0! | S9: =(SUM(E9:H9)/C9) -> #DIV/0! | T9: =(SUM(E9:L9)/D9) -> #DIV/0!
A10: IGCSE Mathematics (Core) | C10: ='ANALYSIS BY SUBJECTS'!$C$63 -> 39 | D10: ='ANALYSIS BY SUBJECTS'!$C$63 -> 39 | H10: 1 | I10: ='ANALYSIS BY SUBJECTS'!#REF! -> #REF! | J10: 2 | K10: 15 | L10: 38 | M10: 27 | O10: =((E10+F10)/C10) -> 0 | P10: =(SUM(G10:H10)/C10) -> 0.025641026 | Q10: =(SUM(I10:L10)/C10) -> #REF! | R10: =M10/C10 -> 0.69230769 | S10: =(SUM(E10:H10)/C10) -> 0.025641026 | T10: =(SUM(E10:L10)/D10) -> #REF!
A11: IGCSE PE (Extended) | C11: 21 | D11: 21 | E11: ='ANALYSIS BY SUBJECTS'!#REF! -> #REF! | F11: ='ANALYSIS BY SUBJECTS'!#REF! -> #REF! | G11: 2 | H11: 7 | I11: 4 | J11: 1 | K11: 0 | L11: 0 | M11: ='ANALYSIS BY SUBJECTS'!#REF! -> #REF! | O11: =((E11+F11)/C11) -> #REF! | P11: =(SUM(G11:H11)/C11) -> 0.42857143 | Q11: =(SUM(I11:L11)/C11) -> 0.23809524 | R11: =M11/C11 -> #REF! | S11: =(SUM(E11:H11)/C11) -> #REF! | T11: =(SUM(E11:L11)/D11) -> #REF!
A12: IGCSE ICT (Extended) | O12: =((E12+F12)/C12) -> #DIV/0! | P12: =(SUM(G12:H12)/C12) -> #DIV/0! | Q12: =(SUM(I12:L12)/C12) -> #DIV/0! | R12: =M12/C12 -> #DIV/0! | S12: =(SUM(E12:H12)/C12) -> #DIV/0! | T12: =(SUM(E12:L12)/D12) -> #DIV/0!

Sheet OVERALL ANALYSIS
A1: SEKOLAH MENENGAH PG ANAK PUTERI HAJAH MASNA
A2: OVERALL RESULTS - YEAR 9, END OF YEAR 2025
C4: NUMBER OF CANDIDATES OBTAINING | O4: PERCENTAGE FOR GRADES | U4: REMARKS
C5: NO. OF CANDIDATE | E5: Distinction | G5: Credit | K5: Pass | M5: Fail | N5: ABSENT | O5: Distinction | P5: Credit | Q5: Pass | R5: Fail | S5: Credit | T5: Pass
A6: Subject | C6: REGISTERED | D6: SAT | E6: A*1 | F6: A2 | G6: B3 | H6: B4 | I6: C5 | J6: C6 | K6: D7 | L6: E8 | M6: U | N6: X | O6: 1-2 | P6: 3-6 | Q6: 7-8 | R6: 9 | S6: % 1-6 | T6: % 1-8
A7: B.Melayu | C7: ='ANALYSIS BY SUBJECTS'!C210 -> 162 | D7: ='ANALYSIS BY SUBJECTS'!C210 -> 162 | E7: ='ANALYSIS BY SUBJECTS'!D210 -> 0 | F7: ='ANALYSIS BY SUBJECTS'!E210 -> 1 | G7: ='ANALYSIS BY SUBJECTS'!F210 -> 10 | H7: ='ANALYSIS BY SUBJECTS'!G210 -> 25 | I7: ='ANALYSIS BY SUBJECTS'!H210 -> 29 | J7: ='ANALYSIS BY SUBJECTS'!I210 -> 32 | K7: ='ANALYSIS BY SUBJECTS'!J210 -> 52 | ... M7: ='ANALYSIS BY SUBJECTS'!L210 -> 1 | N7: 0 | O7: =((E7+F7)/C7) -> 0.0061728395 | P7: =(SUM(G7:J7)/C7) -> 0.59259259 | Q7: =(SUM(K7:L7)/C7) -> 0.39506173 | R7: =M7/C7 -> 0.0061728395 | S7: ='OVERALL PERFORMANCES'!B3 -> 59.876543 | T7: ='OVERALL PERFORMANCES'!C3 -> 99.382716
A8: English Language | C8: ='ANALYSIS BY SUBJECTS'!C211 -> 139 | D8: ='ANALYSIS BY SUBJECTS'!C211 -> 139 | E8: ='ANALYSIS BY SUBJECTS'!D211 -> 0 | F8: ='ANALYSIS BY SUBJECTS'!E211 -> 15 | G8: ='ANALYSIS BY SUBJECTS'!F211 -> 19 | H8: ='ANALYSIS BY SUBJECTS'!G211 -> 25 | I8: ='ANALYSIS BY SUBJECTS'!H211 -> 21 | J8: ='ANALYSIS BY SUBJECTS'!I211 -> 16 | K8: ='ANALYSIS BY SUBJECTS'!J211 -> 18 | ... M8: ='ANALYSIS BY SUBJECTS'!L211 -> 9 | N8: 0 | O8: =((E8+F8)/C8) -> 0.10791367 | P8: =(SUM(G8:J8)/C8) -> 0.58273381 | Q8: =(SUM(K8:L8)/C8) -> 0.24460432 | R8: =M8/C8 -> 0.064748201 | S8: ='OVERALL PERFORMANCES'!B4 -> 69.064748 | T8: ='OVERALL PERFORMANCES'!C4 -> 93.52518
A9: IGCSE English | C9: ='ANALYSIS BY SUBJECTS'!C212 -> 19 | D9: ='ANALYSIS BY SUBJECTS'!C212 -> 19 | E9: ='ANALYSIS BY SUBJECTS'!D212 -> 0 | F9: ='ANALYSIS BY SUBJECTS'!E212 -> 5 | G9: ='ANALYSIS BY SUBJECTS'!F212 -> 2 | H9: ='ANALYSIS BY SUBJECTS'!G212 -> 0 | I9: ='ANALYSIS BY SUBJECTS'!H212 -> 1 | J9: ='ANALYSIS BY SUBJECTS'!I212 -> 2 | K9: ='ANALYSIS BY SUBJECTS'!J212 -> 2 | ... M9: ='ANALYSIS BY SUBJECTS'!L212 -> 3 | N9: 0 | O9: =((E9+F9)/C9) -> 0.26315789 | P9: =(SUM(G9:J9)/C9) -> 0.26315789 | Q9: =(SUM(K9:L9)/C9) -> 0.31578947 | R9: =M9/C9 -> 0.15789474 | S9: ='ANALYSIS BY SUBJECTS'!N212 -> 52.631579 | T9: ='ANALYSIS BY SUBJECTS'!P212 -> 84.210526
A10: Mathematics D | C10: ='ANALYSIS BY SUBJECTS'!C213 -> 124 | D10: ='ANALYSIS BY SUBJECTS'!C213 -> 124 | E10: ='ANALYSIS BY SUBJECTS'!D213 -> 3 | F10: ='ANALYSIS BY SUBJECTS'!E213 -> 9 | G10: ='ANALYSIS BY SUBJECTS'!F213 -> 7 | H10: ='ANALYSIS BY SUBJECTS'!G213 -> 14 | I10: ='ANALYSIS BY SUBJECTS'!H213 -> 8 | J10: ='ANALYSIS BY SUBJECTS'!I213 -> 4 | K10: ='ANALYSIS BY SUBJECTS'!J213 -> 16 | ... M10: ='ANALYSIS BY SUBJECTS'!L213 -> 35 | N10: 0 | O10: =((E10+F10)/C10) -> 0.096774194 | P10: =(SUM(G10:J10)/C10) -> 0.26612903 | Q10: =(SUM(K10:L10)/C10) -> 0.35483871 | R10: =M10/C10 -> 0.28225806 | S10: ='OVERALL PERFORMANCES'!B6 -> 36.290323 | T10: ='OVERALL PERFORMANCES'!C6 -> 71.774194
A11: Additional Maths | C11: ='ANALYSIS BY SUBJECTS'!C214 -> 18 | D11: ='ANALYSIS BY SUBJECTS'!C214 -> 18 | E11: ='ANALYSIS BY SUBJECTS'!D214 -> 0 | F11: ='ANALYSIS BY SUBJECTS'!E214 -> 0 | G11: ='ANALYSIS BY SUBJECTS'!F214 -> 0 | H11: ='ANALYSIS BY SUBJECTS'!G214 -> 2 | I11: ='ANALYSIS BY SUBJECTS'!H214 -> 0 | J11: ='ANALYSIS BY SUBJECTS'!I214 -> 1 | K11: ='ANALYSIS BY SUBJECTS'!J214 -> 2 | ... M11: ='ANALYSIS BY SUBJECTS'!L214 -> 9 | N11: 0 | O11: =((E11+F11)/C11) -> 0 | P11: =(SUM(G11:J11)/C11) -> 0.16666667 | Q11: =(SUM(K11:L11)/C11) -> 0.33333333 | R11: =M11/C11 -> 0.5 | S11: ='OVERALL PERFORMANCES'!B7 -> 16.666667 | T11: ='OVERALL PERFORMANCES'!C7 -> 50
A12: Physics | C12: ='ANALYSIS BY SUBJECTS'!C215 -> 100 | D12: ='ANALYSIS BY SUBJECTS'!C215 -> 100 | E12: ='ANALYSIS BY SUBJECTS'!D215 -> 0 | F12: ='ANALYSIS BY SUBJECTS'!E215 -> 1 | G12: ='ANALYSIS BY SUBJECTS'!F215 -> 1 | H12: ='ANALYSIS BY SUBJECTS'!G215 -> 4 | I12: ='ANALYSIS BY SUBJECTS'!H215 -> 8 | J12: ='ANALYSIS BY SUBJECTS'!I215 -> 11 | K12: ='ANALYSIS BY SUBJECTS'!J215 -> 23 | ... M12: ='ANALYSIS BY SUBJECTS'!L215 -> 27 | N12: 0 | O12: =((E12+F12)/C12) -> 0.01 | P12: =(SUM(G12:J12)/C12) -> 0.24 | Q12: =(SUM(K12:L12)/C12) -> 0.48 | R12: =M12/C12 -> 0.27 | S12: ='OVERALL PERFORMANCES'!B8 -> 25 | T12: ='OVERALL PERFORMANCES'!C8 -> 73
A13: Chemistry | C13: ='ANALYSIS BY SUBJECTS'!C216 -> 81 | D13: ='ANALYSIS BY SUBJECTS'!C216 -> 81 | E13: ='ANALYSIS BY SUBJECTS'!D216 -> 0 | F13: ='ANALYSIS BY SUBJECTS'!E216 -> 0 | G13: ='ANALYSIS BY SUBJECTS'!F216 -> 1 | H13: ='ANALYSIS BY SUBJECTS'!G216 -> 4 | I13: ='ANALYSIS BY SUBJECTS'!H216 -> 4 | J13: ='ANALYSIS BY SUBJECTS'!I216 -> 5 | K13: ='ANALYSIS BY SUBJECTS'!J216 -> 24 | ... M13: ='ANALYSIS BY SUBJECTS'!L216 -> 20 | N13: 0 | O13: =((E13+F13)/C13) -> 0 | P13: =(SUM(G13:J13)/C13) -> 0.17283951 | Q13: =(SUM(K13:L13)/C13) -> 0.58024691 | R13: =M13/C13 -> 0.24691358 | S13: ='OVERALL PERFORMANCES'!B9 -> 17.283951 | T13: ='OVERALL PERFORMANCES'!C9 -> 75.308642
A14: Biology | C14: ='ANALYSIS BY SUBJECTS'!C217 -> 38 | D14: ='ANALYSIS BY SUBJECTS'!C217 -> 38 | E14: ='ANALYSIS BY SUBJECTS'!D217 -> 0 | F14: ='ANALYSIS BY SUBJECTS'!E217 -> 0 | G14: ='ANALYSIS BY SUBJECTS'!F217 -> 0 | H14: ='ANALYSIS BY SUBJECTS'!G217 -> 0 | I14: ='ANALYSIS BY SUBJECTS'!H217 -> 0 | J14: ='ANALYSIS BY SUBJECTS'!I217 -> 2 | K14: ='ANALYSIS BY SUBJECTS'!J217 -> 6 | ... M14: ='ANALYSIS BY SUBJECTS'!L217 -> 18 | N14: 0 | O14: =((E14+F14)/C14) -> 0 | P14: =(SUM(G14:J14)/C14) -> 0.052631579 | Q14: =(SUM(K14:L14)/C14) -> 0.47368421 | R14: =M14/C14 -> 0.47368421 | S14: ='OVERALL PERFORMANCES'!B10 -> 5.2631579 | T14: ='OVERALL PERFORMANCES'!C10 -> 52.631579
A15: Combined Science | C15: ='ANALYSIS BY SUBJECTS'!C218 -> 38 | D15: ='ANALYSIS BY SUBJECTS'!C218 -> 38 | E15: ='ANALYSIS BY SUBJECTS'!D218 -> 0 | F15: ='ANALYSIS BY SUBJECTS'!E218 -> 0 | G15: ='ANALYSIS BY SUBJECTS'!F218 -> 0 | H15: ='ANALYSIS BY SUBJECTS'!G218 -> 0 | I15: ='ANALYSIS BY SUBJECTS'!H218 -> 0 | J15: ='ANALYSIS BY SUBJECTS'!I218 -> 2 | K15: ='ANALYSIS BY SUBJECTS'!J218 -> 6 | ... M15: ='ANALYSIS BY SUBJECTS'!L218 -> 18 | N15: 0 | O15: =((E15+F15)/C15) -> 0 | P15: =(SUM(G15:J15)/C15) -> 0.052631579 | Q15: =(SUM(K15:L15)/C15) -> 0.47368421 | R15: =M15/C15 -> 0.47368421 | S15: ='OVERALL PERFORMANCES'!B11 -> 5.2631579 | T15: ='OVERALL PERFORMANCES'!C11 -> 52.631579
A16: Geography | C16: ='ANALYSIS BY SUBJECTS'!C219 -> 63 | D16: ='ANALYSIS BY SUBJECTS'!C219 -> 63 | E16: ='ANALYSIS BY SUBJECTS'!D219 -> 0 | F16: ='ANALYSIS BY SUBJECTS'!E219 -> 0 | G16: ='ANALYSIS BY SUBJECTS'!F219 -> 0 | H16: ='ANALYSIS BY SUBJECTS'!G219 -> 1 | I16: ='ANALYSIS BY SUBJECTS'!H219 -> 2 | J16: ='ANALYSIS BY SUBJECTS'!I219 -> 4 | K16: ='ANALYSIS BY SUBJECTS'!J219 -> 10 | ... M16: ='ANALYSIS BY SUBJECTS'!L219 -> 35 | N16: 0 | O16: =((E16+F16)/C16) -> 0 | P16: =(SUM(G16:J16)/C16) -> 0.11111111 | Q16: =(SUM(K16:L16)/C16) -> 0.33333333 | R16: =M16/C16 -> 0.55555556 | S16: ='OVERALL PERFORMANCES'!B12 -> 11.111111 | T16: ='OVERALL PERFORMANCES'!C12 -> 44.444444
A17: IRK | C17: ='ANALYSIS BY SUBJECTS'!C220 -> 162 | D17: ='ANALYSIS BY SUBJECTS'!C220 -> 162 | E17: ='ANALYSIS BY SUBJECTS'!D220 -> 26 | F17: ='ANALYSIS BY SUBJECTS'!E220 -> 19 | G17: ='ANALYSIS BY SUBJECTS'!F220 -> 14 | H17: ='ANALYSIS BY SUBJECTS'!G220 -> 15 | I17: ='ANALYSIS BY SUBJECTS'!H220 -> 16 | J17: ='ANALYSIS BY SUBJECTS'!I220 -> 13 | K17: ='ANALYSIS BY SUBJECTS'!J220 -> 20 | ... M17: ='ANALYSIS BY SUBJECTS'!L220 -> 25 | N17: 0 | O17: =((E17+F17)/C17) -> 0.27777778 | P17: =(SUM(G17:J17)/C17) -> 0.35802469 | Q17: =(SUM(K17:L17)/C17) -> 0.20987654 | R17: =M17/C17 -> 0.15432099 | S17: ='OVERALL PERFORMANCES'!B13 -> 63.580247 | T17: ='OVERALL PERFORMANCES'!C13 -> 84.567901
A18: History | C18: ='ANALYSIS BY SUBJECTS'!C221 -> 63 | D18: ='ANALYSIS BY SUBJECTS'!C221 -> 63 | E18: ='ANALYSIS BY SUBJECTS'!D221 -> 3 | F18: ='ANALYSIS BY SUBJECTS'!E221 -> 2 | G18: ='ANALYSIS BY SUBJECTS'!F221 -> 0 | H18: ='ANALYSIS BY SUBJECTS'!G221 -> 12 | I18: ='ANALYSIS BY SUBJECTS'!H221 -> 0 | J18: ='ANALYSIS BY SUBJECTS'!I221 -> 14 | K18: ='ANALYSIS BY SUBJECTS'!J221 -> 7 | ... M18: ='ANALYSIS BY SUBJECTS'!L221 -> 22 | N18: 0 | O18: =((E18+F18)/C18) -> 0.079365079 | P18: =(SUM(G18:J18)/C18) -> 0.41269841 | Q18: =(SUM(K18:L18)/C18) -> 0.15873016 | R18: =M18/C18 -> 0.34920635 | S18: ='OVERALL PERFORMANCES'!B14 -> 49.206349 | T18: ='OVERALL PERFORMANCES'!C14 -> 65.079365
A19: Commerce | C19: ='ANALYSIS BY SUBJECTS'!C222 -> 24 | D19: ='ANALYSIS BY SUBJECTS'!C222 -> 24 | E19: ='ANALYSIS BY SUBJECTS'!D222 -> 0 | F19: ='ANALYSIS BY SUBJECTS'!E222 -> 0 | G19: ='ANALYSIS BY SUBJECTS'!F222 -> 1 | H19: ='ANALYSIS BY SUBJECTS'!G222 -> 3 | I19: ='ANALYSIS BY SUBJECTS'!H222 -> 3 | J19: ='ANALYSIS BY SUBJECTS'!I222 -> 5 | K19: ='ANALYSIS BY SUBJECTS'!J222 -> 9 | ... M19: ='ANALYSIS BY SUBJECTS'!L222 -> 1 | N19: 0 | O19: =((E19+F19)/C19) -> 0 | P19: =(SUM(G19:J19)/C19) -> 0.5 | Q19: =(SUM(K19:L19)/C19) -> 0.45833333 | R19: =M19/C19 -> 0.041666667 | S19: ='OVERALL PERFORMANCES'!B15 -> 50 | T19: ='OVERALL PERFORMANCES'!C15 -> 95.833333
A20: Economics | C20: ='ANALYSIS BY SUBJECTS'!C223 -> 18 | D20: ='ANALYSIS BY SUBJECTS'!C223 -> 18 | E20: ='ANALYSIS BY SUBJECTS'!D223 -> 0 | F20: ='ANALYSIS BY SUBJECTS'!E223 -> 0 | G20: ='ANALYSIS BY SUBJECTS'!F223 -> 0 | H20: ='ANALYSIS BY SUBJECTS'!G223 -> 2 | I20: ='ANALYSIS BY SUBJECTS'!H223 -> 2 | J20: ='ANALYSIS BY SUBJECTS'!I223 -> 5 | K20: ='ANALYSIS BY SUBJECTS'!J223 -> 8 | ... M20: ='ANALYSIS BY SUBJECTS'!L223 -> 1 | N20: 0 | O20: =((E20+F20)/C20) -> 0 | P20: =(SUM(G20:J20)/C20) -> 0.5 | Q20: =(SUM(K20:L20)/C20) -> 0.44444444 | R20: =M20/C20 -> 0.055555556 | S20: ='OVERALL PERFORMANCES'!B16 -> 50 | T20: ='OVERALL PERFORMANCES'!C16 -> 94.444444
A21: Accounting | C21: ='ANALYSIS BY SUBJECTS'!C224 -> 43 | D21: ='ANALYSIS BY SUBJECTS'!C224 -> 43 | E21: ='ANALYSIS BY SUBJECTS'!D224 -> 0 | F21: ='ANALYSIS BY SUBJECTS'!E224 -> 0 | G21: ='ANALYSIS BY SUBJECTS'!F224 -> 0 | H21: ='ANALYSIS BY SUBJECTS'!G224 -> 0 | I21: ='ANALYSIS BY SUBJECTS'!H224 -> 0 | J21: ='ANALYSIS BY SUBJECTS'!I224 -> 3 | K21: ='ANALYSIS BY SUBJECTS'!J224 -> 5 | ... M21: ='ANALYSIS BY SUBJECTS'!L224 -> 30 | N21: 0 | O21: =((E21+F21)/C21) -> 0 | P21: =(SUM(G21:J21)/C21) -> 0.069767442 | Q21: =(SUM(K21:L21)/C21) -> 0.23255814 | R21: =M21/C21 -> 0.69767442 | S21: ='OVERALL PERFORMANCES'!B17 -> 6.9767442 | T21: ='OVERALL PERFORMANCES'!C17 -> 30.232558
... A26: Travel and Tourism | C26: ='ANALYSIS BY SUBJECTS'!C229 -> 48 | D26: ='ANALYSIS BY SUBJECTS'!C229 -> 48 | E26: ='ANALYSIS BY SUBJECTS'!D229 -> 0 | F26: ='ANALYSIS BY SUBJECTS'!E229 -> 4 | G26: ='ANALYSIS BY SUBJECTS'!F229 -> 1 | H26: ='ANALYSIS BY SUBJECTS'!G229 -> 5 | I26: ='ANALYSIS BY SUBJECTS'!H229 -> 5 | J26: ='ANALYSIS BY SUBJECTS'!I229 -> 7 | K26: ='ANALYSIS BY SUBJECTS'!J229 -> 6 | ... M26: ='ANALYSIS BY SUBJECTS'!L229 -> 17 | N26: 0 | O26: =((E26+F26)/C26) -> 0.083333333 | P26: =(SUM(G26:J26)/C26) -> 0.375 | Q26: =(SUM(K26:L26)/C26) -> 0.1875 | R26: =M26/C26 -> 0.35416667 | S26: ='OVERALL PERFORMANCES'!B22 -> 45.833333 | T26: ='OVERALL PERFORMANCES'!C22 -> 64.583333
A27: Computer Science | C27: ='ANALYSIS BY SUBJECTS'!C189 -> 39 | D27: ='ANALYSIS BY SUBJECTS'!C189 -> 39 | E27: ='ANALYSIS BY SUBJECTS'!D189 -> 0 | F27: ='ANALYSIS BY SUBJECTS'!E189 -> 1 | G27: ='ANALYSIS BY SUBJECTS'!F189 -> 0 | H27: ='ANALYSIS BY SUBJECTS'!G189 -> 0 | I27: ='ANALYSIS BY SUBJECTS'!H189 -> 0 | J27: ='ANALYSIS BY SUBJECTS'!I189 -> 4 | K27: ='ANALYSIS BY SUBJECTS'!J189 -> 8 | ... M27: ='ANALYSIS BY SUBJECTS'!L189 -> 17 | N27: 0 | O27: =((E27+F27)/C27) -> 0.025641026 | P27: =(SUM(G27:J27)/C27) -> 0.1025641 | Q27: =(SUM(K27:L27)/C27) -> 0.43589744 | R27: =M27/C27 -> 0.43589744 | S27: ='OVERALL PERFORMANCES'!B23 -> 12.820513 | T27: ='OVERALL PERFORMANCES'!C23 -> 56.410256
A28: Literature in English | C28: 4 | D28: 4 | E28: 0 | F28: 0 | G28: 1 | H28: 1 | I28: 1 | J28: 1 | K28: ='ANALYSIS BY SUBJECTS'!J230 -> 8 | L28: ='ANALYSIS BY SUBJECTS'!K230 -> 9 | M28: ='ANALYSIS BY SUBJECTS'!L230 -> 17 | N28: 0 | O28: =((E28+F28)/C28) -> 0 | P28: =(SUM(G28:J28)/C28) -> 1 | Q28: =(SUM(K28:L28)/C28) -> 4.25 | R28: =M28/C28 -> 4.25 | S28: ='OVERALL PERFORMANCES'!B23 -> 12.820513 | T28: ='OVERALL PERFORMANCES'!C23 -> 56.410256
C30: NUMBER OF CANDIDATES OBTAINING | O30: PERCENTAGE FOR GRADES | U30: REMARKS
C31: NO. OF CANDIDATE | E31: Distinction | G31: Credit | I31: Pass | M31: Fail | N31: ABSENT | O31: Distinction | P31: Credit | Q31: Pass | R31: Fail | S31: Credit | T31: Pass
A32: Subject | C32: REGISTERED | D32: SAT | E32: A* | F32: A | G32: B | H32: C | I32: D | J32: E | K32: F | L32: G | M32: U | N32: X | O32: A*- A | P32: B-C | Q32: D-G | R32: U | S32: % A* - C | T32: % A* - G
A33: IGCSE English E2L (Core) | C33: ='ANALYSIS BY SUBJECTS'!$C$45 -> 0 | D33: ='ANALYSIS BY SUBJECTS'!$C$45 -> 0 | H33: ='ANALYSIS BY SUBJECTS'!D45 -> 0 | I33: ='ANALYSIS BY SUBJECTS'!E45 -> 0 | J33: ='ANALYSIS BY SUBJECTS'!F45 -> 0 | K33: ='ANALYSIS BY SUBJECTS'!G45 -> 0 | L33: ='ANALYSIS BY SUBJECTS'!H45 -> 0 | M33: ='ANALYSIS BY SUBJECTS'!I45 -> 0 | N33: 0 | O33: =((E33+F33)/C33) -> #DIV/0! | P33: =(SUM(G33:H33)/C33) -> #DIV/0! | Q33: =(SUM(I33:L33)/C33) -> #DIV/0! | R33: =M33/C33 -> #DIV/0! | S33: =(SUM(E33:H33)/C33) -> #DIV/0! | T33: =(SUM(E33:L33)/D33) -> #DIV/0!
A34: IGCSE Mathematics (Core) | C34: ='ANALYSIS BY SUBJECTS'!$C$63 -> 39 | D34: ='ANALYSIS BY SUBJECTS'!$C$63 -> 39 | H34: ='ANALYSIS BY SUBJECTS'!D63 -> 16 | I34: ='ANALYSIS BY SUBJECTS'!E63 -> 11 | J34: ='ANALYSIS BY SUBJECTS'!F63 -> 7 | K34: ='ANALYSIS BY SUBJECTS'!G63 -> 3 | L34: ='ANALYSIS BY SUBJECTS'!H63 -> 1 | M34: ='ANALYSIS BY SUBJECTS'!I63 -> 0 | N34: 0 | O34: =((E34+F34)/C34) -> 0 | P34: =(SUM(G34:H34)/C34) -> 0.41025641 | Q34: =(SUM(I34:L34)/C34) -> 0.56410256 | R34: =M34/C34 -> 0 | S34: =(SUM(E34:H34)/C34) -> 0.41025641 | T34: =(SUM(E34:L34)/D34) -> 0.97435897
A35: ICT | C35: ='ANALYSIS BY SUBJECTS'!C231 -> 78 | D35: 39 | E35: 0 | F35: 3 | G35: 29 | H35: 7 | I35: 0 | J35: 0 | K35: 0 | L35: 0 | M35: 0 | N35: 0 | O35: =((E35+F35)/C35) -> 0.038461538 | P35: =(SUM(G35:H35)/C35) -> 0.46153846 | Q35: =(SUM(I35:L35)/C35) -> 0 | R35: =M35/C35 -> 0 | S35: =(SUM(E35:H35)/C35) -> 0.5 | T35: =(SUM(E35:L35)/D35) -> 1

Sheet Sheet1
A1: Y10 MID YEAR EXAMINATION 2016
A2: SEKOLAH MENENGAH PG ANAK PUTERI HAJAH MASNA
A4: No. Of Candidate Registered | E4: 195
A5: No. Of Candidate Sitting | E5: 195
A6: Withdrawn | E6: 0
A8: Credit Attained | B8: No. Of Student | D8: %
A9: 9
A10: 8
A11: 7
A12: 6
A13: 5
A14: 4
A15: 3
A16: 2
A17: 1
A18: 0
A19: Total | B19: 195
C22: No. of Student | D22: %
A23: 4 or more Credits | D23: =C23/B19 -> 0
A24: 5 or more Credits | D24: =C24/B19 -> 0

Sheet Sheet2

Sheet 3'O' and 5'O' & above
A1: YEAR 9, END OF YEAR 2025
B3: No. of Candidates | C3: No. of Credits Obtained | M3: 5 'O' & above | O3: 3 'O' & above
C4: 9 | D4: 8 | E4: 7 | F4: 6 | G4: 5 | H4: 4 | I4: 3 | J4: 2 | K4: 1 | L4: 0 | M4: No. of Candidates | N4: % | O4: No. of Candidates | P4: %
A5: 9Exp | B5: =SUM(C5:L5) -> 18 | C5: =[1]Master!$AZ$47 -> 2 | D5: =[1]Master!$AZ$48 -> 4 | E5: =[1]Master!$AZ$49 -> 3 | F5: =[1]Master!$AZ$50 -> 6 | G5: =[1]Master!$AZ$51 -> 1 | H5: =[1]Master!$AZ$52 -> 1 | I5: =[1]Master!$AZ$53 -> 1 | J5: =[1]Master!$AZ$54 -> 0 | K5: =[1]Master!$AZ$55 -> 0 | L5: =[1]Master!$AZ$56 -> 0 | M5: =SUM(C5:G5) -> 16 | N5: =M5/B5 -> 0.88888889 | O5: =SUM(C5:I5) -> 18 | P5: =O5/B5 -> 1
A6: 9Sci2 | B6: =SUM(C6:L6) -> 15 | C6: =[2]Master!$AZ$47 -> 0 | D6: =[2]Master!$AZ$48 -> 1 | E6: =[2]Master!$AZ$49 -> 3 | F6: =[2]Master!$AZ$50 -> 3 | G6: =[2]Master!$AZ$51 -> 5 | H6: =[2]Master!$AZ$52 -> 2 | I6: =[2]Master!$AZ$53 -> 0 | J6: =[2]Master!$AZ$54 -> 1 | K6: =[2]Master!$AZ$55 -> 0 | L6: =[2]Master!$AZ$56 -> 0 | M6: =SUM(C6:G6) -> 12 | N6: =M6/B6 -> 0.8 | O6: =SUM(C6:I6) -> 14 | P6: =O6/B6 -> 0.93333333
A7: 9Sci3 | B7: =SUM(C7:L7) -> 19 | C7: 2 | D7: 1 | E7: 0 | F7: 0 | G7: 0 | H7: 2 | I7: 8 | J7: 2 | K7: 4 | L7: 0 | M7: =SUM(C7:G7) -> 3 | N7: =M7/B7 -> 0.15789474 | O7: =SUM(C7:I7) -> 13 | P7: =O7/B7 -> 0.68421053
A8: 9S | B8: =SUM(C8:L8) -> 24 | C8: 0 | D8: 0 | E8: 0 | F8: 3 | G8: 4 | H8: 5 | I8: 5 | J8: 5 | K8: 2 | L8: 0 | M8: =SUM(C8:G8) -> 7 | N8: =M8/B8 -> 0.29166667 | O8: =SUM(C8:I8) -> 17 | P8: =O8/B8 -> 0.70833333
A9: 9H | B9: =SUM(C9:L9) -> 19 | C9: 0 | D9: 0 | E9: 1 | F9: 0 | G9: 5 | H9: 4 | I9: 4 | J9: 4 | K9: 1 | L9: 0 | M9: =SUM(C9:G9) -> 6 | N9: =M9/B9 -> 0.31578947 | O9: =SUM(C9:I9) -> 14 | P9: =O9/B9 -> 0.73684211
A10: 9I | B10: =SUM(C10:L10) -> 24 | C10: 0 | D10: 0 | E10: 0 | F10: 1 | G10: 2 | H10: 6 | I10: 5 | J10: 5 | K10: 1 | L10: 4 | M10: =SUM(C10:G10) -> 3 | N10: =M10/B10 -> 0.125 | O10: =SUM(C10:I10) -> 14 | P10: =O10/B10 -> 0.58333333
A11: 9N | B11: =SUM(C11:L11) -> 19 | C11: 0 | D11: 0 | E11: 0 | F11: 1 | G11: 4 | H11: 0 | I11: 6 | J11: 0 | K11: 4 | L11: 4 | M11: =SUM(C11:G11) -> 5 | N11: =M11/B11 -> 0.26315789 | O11: =SUM(C11:I11) -> 11 | P11: =O11/B11 -> 0.57894737
A12: 9E | B12: =SUM(C12:L12) -> 19 | C12: 0 | D12: 0 | E12: 0 | F12: 2 | G12: 1 | H12: 4 | I12: 6 | J12: 1 | K12: 1 | L12: 4 | M12: =SUM(C12:L12) -> 19 | N12: =M12/B12 -> 1 | O12: =SUM(C12:I12) -> 13 | P12: =O12/B12 -> 0.68421053
A13: Total No. of Candidates | B13: =SUM(C13:L13) -> 157 | C13: =SUM(C5:C12) -> 4 | D13: =SUM(D5:D12) -> 6 | E13: =SUM(E5:E12) -> 7 | F13: =SUM(F5:F12) -> 16 | G13: =SUM(G5:G12) -> 22 | H13: =SUM(H5:H12) -> 24 | I13: =SUM(I5:I12) -> 35 | J13: =SUM(J5:J12) -> 18 | ... M13: =SUM(M5:M12) -> 71 | N13: =M13/B13 -> 0.4522293 | O13: =SUM(O5:O12) -> 114 | P13: =O13/B13 -> 0.72611465
A15: % obtained 5'O' & above | B15: =$N$13 -> 0.4522293
A16: % obtained 3'O' & above | B16: =$P$13 -> 0.72611465

Sheet No.of Credits Attained
A1: YEAR 9, END OF YEAR 2025
A2: SEKOLAH MENENGAH PG ANAK PUTERI HAJAH MASNA
A4: No. Of Candidate Registered | E4: 200
A5: No. Of Candidate Sitting | E5: =$B$19 -> 166 | AC5: 29
A6: Withdrawn | E6: 0
A8: Credit Attained | B8: No. Of Student | D8: %
A9: 9 | B9: 3 | D9: =B9/B19 -> 0.018072289
A10: 8 | B10: 12 | D10: =B10/B19 -> 0.072289157
A11: 7 | B11: 20 | D11: =B11/B19 -> 0.12048193
A12: 6 | B12: 31 | D12: =B12/B19 -> 0.18674699
A13: 5 | B13: 25 | D13: =B13/B19 -> 0.15060241
A14: 4 | B14: 27 | D14: =B14/B19 -> 0.1626506
A15: 3 | B15: 25 | D15: =B15/B19 -> 0.15060241
A16: 2 | B16: 15 | D16: =B16/B19 -> 0.090361446
A17: 1 | B17: 2 | D17: =B17/B19 -> 0.012048193
A18: 0 | B18: 6 | D18: =B18/B19 -> 0.036144578
A19: Total | B19: =SUM(B9:C18) -> 166
C22: No. of Student | D22: %
A23: 3 or more Credits | C23: =SUM(B9:C15) -> 143 | D23: =C23/B19 -> 0.86144578
A24: 4 or more Credits | C24: =SUM(B9:C14) -> 118 | D24: =C24/B19 -> 0.71084337
A25: 5 or more Credits | C25: =SUM(B9:C13) -> 91 | D25: =C25/B19 -> 0.54819277
