Workbook

Sheet YEAR 7
A1: BAHASA MELAYU
D2: Distinction | F2: Credit | J2: Pass | L2: Fail
A3: Class | B3: Taught By | C3: Total | D3: A* | E3: A2 | F3: B3 | G3: B4 | H3: C5 | I3: C6 | J3: D7 | K3: E8 | L3: U | M3: Total 1-6 | N3: % 1-6 | O3: Total 1-8 | P3: % 1-8
A4: 7D | B4: Cg Noni Ratina | C4: =SUM(D4:L4) -> 18 | D4: {=TRANSPOSE([1]Master!$J$47:$J$55)} -> 0 | E4: 6 | F4: 4 | G4: 4 | H4: 2 | I4: 1 | J4: 1 | K4: 0 | L4: 0 | M4: =SUM(D4:I4) -> 17 | N4: =(M4/C4)*100 -> 94.444444 | O4: =SUM(D4:K4) -> 18 | P4: =(O4/C4)*100 -> 100
A5: 7Y | B5: Cg Siti Noor Rahayu | C5: =SUM(D5:L5) -> 20 | D5: {=TRANSPOSE([2]Master!$K$66:$K$74)} -> 0 | E5: 2 | F5: 8 | G5: 5 | H5: 2 | I5: 3 | J5: 0 | K5: 0 | L5: 0 | M5: =SUM(D5:I5) -> 20 | N5: =(M5/C5)*100 -> 100 | O5: =SUM(D5:K5) -> 20 | P5: =(O5/C5)*100 -> 100
A6: 7N | B6: Cg Siti Izyan | C6: =SUM(D6:L6) -> 24 | D6: {=TRANSPOSE([3]Master!$K$66:$K$74)} -> 0 | E6: 3 | F6: 4 | G6: 6 | H6: 7 | I6: 3 | J6: 1 | K6: 0 | L6: 0 | M6: =SUM(D6:I6) -> 23 | N6: =(M6/C6)*100 -> 95.833333 | O6: =SUM(D6:K6) -> 24 | P6: =(O6/C6)*100 -> 100
A7: 7A | B7: Cg Siti Noor Rahayu | C7: =SUM(D7:L7) -> 25 | D7: {=TRANSPOSE([4]Master!$J$47:$J$55)} -> 0 | E7: 1 | F7: 7 | G7: 6 | H7: 7 | I7: 3 | J7: 1 | K7: 0 | L7: 0 | M7: =SUM(D7:I7) -> 24 | N7: =(M7/C7)*100 -> 96 | O7: =SUM(D7:K7) -> 25 | P7: =(O7/C7)*100 -> 100
A8: 7M | B8: Cg Noni Ratina | C8: =SUM(D8:L8) -> 25 | D8: {=TRANSPOSE([5]Master!$K$66:$K$74)} -> 0 | E8: 0 | F8: 0 | G8: 3 | H8: 4 | I8: 6 | J8: 5 | K8: 6 | L8: 1 | M8: =SUM(D8:I8) -> 13 | N8: =(M8/C8)*100 -> 52 | O8: =SUM(D8:K8) -> 24 | P8: =(O8/C8)*100 -> 96
A9: 7I | B9: Cg Siti Noor Rahayu | C9: =SUM(D9:L9) -> 24 | D9: {=TRANSPOSE([6]Master!$K$66:$K$74)} -> 0 | E9: 0 | F9: 0 | G9: 2 | H9: 4 | I9: 11 | J9: 5 | K9: 1 | L9: 1 | M9: =SUM(D9:I9) -> 17 | N9: =(M9/C9)*100 -> 70.833333 | O9: =SUM(D9:K9) -> 23 | P9: =(O9/C9)*100 -> 95.833333
A10: 7C | B10: Cg Amalina | C10: =SUM(D10:L10) -> 20 | D10: {=TRANSPOSE([7]Master!$K$66:$K$74)} -> 0 | E10: 0 | F10: 1 | G10: 1 | H10: 1 | I10: 1 | J10: 8 | K10: 2 | L10: 6 | M10: =SUM(D10:I10) -> 4 | N10: =(M10/C10)*100 -> 20 | O10: =SUM(D10:K10) -> 14 | P10: =(O10/C10)*100 -> 70
B11: Overall | C11: =SUM(C4:C10) -> 156 | D11: =SUM(D4:D10) -> 0 | E11: =SUM(E4:E10) -> 12 | F11: =SUM(F4:F10) -> 24 | G11: =SUM(G4:G10) -> 27 | H11: =SUM(H4:H10) -> 27 | I11: =SUM(I4:I10) -> 28 | J11: =SUM(J4:J10) -> 21 | ... L11: =SUM(L4:L10) -> 8 | M11: =SUM(D11:I11) -> 118 | N11: =(M11/C11)*100 -> 75.641026 | O11: =SUM(D11:K11) -> 148 | P11: =(O11/C11)*100 -> 94.871795
A13: ENGLISH LANGUAGE
D14: Distinction | F14: Credit | J14: Pass | L14: Fail
A15: Class | B15: Taught By | C15: Total | D15: A* | E15: A2 | F15: B3 | G15: B4 | H15: C5 | I15: C6 | J15: D7 | K15: E8 | L15: U | M15: Total 1-6 | N15: % 1-6 | O15: Total 1-8 | P15: % 1-8
A16: 7D | B16: Cg Noratikah | C16: =SUM(D16:L16) -> 18 | D16: {=TRANSPOSE([1]Master!$M$47:$M$55)} -> 1 | E16: 13 | F16: 3 | G16: 1 | H16: 0 | I16: 0 | J16: 0 | K16: 0 | L16: 0 | M16: =SUM(D16:I16) -> 18 | N16: =(M16/C16)*100 -> 100 | O16: =SUM(D16:K16) -> 18 | P16: =(O16/C16)*100 -> 100
A17: 7Y | B17: Cg Pieter | C17: =SUM(D17:L17) -> 20 | D17: {=TRANSPOSE([2]Master!$N$66:$N$74)} -> 4 | E17: 7 | F17: 4 | G17: 5 | H17: 0 | I17: 0 | J17: 0 | K17: 0 | L17: 0 | M17: =SUM(D17:I17) -> 20 | N17: =(M17/C17)*100 -> 100 | O17: =SUM(D17:K17) -> 20 | P17: =(O17/C17)*100 -> 100
A18: 7N | B18: Derek | C18: =SUM(D18:L18) -> 24 | D18: {=TRANSPOSE([3]Master!$N$66:$N$74)} -> 2 | E18: 8 | F18: 6 | G18: 6 | H18: 2 | I18: 0 | J18: 0 | K18: 0 | L18: 0 | M18: =SUM(D18:I18) -> 24 | N18: =(M18/C18)*100 -> 100 | O18: =SUM(D18:K18) -> 24 | P18: =(O18/C18)*100 -> 100
A19: 7A | B19: Cg Pieter | C19: =SUM(D19:L19) -> 25 | D19: {=TRANSPOSE([4]Master!$M$47:$M$55)} -> 0 | E19: 8 | F19: 7 | G19: 9 | H19: 0 | I19: 1 | J19: 0 | K19: 0 | L19: 0 | M19: =SUM(D19:I19) -> 25 | N19: =(M19/C19)*100 -> 100 | O19: =SUM(D19:K19) -> 25 | P19: =(O19/C19)*100 -> 100
A20: 7M | B20: Derek | C20: =SUM(D20:L20) -> 25 | D20: {=TRANSPOSE([5]Master!$N$66:$N$74)} -> 0 | E20: 10 | F20: 6 | G20: 1 | H20: 2 | I20: 5 | J20: 1 | K20: 0 | L20: 0 | M20: =SUM(D20:I20) -> 24 | N20: =(M20/C20)*100 -> 96 | O20: =SUM(D20:K20) -> 25 | P20: =(O20/C20)*100 -> 100
A21: 7I | B21: Cg Pieter | C21: =SUM(D21:L21) -> 24 | D21: {=TRANSPOSE([6]Master!$N$66:$N$74)} -> 2 | E21: 3 | F21: 3 | G21: 7 | H21: 4 | I21: 0 | J21: 3 | K21: 2 | L21: 0 | M21: =SUM(D21:I21) -> 19 | N21: =(M21/C21)*100 -> 79.166667 | O21: =SUM(D21:K21) -> 24 | P21: =(O21/C21)*100 -> 100
A22: 7C | B22: Cg Aimi | C22: =SUM(D22:L22) -> 20 | D22: {=TRANSPOSE([7]Master!$N$66:$N$74)} -> 0 | E22: 1 | F22: 0 | G22: 3 | H22: 4 | I22: 1 | J22: 4 | K22: 3 | L22: 4 | M22: =SUM(D22:I22) -> 9 | N22: =(M22/C22)*100 -> 45 | O22: =SUM(D22:K22) -> 16 | P22: =(O22/C22)*100 -> 80
B23: Overall | C23: =SUM(C16:C22) -> 156 | D23: =SUM(D16:D22) -> 9 | E23: =SUM(E16:E22) -> 50 | F23: =SUM(F16:F22) -> 29 | G23: =SUM(G16:G22) -> 32 | H23: =SUM(H16:H22) -> 12 | I23: =SUM(I16:I22) -> 7 | J23: =SUM(J16:J22) -> 8 | ... L23: =SUM(L16:L22) -> 4 | M23: =SUM(D23:I23) -> 139 | N23: =(M23/C23)*100 -> 89.102564 | O23: =SUM(D23:K23) -> 152 | P23: =(O23/C23)*100 -> 97.435897
A25: ISLAMIC RELIGIOUS KNOWLEDGE
D26: Distinction | F26: Credit | J26: Pass | L26: Fail
A27: Class | B27: Taught By | C27: Total | D27: A* | E27: A2 | F27: B3 | G27: B4 | H27: C5 | I27: C6 | J27: D7 | K27: E8 | L27: U | M27: Total 1-6 | N27: % 1-6 | O27: Total 1-8 | P27: % 1-8
A28: 7D | B28: NASYURUL ATIKAH | C28: =SUM(D28:L28) -> 18 | D28: {=TRANSPOSE([1]Master!$S$47:$S$55)} -> 10 | E28: 2 | F28: 4 | G28: 1 | H28: 0 | I28: 0 | J28: 1 | K28: 0 | L28: 0 | M28: =SUM(D28:I28) -> 17 | N28: =(M28/C28)*100 -> 94.444444 | O28: =SUM(D28:K28) -> 18 | P28: =(O28/C28)*100 -> 100
A29: 7Y | B29: KASUMAWATI | C29: =SUM(D29:L29) -> 20 | D29: {=TRANSPOSE([2]Master!$T$66:$T$74)} -> 6 | E29: 9 | F29: 3 | G29: 1 | H29: 0 | I29: 1 | J29: 0 | K29: 0 | L29: 0 | M29: =SUM(D29:I29) -> 20 | N29: =(M29/C29)*100 -> 100 | O29: =SUM(D29:K29) -> 20 | P29: =(O29/C29)*100 -> 100
A30: 7N | B30: NASYURUL ATIKAH | C30: =SUM(D30:L30) -> 24 | D30: {=TRANSPOSE([3]Master!$T$66:$T$74)} -> 1 | E30: 5 | F30: 5 | G30: 6 | H30: 1 | I30: 3 | J30: 2 | K30: 1 | L30: 0 | M30: =SUM(D30:I30) -> 21 | N30: =(M30/C30)*100 -> 87.5 | O30: =SUM(D30:K30) -> 24 | P30: =(O30/C30)*100 -> 100
A31: 7A | B31: KASUMAWATI | C31: =SUM(D31:L31) -> 25 | D31: {=TRANSPOSE([4]Master!$S$47:$S$55)} -> 10 | E31: 8 | F31: 2 | G31: 0 | H31: 3 | I31: 1 | J31: 1 | K31: 0 | L31: 0 | M31: =SUM(D31:I31) -> 24 | N31: =(M31/C31)*100 -> 96 | O31: =SUM(D31:K31) -> 25 | P31: =(O31/C31)*100 -> 100
A32: 7M | B32: KASUMAWATI | C32: =SUM(D32:L32) -> 25 | D32: {=TRANSPOSE([5]Master!$T$66:$T$74)} -> 6 | E32: 8 | F32: 0 | G32: 3 | H32: 4 | I32: 0 | J32: 2 | K32: 0 | L32: 2 | M32: =SUM(D32:I32) -> 21 | N32: =(M32/C32)*100 -> 84 | O32: =SUM(D32:K32) -> 23 | P32: =(O32/C32)*100 -> 92
A33: 7I | B33: NASYURUL ATIKAH | C33: =SUM(D33:L33) -> 24 | D33: {=TRANSPOSE([6]Master!$T$66:$T$74)} -> 0 | E33: 0 | F33: 1 | G33: 3 | H33: 3 | I33: 3 | J33: 6 | K33: 4 | L33: 4 | M33: =SUM(D33:I33) -> 10 | N33: =(M33/C33)*100 -> 41.666667 | O33: =SUM(D33:K33) -> 20 | P33: =(O33/C33)*100 -> 83.333333
A34: 7C | B34: KASUMAWATI | C34: =SUM(D34:L34) -> 20 | D34: {=TRANSPOSE([7]Master!$T$66:$T$74)} -> 1 | E34: 2 | F34: 0 | G34: 3 | H34: 2 | I34: 2 | J34: 1 | K34: 5 | L34: 4 | M34: =SUM(D34:I34) -> 10 | N34: =(M34/C34)*100 -> 50 | O34: =SUM(D34:K34) -> 16 | P34: =(O34/C34)*100 -> 80
B35: Overall | C35: =SUM(C28:C34) -> 156 | D35: =SUM(D28:D34) -> 34 | E35: =SUM(E28:E34) -> 34 | F35: =SUM(F28:F34) -> 15 | G35: =SUM(G28:G34) -> 17 | H35: =SUM(H28:H34) -> 13 | I35: =SUM(I28:I34) -> 10 | J35: =SUM(J28:J34) -> 13 | ... L35: =SUM(L28:L34) -> 10 | M35: =SUM(D35:I35) -> 123 | N35: =(M35/C35)*100 -> 78.846154 | O35: =SUM(D35:K35) -> 146 | P35: =(O35/C35)*100 -> 93.589744
A37: SOCIAL STUDIES
D38: Distinction | F38: Credit | J38: Pass | L38: Fail
A39: Class | B39: Taught By | C39: Total | D39: A* | E39: A2 | F39: B3 | G39: B4 | H39: C5 | I39: C6 | J39: D7 | K39: E8 | L39: U | M39: Total 1-6 | N39: % 1-6 | O39: Total 1-8 | P39: % 1-8
A40: 7D | B40: SUNARDI | C40: =SUM(D40:L40) -> 18 | D40: {=TRANSPOSE([1]Master!$Y$47:$Y$55)} -> 0 | E40: 7 | F40: 5 | G40: 2 | H40: 3 | I40: 1 | J40: 0 | K40: 0 | L40: 0 | M40: =SUM(D40:I40) -> 18 | N40: =(M40/C40)*100 -> 100 | O40: =SUM(D40:K40) -> 18 | P40: =(O40/C40)*100 -> 100
A41: 7Y | B41: PG HJH MARLINAWATI | C41: =SUM(D41:L41) -> 20 | D41: {=TRANSPOSE([2]Master!$Z$66:$Z$74)} -> 3 | E41: 6 | F41: 2 | G41: 5 | H41: 1 | I41: 0 | J41: 2 | K41: 1 | L41: 0 | M41: =SUM(D41:I41) -> 17 | N41: =(M41/C41)*100 -> 85 | O41: =SUM(D41:K41) -> 20 | P41: =(O41/C41)*100 -> 100
A42: 7N | B42: DK MARIEAH | C42: =SUM(D42:L42) -> 24 | D42: {=TRANSPOSE([3]Master!$Z$66:$Z$74)} -> 0 | E42: 1 | F42: 4 | G42: 6 | H42: 5 | I42: 3 | J42: 5 | K42: 0 | L42: 0 | M42: =SUM(D42:I42) -> 19 | N42: =(M42/C42)*100 -> 79.166667 | O42: =SUM(D42:K42) -> 24 | P42: =(O42/C42)*100 -> 100
A43: 7A | B43: DK MARIEAH | C43: =SUM(D43:L43) -> 25 | D43: {=TRANSPOSE([4]Master!$Y$47:$Y$55)} -> 0 | E43: 0 | F43: 0 | G43: 3 | H43: 5 | I43: 6 | J43: 10 | K43: 1 | L43: 0 | M43: =SUM(D43:I43) -> 14 | N43: =(M43/C43)*100 -> 56 | O43: =SUM(D43:K43) -> 25 | P43: =(O43/C43)*100 -> 100
...

Sheet CHART
A2: Subjects | B2: % 1-6 | C2: % 1-8
A3: Bahasa Melayu | B3: ='YEAR 7'!N11 -> 75.641026 | C3: ='YEAR 7'!P11 -> 94.871795
A4: English Language | B4: ='YEAR 7'!N23 -> 89.102564 | C4: ='YEAR 7'!P23 -> 97.435897
A5: I.R.K | B5: ='YEAR 7'!N35 -> 78.846154 | C5: ='YEAR 7'!P35 -> 93.589744
A6: Social Studies | B6: ='YEAR 7'!N109 -> 62.179487 | C6: ='YEAR 7'!P109 -> 92.307692
A7: Mathematics | B7: ='YEAR 7'!N59 -> 28.205128 | C7: ='YEAR 7'!P59 -> 53.846154
A8: Science | B8: ='YEAR 7'!N71 -> 56.687898 | C8: ='YEAR 7'!P71 -> 87.261146
A9: Bahasa Arab | B9: ='YEAR 7'!N80 -> 80.263158 | C9: ='YEAR 7'!P80 -> 96.052632
A10: Melayu Islam Beraja | B10: ='YEAR 7'!N92 -> 82.051282 | C10: ='YEAR 7'!P92 -> 94.230769
A11: Drama | B11: ='YEAR 7'!P99 -> 100 | C11: ='YEAR 7'!P99 -> 100

Sheet 3'O' and 5'O' & above
A1: YEAR 7, END OF YEAR EXAMINATION 2025
B3: No. of Candidates | C3: No. of Credits Obtained | L3: 5 'O' & above | N3: 3 'O' & above
C4: 8 | D4: 7 | E4: 6 | F4: 5 | G4: 4 | H4: 3 | I4: 2 | J4: 1 | K4: 0 | L4: No. of Candidates | M4: % | N4: No. of Candidates | O4: %
A5: 7D | B5: =SUM(C5:K5) -> 18 | C5: {=TRANSPOSE([1]Master!$BO$48:$BO$56)} -> 16 | D5: 1 | E5: 1 | F5: 0 | G5: 0 | H5: 0 | I5: 0 | J5: 0 | K5: 0 | L5: =SUM(C5:F5) -> 18 | M5: =L5/B5 -> 1 | N5: =SUM(C5:H5) -> 18 | O5: =N5/B5 -> 1
A6: 7Y | B6: =SUM(C6:K6) -> 21 | C6: {=TRANSPOSE([2]Master!$BJ$65:$BJ$73)} -> 0 | D6: 0 | E6: 0 | F6: 20 | G6: 0 | H6: 1 | I6: 0 | J6: 0 | K6: 0 | L6: =SUM(C6:F6) -> 20 | M6: =L6/B6 -> 0.95238095 | N6: =SUM(C6:H6) -> 21 | O6: =N6/B6 -> 1
A7: 7N | B7: =SUM(C7:K7) -> 24 | C7: {=TRANSPOSE([3]Master!$BB$67:$BB$75)} -> 6 | D7: 8 | E7: 4 | F7: 5 | G7: 1 | H7: 0 | I7: 0 | J7: 0 | K7: 0 | L7: =SUM(C7:F7) -> 23 | M7: =L7/B7 -> 0.95833333 | N7: =SUM(C7:H7) -> 24 | O7: =N7/B7 -> 1
A8: 7A | B8: =SUM(C8:K8) -> 25 | C8: {=TRANSPOSE([4]Master!$BO$48:$BO$56)} -> 3 | D8: 9 | E8: 7 | F8: 3 | G8: 2 | H8: 0 | I8: 0 | J8: 1 | K8: 0 | L8: =SUM(C8:F8) -> 22 | M8: =L8/B8 -> 0.88 | N8: =SUM(C8:H8) -> 24 | O8: =N8/B8 -> 0.96
A9: 7M | B9: =SUM(C9:K9) -> 25 | C9: {=TRANSPOSE([5]Master!$BP$65:$BP$73)} -> 0 | D9: 4 | E9: 6 | F9: 2 | G9: 6 | H9: 3 | I9: 4 | J9: 0 | K9: 0 | L9: =SUM(C9:F9) -> 12 | M9: =L9/B9 -> 0.48 | N9: =SUM(C9:H9) -> 21 | O9: =N9/B9 -> 0.84
A10: 7I | B10: =SUM(C10:K10) -> 24 | C10: {=TRANSPOSE([6]Master!$BP$66:$BP$74)} -> 0 | D10: 0 | E10: 0 | F10: 0 | G10: 2 | H10: 6 | I10: 8 | J10: 1 | K10: 7 | L10: =SUM(C10:F10) -> 0 | M10: =L10/B10 -> 0 | N10: =SUM(C10:H10) -> 8 | O10: =N10/B10 -> 0.33333333
A11: 7C | B11: =SUM(C11:K11) -> 20 | C11: {=TRANSPOSE([7]Master!$BP$67:$BP$75)} -> 0 | D11: 0 | E11: 1 | F11: 3 | G11: 0 | H11: 4 | I11: 3 | J11: 3 | K11: 6 | L11: =SUM(C11:F11) -> 4 | M11: =L11/B11 -> 0.2 | N11: =SUM(C11:H11) -> 8 | O11: =N11/B11 -> 0.4
A12: Total No. of Candidates | B12: =SUM(B5:B11) -> 157 | C12: =SUM(C5:C11) -> 25 | D12: =SUM(D5:D11) -> 22 | E12: =SUM(E5:E11) -> 19 | F12: =SUM(F5:F11) -> 33 | G12: =SUM(G5:G11) -> 11 | H12: =SUM(H5:H11) -> 14 | I12: =SUM(I5:I11) -> 15 | ... K12: =SUM(K5:K11) -> 13 | L12: =SUM(C12:F12) -> 99 | M12: =L12/B12 -> 0.63057325 | N12: =SUM(N5:N11) -> 124 | O12: =N12/B12 -> 0.78980892
A14: % obtained 5'O' & above | B14: =$M$12 -> 0.63057325
A15: % obtained 3'O' & above | B15: =$O$12 -> 0.78980892

Sheet No.of Credits Attained
A1: ='3''O'' and 5''O'' & above'!$A$1 -> YEAR 7, END OF YEAR EXAMINATION 2025
A3: No. Of Candidate Registered | E3: 200
A4: No. Of Candidate Sitting | E4: ='3''O'' and 5''O'' & above'!$B$12 -> 157
A5: Withdrawn | E5: 0
A7: Credit Attained | B7: No. Of Student | C7: %
A8: 8 | B8: ='3''O'' and 5''O'' & above'!$C$12 -> 25 | C8: =B8/B17 -> 0.15923567
A9: 7 | B9: ='3''O'' and 5''O'' & above'!$D$12 -> 22 | C9: =B9/B17 -> 0.14012739
A10: 6 | B10: ='3''O'' and 5''O'' & above'!$E$12 -> 19 | C10: =B10/B17 -> 0.12101911
A11: 5 | B11: ='3''O'' and 5''O'' & above'!$F$12 -> 33 | C11: =B11/B17 -> 0.21019108
A12: 4 | B12: ='3''O'' and 5''O'' & above'!$G$12 -> 11 | C12: =B12/B17 -> 0.070063694
A13: 3 | B13: ='3''O'' and 5''O'' & above'!$H12 -> 14 | C13: =B13/B17 -> 0.089171975
A14: 2 | B14: ='3''O'' and 5''O'' & above'!$I$12 -> 15 | C14: =B14/B17 -> 0.095541401
A15: 1 | B15: ='3''O'' and 5''O'' & above'!$J$12 -> 5 | C15: =B15/B17 -> 0.031847134
A16: 0 | B16: ='3''O'' and 5''O'' & above'!$K$12 -> 13 | C16: =B16/B17 -> 0.082802548
A17: Total | B17: =SUM(B8:B16) -> 157 | C17: =SUM(C8:C16) -> 1
C20: No. of Student | D20: %
A21: 3 or more Credits | C21: =SUM(B8:C13) -> 124.78981 | D21: =C21/B17 -> 0.79483955
A22: 4 or more Credits | C22: =SUM(B8:C12) -> 110.70064 | D22: =C22/B17 -> 0.7050996
A23: 5 or more Credits | C23: =SUM(B8:C11) -> 99.630573 | D23: =C23/B17 -> 0.63458964

Sheet class avg
A2: Class + No of stdn | B2: Class Avg
A3: 10Sci1
A4: 11Sci2
A5: 11Sci3
A6: 11P
A7: 11E
A8: 11A
A9: 11R
A10: 11L

Sheet By Class
A2: Menengah 4A
D3: Distinction | F3: Credit | J3: Pass | L3: Fail
A4: Subjects | B4: Taught By | C4: Total | D4: 1 | E4: 2 | F4: 3 | G4: 4 | H4: 5 | I4: 6 | J4: 7 | K4: 8 | L4: 9 | M4: Total 1-6 | N4: % 1-6 | O4: Total 1-8 | P4: % 1-8
A5: B.Melayu | N5: =((M5/C5)*100) -> #DIV/0! | O5: =SUM(D5:K5) -> 0 | P5: =((O5/C5)*100) -> #DIV/0!
A6: English | N6: =((M6/C6)*100) -> #DIV/0! | O6: =SUM(D6:K6) -> 0 | P6: =((O6/C6)*100) -> #DIV/0!
A7: Maths | N7: =((M7/C7)*100) -> #DIV/0! | O7: =SUM(D7:K7) -> 0 | P7: =((O7/C7)*100) -> #DIV/0!
A8: Add Maths | N8: =((M8/C8)*100) -> #DIV/0! | O8: =SUM(D8:K8) -> 0 | P8: =((O8/C8)*100) -> #DIV/0!
A9: Physics | N9: =((M9/C9)*100) -> #DIV/0! | O9: =SUM(D9:K9) -> 0 | P9: =((O9/C9)*100) -> #DIV/0!
A10: Chemistry | N10: =((M10/C10)*100) -> #DIV/0! | O10: =SUM(D10:K10) -> 0 | P10: =((O10/C10)*100) -> #DIV/0!
A11: Biology | N11: =((M11/C11)*100) -> #DIV/0! | O11: =SUM(D11:K11) -> 0 | P11: =((O11/C11)*100) -> #DIV/0!
A12: Geography | N12: =((M12/C12)*100) -> #DIV/0! | O12: =SUM(D12:K12) -> 0 | P12: =((O12/C12)*100) -> #DIV/0!
A13: Computer | N13: =((M13/C13)*100) -> #DIV/0! | O13: =SUM(D13:K13) -> 0 | P13: =((O13/C13)*100) -> #DIV/0!
N14: =AVERAGE(N5:N13) -> #DIV/0! | P14: =AVERAGE(P5:P13) -> #DIV/0!
A16: Menengah 4B
D17: Distinction | F17: Credit | J17: Pass | L17: Fail
A18: Subjects | B18: Taught By | C18: Total | D18: 1 | E18: 2 | F18: 3 | G18: 4 | H18: 5 | I18: 6 | J18: 7 | K18: 8 | L18: 9 | M18: Total 1-6 | N18: % 1-6 | O18: Total 1-8 | P18: % 1-8
A19: B.Melayu | N19: =((M19/C19)*100) -> #DIV/0! | O19: =SUM(D19:K19) -> 0 | P19: =((O19/C19)*100) -> #DIV/0!
A20: English | N20: =((M20/C20)*100) -> #DIV/0! | O20: =SUM(D20:K20) -> 0 | P20: =((O20/C20)*100) -> #DIV/0!
A21: Maths | N21: =((M21/C21)*100) -> #DIV/0! | O21: =SUM(D21:K21) -> 0 | P21: =((O21/C21)*100) -> #DIV/0!
A22: Physics | N22: =((M22/C22)*100) -> #DIV/0! | O22: 10 | P22: =((O22/C22)*100) -> #DIV/0!
A23: Chemistry | N23: =((M23/C23)*100) -> #DIV/0! | O23: 10 | P23: =((O23/C23)*100) -> #DIV/0!
A24: Biology | N24: =((M24/C24)*100) -> #DIV/0! | O24: 19 | P24: =((O24/C24)*100) -> #DIV/0!
A25: Geography | N25: =((M25/C25)*100) -> #DIV/0! | O25: 19 | P25: =((O25/C25)*100) -> #DIV/0!
A26: Economics | N26: =((M26/C26)*100) -> #DIV/0! | O26: 3 | P26: =((O26/C26)*100) -> #DIV/0!
A27: Computer | N27: =((M27/C27)*100) -> #DIV/0! | O27: 2 | P27: =((O27/C27)*100) -> #DIV/0!
A28: POA | N28: =((M28/C28)*100) -> #DIV/0! | O28: 12 | P28: =((O28/C28)*100) -> #DIV/0!
N29: =AVERAGE(N19:N28) -> #DIV/0! | P29: =AVERAGE(P19:P28) -> #DIV/0!
A31: Menengah 4C
D32: Distinction | F32: Credit | J32: Pass | L32: Fail
A33: Subjects | B33: Taught By | C33: Total | D33: 1 | E33: 2 | F33: 3 | G33: 4 | H33: 5 | I33: 6 | J33: 7 | K33: 8 | L33: 9 | M33: Total 1-6 | N33: % 1-6 | O33: Total 1-8 | P33: % 1-8
A34: B.Melayu | N34: =((M34/C34)*100) -> #DIV/0! | O34: 18 | P34: =((O34/C34)*100) -> #DIV/0!
A35: English | N35: =((M35/C35)*100) -> #DIV/0! | O35: 15 | P35: =((O35/C35)*100) -> #DIV/0!
A36: Maths | N36: =((M36/C36)*100) -> #DIV/0! | O36: 9 | P36: =((O36/C36)*100) -> #DIV/0!
A37: Comb Sc | N37: =((M37/C37)*100) -> #DIV/0! | O37: 6 | P37: =((O37/C37)*100) -> #DIV/0!
A38: Geography | N38: =((M38/C38)*100) -> #DIV/0! | O38: 7 | P38: =((O38/C38)*100) -> #DIV/0!
A39: History | N39: =((M39/C39)*100) -> #DIV/0! | O39: 14 | P39: =((O39/C39)*100) -> #DIV/0!
A40: IRK | N40: =((M40/C40)*100) -> #DIV/0! | O40: 16 | P40: =((O40/C40)*100) -> #DIV/0!
A41: Commerce | N41: =((M41/C41)*100) -> #DIV/0! | O41: 14 | P41: =((O41/C41)*100) -> #DIV/0!
A42: Agr Sc | N42: =((M42/C42)*100) -> #DIV/0! | O42: 2 | P42: =((O42/C42)*100) -> #DIV/0!
N43: =AVERAGE(N34:N42) -> #DIV/0! | P43: =AVERAGE(P34:P42) -> #DIV/0!
...
