Workbook

Sheet YEAR 8 SPA
A1: BAHASA MELAYU
D2: Distinction | F2: Credit | J2: Pass | L2: Fail
A3: Class | B3: Taught By | C3: Total | D3: A* | E3: A2 | F3: B3 | G3: B4 | H3: C5 | I3: C6 | J3: D7 | K3: E8 | L3: U | M3: Total 1-6 | N3: % 1-6 | O3: Total 1-8 | P3: % 1-8
A4: 8C | B4: Cg Siti izyan | C4: =SUM(D4:L4) -> 20 | D4: {=TRANSPOSE([1]MASTER!$Q$34:$Q$42)} -> 0 | E4: 2 | F4: 12 | G4: 4 | H4: 2 | I4: 0 | J4: 0 | K4: 0 | L4: 0 | M4: =SUM(D4:I4) -> 20 | N4: =((M4/C4)*100) -> 100 | O4: =SUM(D4:K4) -> 20 | P4: =((O4/C4)*100) -> 100
A5: 8H | B5: Cg Ermawati | C5: =SUM(D5:L5) -> 20 | D5: {=TRANSPOSE([2]MASTER!$Q$34:$Q$42)} -> 0 | E5: 0 | F5: 4 | G5: 8 | H5: 7 | I5: 1 | J5: 0 | K5: 0 | L5: 0 | M5: =SUM(D5:I5) -> 20 | N5: =((M5/C5)*100) -> 100 | O5: =SUM(D5:K5) -> 20 | P5: =((O5/C5)*100) -> 100
A6: 8A | B6: Cg Noni Ratina | C6: =SUM(D6:L6) -> 35 | D6: {=TRANSPOSE([3]MASTER!$Q$49:$Q$57)} -> 0 | E6: 0 | F6: 4 | G6: 8 | H6: 7 | I6: 2 | J6: 2 | K6: 0 | L6: 12 | M6: =SUM(D6:I6) -> 21 | N6: =((M6/C6)*100) -> 60 | O6: =SUM(D6:K6) -> 23 | P6: =((O6/C6)*100) -> 65.714286
A7: 8M | B7: Cg Noni Ratina | C7: =SUM(D7:L7) -> 24 | D7: {=TRANSPOSE([4]MASTER!$Q$56:$Q$64)} -> 0 | E7: 1 | F7: 3 | G7: 8 | H7: 4 | I7: 7 | J7: 1 | K7: 0 | L7: 0 | M7: =SUM(D7:I7) -> 23 | N7: =((M7/C7)*100) -> 95.833333 | O7: =SUM(D7:K7) -> 24 | P7: =((O7/C7)*100) -> 100
A8: 8P | B8: Cg Ermawati | C8: =SUM(D8:L8) -> 25 | D8: {=TRANSPOSE([5]MASTER!$Q$44:$Q$52)} -> 0 | E8: 0 | F8: 2 | G8: 4 | H8: 8 | I8: 5 | J8: 5 | K8: 0 | L8: 1 | M8: =SUM(D8:I8) -> 19 | N8: =((M8/C8)*100) -> 76 | O8: =SUM(D8:K8) -> 24 | P8: =((O8/C8)*100) -> 96
A9: 8I | B9: Cg Siti izyan | C9: =SUM(D9:L9) -> 24 | D9: {=TRANSPOSE([6]MASTER!$Q$56:$Q$64)} -> 0 | E9: 0 | F9: 0 | G9: 3 | H9: 5 | I9: 8 | J9: 5 | K9: 3 | L9: 0 | M9: =SUM(D9:I9) -> 16 | N9: =((M9/C9)*100) -> 66.666667 | O9: =SUM(D9:K9) -> 24 | P9: =((O9/C9)*100) -> 100
A10: 8O | B10: Cg Siti Izyan | C10: =SUM(D10:L10) -> 15 | D10: {=TRANSPOSE([7]MASTER!$Q$29:$Q$37)} -> 0 | E10: 0 | F10: 0 | G10: 0 | H10: 2 | I10: 3 | J10: 7 | K10: 1 | L10: 2 | M10: =SUM(D10:I10) -> 5 | N10: =((M10/C10)*100) -> 33.333333 | O10: =SUM(D10:K10) -> 13 | P10: =((O10/C10)*100) -> 86.666667
A11: 8N | B11: Cg Ermawati | C11: =SUM(D11:L11) -> 12 | D11: {=TRANSPOSE([8]MASTER!$Q$26:$Q$34)} -> 0 | E11: 0 | F11: 0 | G11: 0 | H11: 0 | I11: 0 | J11: 6 | K11: 4 | L11: 2 | M11: =SUM(D11:I11) -> 0 | N11: =((M11/C11)*100) -> 0 | O11: =SUM(D11:K11) -> 10 | P11: =((O11/C11)*100) -> 83.333333
B12: Overall | C12: =SUM(C4:C10) -> 163 | D12: =SUM(D4:D10) -> 0 | E12: =SUM(E4:E10) -> 3 | F12: =SUM(F4:F10) -> 25 | G12: =SUM(G4:G10) -> 35 | H12: =SUM(H4:H10) -> 35 | I12: =SUM(I4:I10) -> 26 | J12: =SUM(J4:J10) -> 20 | ... L12: =SUM(L4:L10) -> 15 | M12: =SUM(D12:I12) -> 124 | N12: =((M12/C12)*100) -> 76.07362 | O12: =SUM(D12:K12) -> 148 | P12: =((O12/C12)*100) -> 90.797546
A14: ENGLISH LANGUAGE
D15: Distinction | F15: Credit | J15: Pass | L15: Fail
A16: Class | B16: Taught By | C16: Total | D16: A* | E16: A2 | F16: B3 | G16: B4 | H16: C5 | I16: C6 | J16: D7 | K16: E8 | L16: U | M16: Total 1-6 | N16: % 1-6 | O16: Total 1-8 | P16: % 1-8
A17: 8C | B17: Derek | C17: =SUM(D17:L17) -> 20 | D17: {=TRANSPOSE([1]MASTER!$Z$34:$Z$42)} -> 3 | E17: 11 | F17: 6 | G17: 0 | H17: 0 | I17: 0 | J17: 0 | K17: 0 | L17: 0 | M17: =SUM(D17:I17) -> 20 | N17: =((M17/C17)*100) -> 100 | O17: =SUM(D17:K17) -> 20 | P17: =((O17/C17)*100) -> 100
A18: 8H | B18: Cg Pieter | C18: =SUM(D18:L18) -> 20 | D18: {=TRANSPOSE([2]MASTER!$Z$34:$Z$42)} -> 1 | E18: 10 | F18: 1 | G18: 5 | H18: 3 | I18: 0 | J18: 0 | K18: 0 | L18: 0 | M18: =SUM(D18:I18) -> 20 | N18: =((M18/C18)*100) -> 100 | O18: =SUM(D18:K18) -> 20 | P18: =((O18/C18)*100) -> 100
A19: 8A | B19: Derek | C19: =SUM(D19:L19) -> 23 | D19: {=TRANSPOSE([3]MASTER!$Z$49:$Z$57)} -> 0 | E19: 3 | F19: 14 | G19: 6 | H19: 0 | I19: 0 | J19: 0 | K19: 0 | L19: 0 | M19: =SUM(D19:I19) -> 23 | N19: =((M19/C19)*100) -> 100 | O19: =SUM(D19:K19) -> 23 | P19: =((O19/C19)*100) -> 100
A20: 8M | B20: Cg Pieter | C20: =SUM(D20:L20) -> 24 | D20: {=TRANSPOSE([4]MASTER!$Z$56:$Z$64)} -> 0 | E20: 6 | F20: 3 | G20: 8 | H20: 5 | I20: 1 | J20: 1 | K20: 0 | L20: 0 | M20: =SUM(D20:I20) -> 23 | N20: =((M20/C20)*100) -> 95.833333 | O20: =SUM(D20:K20) -> 24 | P20: =((O20/C20)*100) -> 100
A21: 8P | B21: Derek | C21: =SUM(D21:L21) -> 25 | D21: {=TRANSPOSE([5]MASTER!$Z$44:$Z$52)} -> 0 | E21: 4 | F21: 6 | G21: 5 | H21: 6 | I21: 1 | J21: 3 | K21: 0 | L21: 0 | M21: =SUM(D21:I21) -> 22 | N21: =((M21/C21)*100) -> 88 | O21: =SUM(D21:K21) -> 25 | P21: =((O21/C21)*100) -> 100
A22: 8I | B22: Aimi | C22: =SUM(D22:L22) -> 24 | D22: {=TRANSPOSE([6]MASTER!$Z$56:$Z$64)} -> 0 | E22: 0 | F22: 2 | G22: 6 | H22: 6 | I22: 2 | J22: 8 | K22: 0 | L22: 0 | M22: =SUM(D22:I22) -> 16 | N22: =((M22/C22)*100) -> 66.666667 | O22: =SUM(D22:K22) -> 24 | P22: =((O22/C22)*100) -> 100
A23: 8O | B23: Dk Hjh Sri Hani | C23: =SUM(D23:L23) -> 15 | D23: {=TRANSPOSE([7]MASTER!$Z$29:$Z$37)} -> 0 | E23: 0 | F23: 0 | G23: 1 | H23: 1 | I23: 3 | J23: 7 | K23: 2 | L23: 1 | M23: =SUM(D23:I23) -> 5 | N23: =((M23/C23)*100) -> 33.333333 | O23: =SUM(D23:K23) -> 14 | P23: =((O23/C23)*100) -> 93.333333
A24: 8N | B24: Aimi | C24: =SUM(D24:L24) -> 12 | D24: {=TRANSPOSE([8]MASTER!$Z$26:$Z$34)} -> 0 | E24: 0 | F24: 0 | G24: 0 | H24: 1 | I24: 1 | J24: 1 | K24: 5 | L24: 4 | M24: =SUM(D24:I24) -> 2 | N24: =((M24/C24)*100) -> 16.666667 | O24: =SUM(D24:K24) -> 8 | P24: =((O24/C24)*100) -> 66.666667
B25: Overall | C25: =SUM(C17:C23) -> 151 | D25: =SUM(D17:D23) -> 4 | E25: =SUM(E17:E23) -> 34 | F25: =SUM(F17:F23) -> 32 | G25: =SUM(G17:G23) -> 31 | H25: =SUM(H17:H23) -> 21 | I25: =SUM(I17:I23) -> 7 | J25: =SUM(J17:J23) -> 19 | ... L25: =SUM(L17:L23) -> 1 | M25: =SUM(D25:I25) -> 129 | N25: =((M25/C25)*100) -> 85.430464 | O25: =SUM(D25:K25) -> 150 | P25: =((O25/C25)*100) -> 99.337748
A27: ISLAMIC RELIGIOUS KNOWLEDGE
D28: Distinction | F28: Credit | J28: Pass | L28: Fail
A29: Class | B29: Taught By | C29: Total | D29: A* | E29: A2 | F29: B3 | G29: B4 | H29: C5 | I29: C6 | J29: D7 | K29: E8 | L29: U | M29: Total 1-6 | N29: % 1-6 | O29: Total 1-8 | P29: % 1-8
A30: 8C | B30: HJ AZMI | C30: =SUM(D30:L30) -> 20 | D30: {=TRANSPOSE([1]MASTER!$BA$34:$BA$42)} -> 2 | E30: 6 | F30: 10 | G30: 1 | H30: 1 | I30: 0 | J30: 0 | K30: 0 | L30: 0 | M30: =SUM(D30:I30) -> 20 | N30: =((M30/C30)*100) -> 100 | O30: =SUM(D30:K30) -> 20 | P30: =((O30/C30)*100) -> 100
A31: 8H | B31: HJ AZMI | C31: =SUM(D31:L31) -> 20 | D31: {=TRANSPOSE([2]MASTER!$BA$34:$BA$42)} -> 2 | E31: 10 | F31: 1 | G31: 2 | H31: 1 | I31: 2 | J31: 1 | K31: 1 | L31: 0 | M31: =SUM(D31:I31) -> 18 | N31: =((M31/C31)*100) -> 90 | O31: =SUM(D31:K31) -> 20 | P31: =((O31/C31)*100) -> 100
A32: 8A | B32: HJH FAUZIAHWATI | C32: =SUM(D32:L32) -> 35 | D32: {=TRANSPOSE([3]MASTER!$BA$49:$BA$57)} -> 0 | E32: 9 | F32: 3 | G32: 7 | H32: 1 | I32: 2 | J32: 1 | K32: 0 | L32: 12 | M32: =SUM(D32:I32) -> 22 | N32: =((M32/C32)*100) -> 62.857143 | O32: =SUM(D32:K32) -> 23 | P32: =((O32/C32)*100) -> 65.714286
A33: 8M | B33: HJH FAUZIAHWATI | C33: =SUM(D33:L33) -> 24 | D33: {=TRANSPOSE([4]MASTER!$BA$56:$BA$64)} -> 1 | E33: 3 | F33: 2 | G33: 5 | H33: 3 | I33: 2 | J33: 5 | K33: 2 | L33: 1 | M33: =SUM(D33:I33) -> 16 | N33: =((M33/C33)*100) -> 66.666667 | O33: =SUM(D33:K33) -> 23 | P33: =((O33/C33)*100) -> 95.833333
A34: 8P | B34: HJ AZMI | C34: =SUM(D34:L34) -> 25 | D34: {=TRANSPOSE([5]MASTER!$BA$44:$BA$52)} -> 2 | E34: 2 | F34: 2 | G34: 4 | H34: 2 | I34: 1 | J34: 7 | K34: 1 | L34: 4 | M34: =SUM(D34:I34) -> 13 | N34: =((M34/C34)*100) -> 52 | O34: =SUM(D34:K34) -> 21 | P34: =((O34/C34)*100) -> 84
A35: 8I | B35: HJH FAUZIAHWATI | C35: =SUM(D35:L35) -> 24 | D35: {=TRANSPOSE([6]MASTER!$BA$56:$BA$64)} -> 0 | E35: 1 | F35: 2 | G35: 3 | H35: 0 | I35: 5 | J35: 7 | K35: 2 | L35: 4 | M35: =SUM(D35:I35) -> 11 | N35: =((M35/C35)*100) -> 45.833333 | O35: =SUM(D35:K35) -> 20 | P35: =((O35/C35)*100) -> 83.333333
A36: 8O | B36: HJ AZMI | C36: =SUM(D36:L36) -> 15 | D36: {=TRANSPOSE([7]MASTER!$BA$29:$BA$37)} -> 0 | E36: 0 | F36: 0 | G36: 0 | H36: 2 | I36: 0 | J36: 2 | K36: 5 | L36: 6 | M36: 9 | N36: =((M36/C36)*100) -> 60 | O36: =SUM(D36:K36) -> 9 | P36: =((O36/C36)*100) -> 60
A37: 8N | B37: HJH FAUZIAHWATI | C37: =SUM(D37:L37) -> 12 | D37: {=TRANSPOSE([8]MASTER!$BA$26:$BA$34)} -> 0 | E37: 0 | F37: 0 | G37: 0 | H37: 0 | I37: 0 | J37: 2 | K37: 1 | L37: 9 | M37: 9 | N37: =((M37/C37)*100) -> 75 | O37: =SUM(D37:K37) -> 3 | P37: =((O37/C37)*100) -> 25
B38: Overall | C38: =SUM(C30:C36) -> 163 | D38: =SUM(D30:D36) -> 7 | E38: =SUM(E30:E36) -> 31 | F38: =SUM(F30:F36) -> 20 | G38: =SUM(G30:G36) -> 22 | H38: =SUM(H30:H36) -> 10 | I38: =SUM(I30:I36) -> 12 | J38: =SUM(J30:J36) -> 23 | ... L38: =SUM(L30:L36) -> 27 | M38: =SUM(D38:I38) -> 102 | N38: =((M38/C38)*100) -> 62.576687 | O38: =SUM(D38:K38) -> 136 | P38: =((O38/C38)*100) -> 83.435583
A40: SOCIAL STUDIES
D41: Distinction | F41: Credit | J41: Pass | L41: Fail
A42: Class | B42: Taught By | C42: Total | D42: A* | E42: A2 | F42: B3 | G42: B4 | H42: C5 | I42: C6 | J42: D7 | K42: E8 | L42: U | M42: Total 1-6 | N42: % 1-6 | O42: Total 1-8 | P42: % 1-8
A43: 8C | B43: DK MARIEAH | C43: =SUM(D43:L43) -> 20 | D43: {=TRANSPOSE([1]MASTER!$BS$34:$BS$42)} -> 0 | E43: 5 | F43: 6 | G43: 7 | H43: 1 | I43: 1 | J43: 0 | K43: 0 | L43: 0 | M43: =SUM(D43:I43) -> 20 | N43: =((M43/C43)*100) -> 100 | O43: =SUM(D43:K43) -> 20 | P43: =((O43/C43)*100) -> 100
...

Sheet YEAR 8 SPE
A1: BAHASA MELAYU
D2: Distinction | F2: Credit | J2: Pass | L2: Fail
A3: Class | B3: Taught By | C3: Total | D3: A* | E3: A2 | F3: B3 | G3: B4 | H3: C5 | I3: C6 | J3: D7 | K3: E8 | L3: U | M3: Total 1-6 | N3: % 1-6 | O3: Total 1-8 | P3: % 1-8
A4: 8C | B4: Cg Siti izyan | C4: =SUM(D4:L4) -> 20 | D4: {=TRANSPOSE([9]MASTER!$Q$34:$Q$42)} -> 0 | E4: 4 | F4: 11 | G4: 4 | H4: 1 | I4: 0 | J4: 0 | K4: 0 | L4: 0 | M4: =SUM(D4:I4) -> 20 | N4: =((M4/C4)*100) -> 100 | O4: =SUM(D4:K4) -> 20 | P4: =((O4/C4)*100) -> 100
A5: 8H | B5: Cg Ermawati | C5: =SUM(D5:L5) -> 20 | D5: {=TRANSPOSE([12]MASTER!$Q$34:$Q$42)} -> 0 | E5: 0 | F5: 4 | G5: 7 | H5: 8 | I5: 1 | J5: 0 | K5: 0 | L5: 0 | M5: =SUM(D5:I5) -> 20 | N5: =((M5/C5)*100) -> 100 | O5: =SUM(D5:K5) -> 20 | P5: =((O5/C5)*100) -> 100
A6: 8A | B6: Cg Noni Ratina | C6: =SUM(D6:L6) -> 23 | D6: {=TRANSPOSE([10]MASTER!$Q$49:$Q$57)} -> 0 | E6: 0 | F6: 1 | G6: 5 | H6: 5 | I6: 8 | J6: 4 | K6: 0 | L6: 0 | M6: =SUM(D6:I6) -> 19 | N6: =((M6/C6)*100) -> 82.608696 | O6: =SUM(D6:K6) -> 23 | P6: =((O6/C6)*100) -> 100
A7: 8M | B7: Cg Noni Ratina | C7: =SUM(D7:L7) -> 24 | D7: {=TRANSPOSE([11]MASTER!$Q$56:$Q$64)} -> 0 | E7: 2 | F7: 1 | G7: 6 | H7: 5 | I7: 6 | J7: 4 | K7: 0 | L7: 0 | M7: =SUM(D7:I7) -> 20 | N7: =((M7/C7)*100) -> 83.333333 | O7: =SUM(D7:K7) -> 24 | P7: =((O7/C7)*100) -> 100
A8: 8P | B8: Cg Ermawati | C8: =SUM(D8:L8) -> 25 | D8: {=TRANSPOSE([13]MASTER!$Q$44:$Q$52)} -> 0 | E8: 0 | F8: 2 | G8: 4 | H8: 8 | I8: 5 | J8: 5 | K8: 0 | L8: 1 | M8: =SUM(D8:I8) -> 19 | N8: =((M8/C8)*100) -> 76 | O8: =SUM(D8:K8) -> 24 | P8: =((O8/C8)*100) -> 96
A9: 8I | B9: Cg Siti izyan | C9: =SUM(D9:L9) -> 24 | D9: {=TRANSPOSE([14]MASTER!$Q$56:$Q$64)} -> 0 | E9: 0 | F9: 0 | G9: 4 | H9: 4 | I9: 9 | J9: 6 | K9: 1 | L9: 0 | M9: =SUM(D9:I9) -> 17 | N9: =((M9/C9)*100) -> 70.833333 | O9: =SUM(D9:K9) -> 24 | P9: =((O9/C9)*100) -> 100
A10: 8O | B10: Cg Siti Izyan | C10: =SUM(D10:L10) -> 15 | D10: {=TRANSPOSE([15]MASTER!$Q$29:$Q$37)} -> 0 | E10: 0 | F10: 0 | G10: 0 | H10: 4 | I10: 2 | J10: 7 | K10: 0 | L10: 2 | M10: =SUM(D10:I10) -> 6 | N10: =((M10/C10)*100) -> 40 | O10: =SUM(D10:K10) -> 13 | P10: =((O10/C10)*100) -> 86.666667
A11: 8N | B11: Cg Ermawati | C11: =SUM(D11:L11) -> 12 | D11: {=TRANSPOSE([16]MASTER!$Q$26:$Q$34)} -> 0 | E11: 0 | F11: 0 | G11: 0 | H11: 0 | I11: 0 | J11: 6 | K11: 3 | L11: 3 | M11: =SUM(D11:I11) -> 0 | N11: =((M11/C11)*100) -> 0 | O11: =SUM(D11:K11) -> 9 | P11: =((O11/C11)*100) -> 75
B12: Overall | C12: =SUM(C4:C11) -> 163 | D12: =SUM(D4:D11) -> 0 | E12: =SUM(E4:E11) -> 6 | F12: =SUM(F4:F11) -> 19 | G12: =SUM(G4:G11) -> 30 | H12: =SUM(H4:H11) -> 35 | I12: =SUM(I4:I11) -> 31 | J12: =SUM(J4:J11) -> 32 | ... L12: =SUM(L4:L11) -> 6 | M12: =SUM(D12:I12) -> 121 | N12: =((M12/C12)*100) -> 74.233129 | O12: =SUM(D12:K12) -> 157 | P12: =((O12/C12)*100) -> 96.319018
A14: ENGLISH LANGUAGE
D15: Distinction | F15: Credit | J15: Pass | L15: Fail
A16: Class | B16: Taught By | C16: Total | D16: A* | E16: A2 | F16: B3 | G16: B4 | H16: C5 | I16: C6 | J16: D7 | K16: E8 | L16: U | M16: Total 1-6 | N16: % 1-6 | O16: Total 1-8 | P16: % 1-8
A17: 8C | B17: Derek | C17: =SUM(D17:L17) -> 20 | D17: {=TRANSPOSE([9]MASTER!$Z$34:$Z$42)} -> 8 | E17: 12 | F17: 0 | G17: 0 | H17: 0 | I17: 0 | J17: 0 | K17: 0 | L17: 0 | M17: =SUM(D17:I17) -> 20 | N17: =((M17/C17)*100) -> 100 | O17: =SUM(D17:K17) -> 20 | P17: =((O17/C17)*100) -> 100
A18: 8H | B18: Cg Pieter | C18: =SUM(D18:L18) -> 20 | D18: {=TRANSPOSE([12]MASTER!$Z$34:$Z$42)} -> 3 | E18: 8 | F18: 1 | G18: 6 | H18: 2 | I18: 0 | J18: 0 | K18: 0 | L18: 0 | M18: =SUM(D18:I18) -> 20 | N18: =((M18/C18)*100) -> 100 | O18: =SUM(D18:K18) -> 20 | P18: =((O18/C18)*100) -> 100
A19: 8A | B19: Derek | C19: =SUM(D19:L19) -> 23 | D19: {=TRANSPOSE([10]MASTER!$Z$49:$Z$57)} -> 1 | E19: 17 | F19: 4 | G19: 1 | H19: 0 | I19: 0 | J19: 0 | K19: 0 | L19: 0 | M19: =SUM(D19:I19) -> 23 | N19: =((M19/C19)*100) -> 100 | O19: =SUM(D19:K19) -> 23 | P19: =((O19/C19)*100) -> 100
A20: 8M | B20: Cg Pieter | C20: =SUM(D20:L20) -> 24 | D20: {=TRANSPOSE([11]MASTER!$Z$56:$Z$64)} -> 3 | E20: 6 | F20: 7 | G20: 6 | H20: 1 | I20: 1 | J20: 0 | K20: 0 | L20: 0 | M20: =SUM(D20:I20) -> 24 | N20: =((M20/C20)*100) -> 100 | O20: =SUM(D20:K20) -> 24 | P20: =((O20/C20)*100) -> 100
A21: 8P | B21: Derek | C21: =SUM(D21:L21) -> 25 | D21: {=TRANSPOSE([13]MASTER!$Z$44:$Z$52)} -> 0 | E21: 4 | F21: 6 | G21: 5 | H21: 6 | I21: 1 | J21: 3 | K21: 0 | L21: 0 | M21: =SUM(D21:I21) -> 22 | N21: =((M21/C21)*100) -> 88 | O21: =SUM(D21:K21) -> 25 | P21: =((O21/C21)*100) -> 100
A22: 8I | B22: Aimi | C22: =SUM(D22:L22) -> 24 | D22: {=TRANSPOSE([14]MASTER!$Z$56:$Z$64)} -> 0 | E22: 0 | F22: 3 | G22: 6 | H22: 5 | I22: 5 | J22: 5 | K22: 0 | L22: 0 | M22: =SUM(D22:I22) -> 19 | N22: =((M22/C22)*100) -> 79.166667 | O22: =SUM(D22:K22) -> 24 | P22: =((O22/C22)*100) -> 100
A23: 8O | B23: Dk Hjh Sri Hani | C23: =SUM(D23:L23) -> 15 | D23: {=TRANSPOSE([15]MASTER!$Z$29:$Z$37)} -> 0 | E23: 0 | F23: 1 | G23: 2 | H23: 1 | I23: 5 | J23: 5 | K23: 0 | L23: 1 | M23: =SUM(D23:I23) -> 9 | N23: =((M23/C23)*100) -> 60 | O23: =SUM(D23:K23) -> 14 | P23: =((O23/C23)*100) -> 93.333333
A24: 8N | B24: Aimi | C24: =SUM(D24:L24) -> 12 | D24: {=TRANSPOSE([16]MASTER!$Z$26:$Z$34)} -> 0 | E24: 0 | F24: 0 | G24: 0 | H24: 2 | I24: 0 | J24: 2 | K24: 4 | L24: 4 | M24: =SUM(D24:I24) -> 2 | N24: =((M24/C24)*100) -> 16.666667 | O24: =SUM(D24:K24) -> 8 | P24: =((O24/C24)*100) -> 66.666667
B25: Overall | C25: =SUM(C17:C24) -> 163 | D25: =SUM(D17:D24) -> 15 | E25: =SUM(E17:E24) -> 47 | F25: =SUM(F17:F24) -> 22 | G25: =SUM(G17:G24) -> 26 | H25: =SUM(H17:H24) -> 17 | I25: =SUM(I17:I24) -> 12 | J25: =SUM(J17:J24) -> 15 | ... L25: =SUM(L17:L24) -> 5 | M25: =SUM(D25:I25) -> 139 | N25: =((M25/C25)*100) -> 85.276074 | O25: =SUM(D25:K25) -> 158 | P25: =((O25/C25)*100) -> 96.932515
A27: ISLAMIC RELIGIOUS KNOWLEDGE
D28: Distinction | F28: Credit | J28: Pass | L28: Fail
A29: Class | B29: Taught By | C29: Total | D29: A* | E29: A2 | F29: B3 | G29: B4 | H29: C5 | I29: C6 | J29: D7 | K29: E8 | L29: U | M29: Total 1-6 | N29: % 1-6 | O29: Total 1-8 | P29: % 1-8
A30: 8C | B30: HJ AZMI | C30: =SUM(D30:L30) -> 20 | D30: {=TRANSPOSE([9]MASTER!$BA$34:$BA$42)} -> 8 | E30: 8 | F30: 3 | G30: 1 | H30: 0 | I30: 0 | J30: 0 | K30: 0 | L30: 0 | M30: =SUM(D30:I30) -> 20 | N30: =((M30/C30)*100) -> 100 | O30: =SUM(D30:K30) -> 20 | P30: =((O30/C30)*100) -> 100
A31: 8H | B31: HJ AZMI | C31: =SUM(D31:L31) -> 20 | D31: {=TRANSPOSE([12]MASTER!$BA$34:$BA$42)} -> 11 | E31: 4 | F31: 1 | G31: 1 | H31: 0 | I31: 0 | J31: 3 | K31: 0 | L31: 0 | M31: =SUM(D31:I31) -> 17 | N31: =((M31/C31)*100) -> 85 | O31: =SUM(D31:K31) -> 20 | P31: =((O31/C31)*100) -> 100
A32: 8A | B32: HJH FAUZIAHWATI | C32: =SUM(D32:L32) -> 23 | D32: {=TRANSPOSE([10]MASTER!$BA$49:$BA$57)} -> 3 | E32: 12 | F32: 4 | G32: 2 | H32: 1 | I32: 0 | J32: 1 | K32: 0 | L32: 0 | M32: =SUM(D32:I32) -> 22 | N32: =((M32/C32)*100) -> 95.652174 | O32: =SUM(D32:K32) -> 23 | P32: =((O32/C32)*100) -> 100
A33: 8M | B33: HJH FAUZIAHWATI | C33: =SUM(D33:L33) -> 24 | D33: {=TRANSPOSE([11]MASTER!$BA$56:$BA$64)} -> 3 | E33: 6 | F33: 2 | G33: 3 | H33: 0 | I33: 2 | J33: 5 | K33: 2 | L33: 1 | M33: =SUM(D33:I33) -> 16 | N33: =((M33/C33)*100) -> 66.666667 | O33: =SUM(D33:K33) -> 23 | P33: =((O33/C33)*100) -> 95.833333
A34: 8P | B34: HJ AZMI | C34: =SUM(D34:L34) -> 25 | D34: {=TRANSPOSE([13]MASTER!$BA$44:$BA$52)} -> 2 | E34: 2 | F34: 2 | G34: 4 | H34: 2 | I34: 1 | J34: 7 | K34: 1 | L34: 4 | M34: =SUM(D34:I34) -> 13 | N34: =((M34/C34)*100) -> 52 | O34: =SUM(D34:K34) -> 21 | P34: =((O34/C34)*100) -> 84
A35: 8I | B35: HJH FAUZIAHWATI | C35: =SUM(D35:L35) -> 24 | D35: {=TRANSPOSE([14]MASTER!$BA$56:$BA$64)} -> 1 | E35: 5 | F35: 0 | G35: 1 | H35: 2 | I35: 5 | J35: 4 | K35: 3 | L35: 3 | M35: =SUM(D35:I35) -> 14 | N35: =((M35/C35)*100) -> 58.333333 | O35: =SUM(D35:K35) -> 21 | P35: =((O35/C35)*100) -> 87.5
A36: 8O | B36: HJ AZMI | C36: =SUM(D36:L36) -> 15 | D36: {=TRANSPOSE([15]MASTER!$BA$29:$BA$37)} -> 0 | E36: 0 | F36: 0 | G36: 2 | H36: 1 | I36: 0 | J36: 3 | K36: 5 | L36: 4 | M36: 9 | N36: =((M36/C36)*100) -> 60 | O36: =SUM(D36:K36) -> 11 | P36: =((O36/C36)*100) -> 73.333333
A37: 8N | B37: HJH FAUZIAHWATI | C37: =SUM(D37:L37) -> 12 | D37: {=TRANSPOSE([16]MASTER!$BA$26:$BA$34)} -> 0 | E37: 0 | F37: 0 | G37: 0 | H37: 0 | I37: 0 | J37: 1 | K37: 2 | L37: 9 | M37: 9 | N37: =((M37/C37)*100) -> 75 | O37: =SUM(D37:K37) -> 3 | P37: =((O37/C37)*100) -> 25
B38: Overall | C38: =SUM(C30:C37) -> 163 | D38: =SUM(D30:D37) -> 28 | E38: =SUM(E30:E37) -> 37 | F38: =SUM(F30:F37) -> 12 | G38: =SUM(G30:G37) -> 14 | H38: =SUM(H30:H37) -> 6 | I38: =SUM(I30:I37) -> 8 | J38: =SUM(J30:J37) -> 24 | ... L38: =SUM(L30:L37) -> 21 | M38: =SUM(D38:I38) -> 105 | N38: =((M38/C38)*100) -> 64.417178 | O38: =SUM(D38:K38) -> 142 | P38: =((O38/C38)*100) -> 87.116564
A40: SOCIAL STUDIES
D41: Distinction | F41: Credit | J41: Pass | L41: Fail
A42: Class | B42: Taught By | C42: Total | D42: A* | E42: A2 | F42: B3 | G42: B4 | H42: C5 | I42: C6 | J42: D7 | K42: E8 | L42: U | M42: Total 1-6 | N42: % 1-6 | O42: Total 1-8 | P42: % 1-8
A43: 8C | B43: DK MARIEAH | C43: =SUM(D43:L43) -> 20 | D43: {=TRANSPOSE([9]MASTER!$BS$34:$BS$42)} -> 0 | E43: 4 | F43: 5 | G43: 3 | H43: 5 | I43: 1 | J43: 2 | K43: 0 | L43: 0 | M43: =SUM(D43:I43) -> 18 | N43: =((M43/C43)*100) -> 90 | O43: =SUM(D43:K43) -> 20 | P43: =((O43/C43)*100) -> 100
...

Sheet SPA CHART
A1: PERCENTAGE OBTAINING 1-6 AND 1-8 IN SPA
A3: Subjects | B3: % 1-6 | C3: % 1-8
A4: Bahasa Melayu | B4: ='YEAR 8 SPA'!N112 -> 76.07362 | C4: ='YEAR 8 SPA'!P112 -> 90.797546
A5: English Language | B5: ='YEAR 8 SPA'!N113 -> 85.430464 | C5: ='YEAR 8 SPA'!P113 -> 99.337748
A6: I.R.K | B6: ='YEAR 8 SPA'!N114 -> 62.576687 | C6: ='YEAR 8 SPA'!P114 -> 83.435583
A7: Social Studies | B7: ='YEAR 8 SPA'!N115 -> 69.93865 | C7: ='YEAR 8 SPA'!P115 -> 91.411043
A8: Mathematics | B8: ='YEAR 8 SPA'!N116 -> 31.90184 | C8: ='YEAR 8 SPA'!P116 -> 64.417178
A9: Science | B9: ='YEAR 8 SPA'!N117 -> 27.607362 | C9: ='YEAR 8 SPA'!P117 -> 69.93865
A10: Bahasa Arab | B10: ='YEAR 8 SPA'!N118 -> 59.52381 | C10: ='YEAR 8 SPA'!P118 -> 83.333333
A11: Drama | B11: ='YEAR 8 SPA'!$N$105 -> 100 | C11: ='YEAR 8 SPA'!$P$119 -> 100
A12: Melayu Islam Beraja | B12: ='YEAR 8 SPA'!N120 -> 74.846626 | C12: ='YEAR 8 SPA'!P120 -> 89.570552

Sheet 3'O' and 5'O' & above (SPA)
A1: YEAR 8, STUDENT PROGRESS ASSESSMENT (SPA) 2024
B3: No. of Candidates | C3: No. of Credits Obtained | L3: 5 'O' & above | N3: 3 'O' & above
C4: 8 | D4: 7 | E4: 6 | F4: 5 | G4: 4 | H4: 3 | I4: 2 | J4: 1 | K4: 0 | L4: No. of Candidates | M4: % | N4: No. of Candidates | O4: %
A5: 8C | B5: =SUM(C5:K5) -> 20 | C5: {=TRANSPOSE([1]MASTER!$DA$36:$DA$44)} -> 13 | D5: 6 | E5: 1 | F5: 0 | G5: 0 | H5: 0 | I5: 0 | J5: 0 | K5: 0 | L5: =SUM(C5:F5) -> 20 | M5: =L5/B5 -> 1 | N5: =SUM(C5:H5) -> 20 | O5: =N5/B5 -> 1
A6: 8H | B6: =SUM(C6:K6) -> 20 | C6: {=TRANSPOSE([2]MASTER!$CY$36:$CY$44)} -> 14 | D6: 1 | E6: 3 | F6: 1 | G6: 1 | H6: 0 | I6: 0 | J6: 0 | K6: 0 | L6: =SUM(C6:F6) -> 19 | M6: =L6/B6 -> 0.95 | N6: =SUM(C6:H6) -> 20 | O6: =N6/B6 -> 1
A7: 8A | B7: =SUM(C7:K7) -> 23 | C7: {=TRANSPOSE([3]MASTER!$CY$51:$CY$59)} -> 2 | D7: 9 | E7: 8 | F7: 2 | G7: 2 | H7: 0 | I7: 0 | J7: 0 | K7: 0 | L7: =SUM(C7:F7) -> 21 | M7: =L7/B7 -> 0.91304348 | N7: =SUM(C7:H7) -> 23 | O7: =N7/B7 -> 1
A8: 8M | B8: =SUM(C8:K8) -> 24 | C8: {=TRANSPOSE([4]MASTER!$CY$58:$CY$66)} -> 2 | D8: 1 | E8: 7 | F8: 6 | G8: 7 | H8: 0 | I8: 0 | J8: 1 | K8: 0 | L8: =SUM(C8:F8) -> 16 | M8: =L8/B8 -> 0.66666667 | N8: =SUM(C8:H8) -> 23 | O8: =N8/B8 -> 0.95833333
A9: 8P | B9: =SUM(C9:K9) -> 25 | C9: {=TRANSPOSE([5]MASTER!$DB$46:$DB$54)} -> 0 | D9: 3 | E9: 4 | F9: 2 | G9: 6 | H9: 4 | I9: 2 | J9: 4 | K9: 0 | L9: =SUM(C9:F9) -> 9 | M9: =L9/B9 -> 0.36 | N9: =SUM(C9:H9) -> 19 | O9: =N9/B9 -> 0.76
A10: 8I | B10: =SUM(C10:K10) -> 24 | C10: =[6]MASTER!$DA$58 -> 0 | D10: =[6]MASTER!$DA$59 -> 0 | E10: =[6]MASTER!$DA$60 -> 2 | F10: =[6]MASTER!$DA$61 -> 6 | G10: =[6]MASTER!$DA$62 -> 4 | H10: =[6]MASTER!$DA$63 -> 5 | I10: =[6]MASTER!$DA$64 -> 6 | J10: =[6]MASTER!$DA$65 -> 1 | K10: =[6]MASTER!$DA$66 -> 0 | L10: =SUM(C10:F10) -> 8 | M10: =L10/B10 -> 0.33333333 | N10: =SUM(C10:H10) -> 17 | O10: =N10/B10 -> 0.70833333
A11: 8O | B11: =SUM(C11:K11) -> 15 | C11: =[7]MASTER!$DA$31 -> 0 | D11: =[7]MASTER!$DA$32 -> 0 | E11: =[7]MASTER!$DA$33 -> 0 | F11: =[7]MASTER!$DA$34 -> 1 | G11: =[7]MASTER!$DA$35 -> 2 | H11: =[7]MASTER!$DA$36 -> 1 | I11: =[7]MASTER!$DA$37 -> 2 | J11: =[7]MASTER!$DA$38 -> 6 | K11: =[7]MASTER!$DA$39 -> 3 | L11: =SUM(C11:F11) -> 1 | M11: =L11/B11 -> 0.066666667 | N11: =SUM(C11:H11) -> 4 | O11: =N11/B11 -> 0.26666667
A12: 8N | B12: =SUM(C12:K12) -> 12 | C12: =[8]MASTER!$DA$28 -> 0 | D12: =[8]MASTER!$DA$29 -> 0 | E12: =[8]MASTER!$DA$30 -> 0 | F12: =[8]MASTER!$DA$31 -> 0 | G12: =[8]MASTER!$DA$32 -> 0 | H12: =[8]MASTER!$DA$33 -> 0 | I12: =[8]MASTER!$DA$34 -> 2 | J12: =[8]MASTER!$DA$35 -> 2 | K12: =[8]MASTER!$DA$36 -> 8 | L12: =SUM(C12:F12) -> 0 | M12: =L12/B12 -> 0 | N12: =SUM(C12:H12) -> 0 | O12: =N12/B12 -> 0
A13: Total No. of Candidates | B13: =SUM(B5:B12) -> 163 | C13: =SUM(C5:C12) -> 31 | D13: =SUM(D5:D12) -> 20 | E13: =SUM(E5:E12) -> 25 | F13: =SUM(F5:F12) -> 18 | G13: =SUM(G5:G12) -> 22 | H13: =SUM(H5:H12) -> 10 | I13: =SUM(I5:I12) -> 12 | ... L13: =SUM(L5:L12) -> 94 | M13: =L13/B13 -> 0.57668712 | N13: =M13/C13 -> 0.01860281 | O13: =N13/B13 -> 0.00011412767
A15: % obtained 5'O' & above | B15: =$M$13 -> 0.57668712
A16: % obtained 3'O' & above | B16: =$O$13 -> 0.00011412767

Sheet No.of Credits Attained (SPA)
A1: YEAR 8, STUDENT PROGRESS ASSESSMENT (SPA) 2024
A3: No. Of Candidate Registered | E3: 200
A4: No. Of Candidate Sitting | E4: ='3''O'' and 5''O'' & above (SPA)'!$B$13 -> 163
A5: Withdrawn | E5: 0
A7: Credit Attained | B7: No. Of Student | D7: %
A8: 8 | B8: ='3''O'' and 5''O'' & above (SPA)'!$C$13 -> 31 | D8: =B8/B17 -> 0.19018405
A9: 7 | B9: ='3''O'' and 5''O'' & above (SPA)'!$D$13 -> 20 | D9: =B9/B17 -> 0.12269939
A10: 6 | B10: ='3''O'' and 5''O'' & above (SPA)'!$E$13 -> 25 | D10: =B10/B17 -> 0.15337423
A11: 5 | B11: ='3''O'' and 5''O'' & above (SPA)'!$F$13 -> 18 | D11: =B11/B17 -> 0.11042945
A12: 4 | B12: ='3''O'' and 5''O'' & above (SPA)'!$G$13 -> 22 | D12: =B12/B17 -> 0.13496933
A13: 3 | B13: ='3''O'' and 5''O'' & above (SPA)'!$H$13 -> 10 | D13: =B13/B17 -> 0.061349693
A14: 2 | B14: ='3''O'' and 5''O'' & above (SPA)'!$I$13 -> 12 | D14: =B14/B17 -> 0.073619632
A15: 1 | B15: ='3''O'' and 5''O'' & above (SPA)'!$J$13 -> 14 | D15: =B15/B17 -> 0.085889571
A16: 0 | B16: ='3''O'' and 5''O'' & above (SPA)'!$K$13 -> 11 | D16: =B16/B17 -> 0.067484663
A17: Total | B17: =SUM(B8:C16) -> 163
C20: No. of Student | D20: %
A21: 3 or more Credits | C21: =SUM(B8:C13) -> 126 | D21: =C21/B17 -> 0.77300613
A22: 4 or more Credits | C22: =SUM(B8:C12) -> 116 | D22: =C22/B17 -> 0.71165644
A23: 5 or more Credits | C23: =SUM(B8:C11) -> 94 | D23: =C23/B17 -> 0.57668712

Sheet class avg
A2: Class + No of stdn | B2: Class Avg
A3: 10Sci1
A4: 11Sci2
A5: 11Sci3
A6: 11P
A7: 11E
A8: 11A
A9: 11R
A10: 11L

Sheet By Class
A2: Menengah 4A
D3: Distinction | F3: Credit | J3: Pass | L3: Fail
A4: Subjects | B4: Taught By | C4: Total | D4: 1 | E4: 2 | F4: 3 | G4: 4 | H4: 5 | I4: 6 | J4: 7 | K4: 8 | L4: 9 | M4: Total 1-6 | N4: % 1-6 | O4: Total 1-8 | P4: % 1-8
A5: B.Melayu | N5: =((M5/C5)*100) -> #DIV/0! | O5: =SUM(D5:K5) -> 0 | P5: =((O5/C5)*100) -> #DIV/0!
A6: English | N6: =((M6/C6)*100) -> #DIV/0! | O6: =SUM(D6:K6) -> 0 | P6: =((O6/C6)*100) -> #DIV/0!
A7: Maths | N7: =((M7/C7)*100) -> #DIV/0! | O7: =SUM(D7:K7) -> 0 | P7: =((O7/C7)*100) -> #DIV/0!
A8: Add Maths | N8: =((M8/C8)*100) -> #DIV/0! | O8: =SUM(D8:K8) -> 0 | P8: =((O8/C8)*100) -> #DIV/0!
A9: Physics | N9: =((M9/C9)*100) -> #DIV/0! | O9: =SUM(D9:K9) -> 0 | P9: =((O9/C9)*100) -> #DIV/0!
A10: Chemistry | N10: =((M10/C10)*100) -> #DIV/0! | O10: =SUM(D10:K10) -> 0 | P10: =((O10/C10)*100) -> #DIV/0!
A11: Biology | N11: =((M11/C11)*100) -> #DIV/0! | O11: =SUM(D11:K11) -> 0 | P11: =((O11/C11)*100) -> #DIV/0!
A12: Geography | N12: =((M12/C12)*100) -> #DIV/0! | O12: =SUM(D12:K12) -> 0 | P12: =((O12/C12)*100) -> #DIV/0!
A13: Computer | N13: =((M13/C13)*100) -> #DIV/0! | O13: =SUM(D13:K13) -> 0 | P13: =((O13/C13)*100) -> #DIV/0!
N14: =AVERAGE(N5:N13) -> #DIV/0! | P14: =AVERAGE(P5:P13) -> #DIV/0!
A16: Menengah 4B
D17: Distinction | F17: Credit | J17: Pass | L17: Fail
A18: Subjects | B18: Taught By | C18: Total | D18: 1 | E18: 2 | F18: 3 | G18: 4 | H18: 5 | I18: 6 | J18: 7 | K18: 8 | L18: 9 | M18: Total 1-6 | N18: % 1-6 | O18: Total 1-8 | P18: % 1-8
A19: B.Melayu | N19: =((M19/C19)*100) -> #DIV/0! | O19: =SUM(D19:K19) -> 0 | P19: =((O19/C19)*100) -> #DIV/0!
A20: English | N20: =((M20/C20)*100) -> #DIV/0! | O20: =SUM(D20:K20) -> 0 | P20: =((O20/C20)*100) -> #DIV/0!
A21: Maths | N21: =((M21/C21)*100) -> #DIV/0! | O21: =SUM(D21:K21) -> 0 | P21: =((O21/C21)*100) -> #DIV/0!
A22: Physics | N22: =((M22/C22)*100) -> #DIV/0! | O22: 10 | P22: =((O22/C22)*100) -> #DIV/0!
A23: Chemistry | N23: =((M23/C23)*100) -> #DIV/0! | O23: 10 | P23: =((O23/C23)*100) -> #DIV/0!
A24: Biology | N24: =((M24/C24)*100) -> #DIV/0! | O24: 19 | P24: =((O24/C24)*100) -> #DIV/0!
A25: Geography | N25: =((M25/C25)*100) -> #DIV/0! | O25: 19 | P25: =((O25/C25)*100) -> #DIV/0!
A26: Economics | N26: =((M26/C26)*100) -> #DIV/0! | O26: 3 | P26: =((O26/C26)*100) -> #DIV/0!
A27: Computer | N27: =((M27/C27)*100) -> #DIV/0! | O27: 2 | P27: =((O27/C27)*100) -> #DIV/0!
A28: POA | N28: =((M28/C28)*100) -> #DIV/0! | O28: 12 | P28: =((O28/C28)*100) -> #DIV/0!
N29: =AVERAGE(N19:N28) -> #DIV/0! | P29: =AVERAGE(P19:P28) -> #DIV/0!
A31: Menengah 4C
D32: Distinction | F32: Credit | J32: Pass | L32: Fail
A33: Subjects | B33: Taught By | C33: Total | D33: 1 | E33: 2 | F33: 3 | G33: 4 | H33: 5 | I33: 6 | J33: 7 | K33: 8 | L33: 9 | M33: Total 1-6 | N33: % 1-6 | O33: Total 1-8 | P33: % 1-8
A34: B.Melayu | N34: =((M34/C34)*100) -> #DIV/0! | O34: 18 | P34: =((O34/C34)*100) -> #DIV/0!
A35: English | N35: =((M35/C35)*100) -> #DIV/0! | O35: 15 | P35: =((O35/C35)*100) -> #DIV/0!
A36: Maths | N36: =((M36/C36)*100) -> #DIV/0! | O36: 9 | P36: =((O36/C36)*100) -> #DIV/0!
A37: Comb Sc | N37: =((M37/C37)*100) -> #DIV/0! | O37: 6 | P37: =((O37/C37)*100) -> #DIV/0!
A38: Geography | N38: =((M38/C38)*100) -> #DIV/0! | O38: 7 | P38: =((O38/C38)*100) -> #DIV/0!
A39: History | N39: =((M39/C39)*100) -> #DIV/0! | O39: 14 | P39: =((O39/C39)*100) -> #DIV/0!
A40: IRK | N40: =((M40/C40)*100) -> #DIV/0! | O40: 16 | P40: =((O40/C40)*100) -> #DIV/0!
A41: Commerce | N41: =((M41/C41)*100) -> #DIV/0! | O41: 14 | P41: =((O41/C41)*100) -> #DIV/0!
A42: Agr Sc | N42: =((M42/C42)*100) -> #DIV/0! | O42: 2 | P42: =((O42/C42)*100) -> #DIV/0!
N43: =AVERAGE(N34:N42) -> #DIV/0! | P43: =AVERAGE(P34:P42) -> #DIV/0!
...
