Workbook

Sheet ANALYSIS BY SUBJECTS
A1: BAHASA MELAYU (1201)
D2: Distinction | F2: Credit | J2: Pass | L2: Fail
A3: Class | B3: Taught By | C3: Total | D3: A* | E3: A2 | F3: B3 | G3: B4 | H3: C5 | I3: C6 | J3: D7 | K3: E8 | L3: U | M3: Total 1-6 | N3: % 1-6 | O3: Total 1-8 | P3: % 1-8
A4: 10SCI2 | B4: Cg Amalina | C4: =SUM(D4:L4) -> 21 | D4: {=TRANSPOSE([1]Master!$G$47:$G$55)} -> 0 | E4: 0 | F4: 2 | G4: 2 | H4: 3 | I4: 3 | J4: 8 | K4: 3 | L4: 0 | M4: =SUM(D4:I4) -> 10 | N4: =((M4/C4)*100) -> 47.619048 | O4: =SUM(D4:K4) -> 21 | P4: =((O4/C4)*100) -> 100
A5: 10SCI3 | B5: Cg Haji Habil | C5: =SUM(D5:L5) -> 14 | D5: {=TRANSPOSE([2]Master!$J$47:$J$55)} -> 0 | E5: 2 | F5: 4 | G5: 5 | H5: 3 | I5: 0 | J5: 0 | K5: 0 | L5: 0 | M5: =SUM(D5:I5) -> 14 | N5: =((M5/C5)*100) -> 100 | O5: =SUM(D5:K5) -> 14 | P5: =((O5/C5)*100) -> 100
A6: 10P | B6: Cg Amalina | C6: =SUM(D6:L6) -> 24 | D6: {=TRANSPOSE([3]Master!$J$46:$J$54)} -> 0 | E6: 0 | F6: 0 | G6: 0 | H6: 0 | I6: 4 | J6: 11 | K6: 6 | L6: 3 | M6: =SUM(D6:I6) -> 4 | N6: =((M6/C6)*100) -> 16.666667 | O6: =SUM(D6:K6) -> 21 | P6: =((O6/C6)*100) -> 87.5
A7: 10R | B7: Cg Haji Habil | C7: =SUM(D7:L7) -> 23 | D7: {=TRANSPOSE([4]Master!$I$47:$I$55)} -> 0 | E7: 0 | F7: 2 | G7: 13 | H7: 4 | I7: 3 | J7: 0 | K7: 1 | L7: 0 | M7: =SUM(D7:I7) -> 22 | N7: =((M7/C7)*100) -> 95.652174 | O7: =SUM(D7:K7) -> 23 | P7: =((O7/C7)*100) -> 100
A8: 10I | B8: Cg Hjh Nooraini | C8: =SUM(D8:L8) -> 26 | D8: {=TRANSPOSE([12]Master!$J$47:$J$55)} -> 0 | E8: 0 | F8: 1 | G8: 1 | H8: 2 | I8: 6 | J8: 11 | K8: 4 | L8: 1 | M8: =SUM(G9:L9) -> 21 | N8: =((M8/C8)*100) -> 80.769231 | O8: =SUM(F8:L8) -> 26 | P8: =((O8/C8)*100) -> 100
A9: 10M | B9: Cg Hjh Nooraini | C9: =SUM(D9:L9) -> 21 | D9: {=TRANSPOSE([13]Master!$I$47:$I$55)} -> 0 | E9: 0 | F9: 0 | G9: 0 | H9: 1 | I9: 0 | J9: 7 | K9: 5 | L9: 8 | M9: =SUM(G10:L10) -> 20 | N9: =((M9/C9)*100) -> 95.238095 | O9: =SUM(G10:L10) -> 20 | P9: =((O9/C9)*100) -> 95.238095
A10: 10E | B10: Cg Amalina | C10: =SUM(D10:L10) -> 20 | D10: {=TRANSPOSE([14]Master!$J$47:$J$55)} -> 0 | E10: 0 | F10: 0 | G10: 0 | H10: 1 | I10: 2 | J10: 4 | K10: 7 | L10: 6 | M10: =SUM(D10:F10) -> 0 | N10: =((M10/C10)*100) -> 0 | O10: =SUM(D10:F10) -> 0 | P10: =((O10/C10)*100) -> 0
B11: Overall | C11: =SUM(C4:C10) -> 149 | D11: =SUM(D4:D10) -> 0 | E11: =SUM(E4:E10) -> 2 | F11: =SUM(F4:F10) -> 9 | G11: =SUM(G4:G10) -> 21 | H11: =SUM(H4:H10) -> 14 | I11: =SUM(I4:I10) -> 18 | J11: =SUM(J4:J10) -> 41 | ... M11: =SUM(M4:M10) -> 91 | N11: =((M11/C11)*100) -> 61.073826 | O11: =SUM(O4:O10) -> 125 | P11: =((O11/C11)*100) -> 83.892617
A13: SASTERA (2023)
D14: Distinction | F14: Credit | J14: Pass | L14: Fail
A15: Class | B15: Taught By | C15: Total | D15: A* | E15: A2 | F15: B3 | G15: B4 | H15: C5 | I15: C6 | J15: D7 | K15: E8 | L15: U | M15: Total 1-6 | N15: % 1-6 | O15: Total 1-8 | P15: % 1-8
A16: 10M | B16: Cg Ummi Sahirah | C16: =SUM(D16:L16) -> 21 | D16: {=TRANSPOSE([13]Master!$AG$47:$AG$55)} -> 0 | E16: 0 | F16: 2 | G16: 1 | H16: 5 | I16: 2 | J16: 8 | K16: 0 | L16: 3 | M16: =SUM(D16:I16) -> 10 | N16: =((M16/C16)*100) -> 47.619048 | O16: =SUM(D16:K16) -> 18 | P16: =((O16/C16)*100) -> 85.714286
A17: 10E | B17: Cg Ummi Sahirah | C17: =SUM(D17:L17) -> 20 | D17: {=TRANSPOSE([14]Master!$Y$47:$Y$55)} -> 0 | E17: 3 | F17: 2 | G17: 0 | H17: 5 | I17: 3 | J17: 5 | K17: 0 | L17: 2 | M17: =SUM(D17:I17) -> 13 | N17: =((M17/C17)*100) -> 65 | O17: =SUM(D17:K17) -> 18 | P17: =((O17/C17)*100) -> 90
B18: Overall | C18: =SUM(C16:C17) -> 41 | D18: =SUM(D16:D17) -> 0 | E18: =SUM(E16:E17) -> 3 | F18: =SUM(F16:F17) -> 4 | G18: =SUM(G16:G17) -> 1 | H18: =SUM(H16:H17) -> 10 | I18: =SUM(I16:I17) -> 5 | J18: =SUM(J16:J17) -> 13 | ... M18: =SUM(M16:M17) -> 23 | N18: =((M18/C18)*100) -> 56.097561 | O18: =SUM(O16:O17) -> 36 | P18: =((O18/C18)*100) -> 87.804878
A20: ENGLISH LANGUAGE (1120)
D21: Distinction | F21: Credit | J21: Pass | L21: Fail
A22: Class | B22: Taught By | C22: Total | D22: A* | E22: A2 | F22: B3 | G22: B4 | H22: C5 | I22: C6 | J22: D7 | K22: E8 | L22: U | M22: Total 1-6 | N22: % 1-6 | O22: Total 1-8 | P22: % 1-8
A23: 10SCI2 | B23: Cg Ana | C23: =SUM(D23:L23) -> 21 | D23: {=TRANSPOSE([1]Master!$J$47:$J$55)} -> 0 | E23: 0 | F23: 0 | G23: 0 | H23: 7 | I23: 8 | J23: 6 | K23: 0 | L23: 0 | M23: =SUM(D23:I23) -> 15 | N23: =((M23/C23)*100) -> 71.428571 | O23: =SUM(D23:K23) -> 21 | P23: =((O23/C23)*100) -> 100
A24: 10SCI3 | B24: Cg Hjh Mariah | C24: =SUM(D24:L24) -> 14 | D24: {=TRANSPOSE([2]Master!$M$47:$M$55)} -> 0 | E24: 3 | F24: 3 | G24: 3 | H24: 3 | I24: 2 | J24: 0 | K24: 0 | L24: 0 | M24: =SUM(D24:I24) -> 14 | N24: =((M24/C24)*100) -> 100 | O24: =SUM(D24:K24) -> 14 | P24: =((O24/C24)*100) -> 100
A25: 10P | B25: Cg Suhaila | C25: =SUM(D25:L25) -> 24 | D25: {=TRANSPOSE([3]Master!$M$46:$M$54)} -> 0 | E25: 10 | F25: 3 | G25: 5 | H25: 5 | I25: 1 | J25: 0 | K25: 0 | L25: 0 | M25: =SUM(D25:I25) -> 24 | N25: =((M25/C25)*100) -> 100 | O25: =SUM(D25:K25) -> 24 | P25: =((O25/C25)*100) -> 100
A26: 10R | B26: Cg Hjh Mariah | C26: =SUM(D26:L26) -> 23 | D26: {=TRANSPOSE([4]Master!$L$47:$L$55)} -> 0 | E26: 2 | F26: 3 | G26: 4 | H26: 4 | I26: 5 | J26: 5 | K26: 0 | L26: 0 | M26: =SUM(D26:I26) -> 18 | N26: =((M26/C26)*100) -> 78.26087 | O26: =SUM(D26:K26) -> 23 | P26: =((O26/C26)*100) -> 100
A27: 10I | B27: Cg Norsuzilawati | C27: =SUM(D27:L27) -> 26 | D27: {=TRANSPOSE([12]Master!$M$47:$M$55)} -> 0 | E27: 0 | F27: 0 | G27: 0 | H27: 2 | I27: 2 | J27: 13 | K27: 7 | L27: 2 | M27: =SUM(D27:I27) -> 4 | N27: =((M27/C27)*100) -> 15.384615 | O27: =SUM(D27:K27) -> 24 | P27: =((O27/C27)*100) -> 92.307692
A28: 10M | B28: Cg Asfarina | C28: =SUM(D28:L28) -> 21 | D28: {=TRANSPOSE([13]Master!$L$47:$L$55)} -> 0 | E28: 1 | F28: 1 | G28: 1 | H28: 2 | I28: 4 | J28: 6 | K28: 4 | L28: 2 | M28: =SUM(D28:I28) -> 9 | N28: =((M28/C28)*100) -> 42.857143 | O28: =SUM(D28:K28) -> 19 | P28: =((O28/C28)*100) -> 90.47619
A29: 10E | B29: Cg Asfarina | C29: =SUM(D29:L29) -> 20 | D29: {=TRANSPOSE([14]Master!$M$47:$M$55)} -> 0 | E29: 0 | F29: 0 | G29: 0 | H29: 1 | I29: 3 | J29: 5 | K29: 3 | L29: 8 | M29: =SUM(D29:I29) -> 4 | N29: =((M29/C29)*100) -> 20 | O29: =SUM(D29:K29) -> 12 | P29: =((O29/C29)*100) -> 60
B30: Overall | C30: =SUM(C23:C29) -> 149 | D30: =SUM(D23:D29) -> 0 | E30: =SUM(E23:E29) -> 16 | F30: =SUM(F23:F29) -> 10 | G30: =SUM(G23:G29) -> 13 | H30: =SUM(H23:H29) -> 24 | I30: =SUM(I23:I29) -> 25 | J30: =SUM(J23:J29) -> 35 | ... M30: =SUM(M23:M29) -> 88 | N30: =((M30/C30)*100) -> 59.060403 | O30: =SUM(O23:O29) -> 137 | P30: =((O30/C30)*100) -> 91.946309
A32: MATHEMATICS D (4024)
D33: Distinction | F33: Credit | J33: Pass | L33: Fail
A34: Class | B34: Taught By | C34: Total | D34: A* | E34: A2 | F34: B3 | G34: B4 | H34: C5 | I34: C6 | J34: D7 | K34: E8 | L34: U | M34: Total 1-6 | N34: % 1-6 | O34: Total 1-8 | P34: % 1-8
A35: 10SCI2 | B35: Cg Iqzal | C35: =SUM(D35:L35) -> 21 | D35: {=TRANSPOSE([1]Master!$M$47:$M$55)} -> 0 | E35: 1 | F35: 0 | G35: 1 | H35: 0 | I35: 0 | J35: 6 | K35: 7 | L35: 6 | M35: =SUM(D35:I35) -> 2 | N35: =((M35/C35)*100) -> 9.5238095 | O35: =SUM(D35:K35) -> 15 | P35: =((O35/C35)*100) -> 71.428571
A36: 10SCI3 | B36: Cg Afifah | C36: =SUM(D36:L36) -> 14 | D36: {=TRANSPOSE([2]Master!$P$47:$P$55)} -> 0 | E36: 0 | F36: 0 | G36: 2 | H36: 1 | I36: 3 | J36: 5 | K36: 3 | L36: 0 | M36: =SUM(D36:I36) -> 6 | N36: =((M36/C36)*100) -> 42.857143 | O36: =SUM(D36:K36) -> 14 | P36: =((O36/C36)*100) -> 100
A37: 10P | B37: Cg Zunainah | C37: =SUM(D37:L37) -> 24 | D37: {=TRANSPOSE([3]Master!$M$46:$M$54)} -> 0 | E37: 10 | F37: 3 | G37: 5 | H37: 5 | I37: 1 | J37: 0 | K37: 0 | L37: 0 | M37: =SUM(D37:I37) -> 24 | N37: 0 | O37: =SUM(D37:K37) -> 24 | P37: 6.25
A38: 10R | B38: Cg Iqzal | C38: =SUM(D38:L38) -> 23 | D38: {=TRANSPOSE([4]Master!$O$47:$O$55)} -> 0 | E38: 0 | F38: 0 | G38: 0 | H38: 0 | I38: 0 | J38: 2 | K38: 2 | L38: 19 | M38: =SUM(D38:I38) -> 0 | N38: 0 | O38: =SUM(D38:K38) -> 4 | P38: 14.285714
A39: 10I | B39: Cg Afifah | C39: =SUM(D39:L39) -> 26 | D39: {=TRANSPOSE([12]Master!$P$47:$P$55)} -> 0 | E39: 0 | F39: 0 | G39: 0 | H39: 0 | I39: 0 | J39: 0 | K39: 2 | L39: 24 | M39: =SUM(D39:I39) -> 0 | N39: 0 | O39: =SUM(D39:K39) -> 2 | P39: 28.571429
B40: Overall | C40: =SUM(C35:C39) -> 108 | D40: =SUM(D35:D39) -> 0 | E40: =SUM(E35:E39) -> 11 | F40: =SUM(F35:F39) -> 3 | G40: =SUM(G35:G39) -> 8 | H40: =SUM(H35:H39) -> 6 | I40: =SUM(I35:I39) -> 4 | J40: =SUM(J35:J39) -> 13 | ... M40: =SUM(M35:M39) -> 32 | N40: =((M40/C40)*100) -> 29.62963 | O40: =SUM(O35:O39) -> 59 | P40: =((O40/C40)*100) -> 54.62963
A42: MATHEMATICS IGCSE - CORE (0580)
D43: GRADE
A44: Class | B44: Taught By | C44: Total | D44: C | E44: D | F44: E | G44: F | H44: G | I44: U | M44: Total C | N44: % C | O44: Total C-G | P44: % C-G
...

Sheet OVERALL PERFORMANCES
A2: Subjects | B2: % 1-6 | C2: % 1-8
A3: B.Melayu | B3: ='ANALYSIS BY SUBJECTS'!N179 -> 61.073826 | C3: ='ANALYSIS BY SUBJECTS'!P179 -> 87.919463
A4: English Language | B4: ='ANALYSIS BY SUBJECTS'!N180 -> 59.060403 | C4: ='ANALYSIS BY SUBJECTS'!P180 -> 91.946309
A5: Mathematics D | B5: ='ANALYSIS BY SUBJECTS'!N181 -> 29.62963 | C5: ='ANALYSIS BY SUBJECTS'!P181 -> 54.62963
A6: Physics | B6: ='ANALYSIS BY SUBJECTS'!N182 -> 42.592593 | C6: ='ANALYSIS BY SUBJECTS'!P182 -> 62.962963
A7: Chemistry | B7: ='ANALYSIS BY SUBJECTS'!N183 -> 62.162162 | C7: ='ANALYSIS BY SUBJECTS'!P183 -> 94.594595
A8: Biology | B8: ='ANALYSIS BY SUBJECTS'!N184 -> 68.571429 | C8: ='ANALYSIS BY SUBJECTS'!P184 -> 94.285714
A9: Combined Science | B9: ='ANALYSIS BY SUBJECTS'!N185 -> 2.4390244 | C9: ='ANALYSIS BY SUBJECTS'!P185 -> 26.829268
A10: Geography | B10: ='ANALYSIS BY SUBJECTS'!N186 -> 7.9365079 | C10: ='ANALYSIS BY SUBJECTS'!P186 -> 57.142857
A11: IRK | B11: ='ANALYSIS BY SUBJECTS'!N187 -> 62.162162 | C11: ='ANALYSIS BY SUBJECTS'!P187 -> 83.108108
A12: History | B12: ='ANALYSIS BY SUBJECTS'!N188 -> 30.434783 | C12: ='ANALYSIS BY SUBJECTS'!P188 -> 91.304348
A13: Commerce | B13: ='ANALYSIS BY SUBJECTS'!N189 -> 72.727273 | C13: ='ANALYSIS BY SUBJECTS'!P189 -> 100
A14: Economics | B14: ='ANALYSIS BY SUBJECTS'!N190 -> 33.333333 | C14: ='ANALYSIS BY SUBJECTS'!P190 -> 91.666667
... A19: Sastera | B19: ='ANALYSIS BY SUBJECTS'!N195 -> 56.097561 | C19: ='ANALYSIS BY SUBJECTS'!P195 -> 87.804878
A20: Computer Science | B20: ='ANALYSIS BY SUBJECTS'!$N$165 -> 65 | C20: ='ANALYSIS BY SUBJECTS'!$P$165 -> 95
A21: ='ANALYSIS BY SUBJECTS'!A167 -> IG ICT | B21: ='ANALYSIS BY SUBJECTS'!$N$171 -> 25 | C21: ='ANALYSIS BY SUBJECTS'!$P$171 -> 87.5

Sheet CLASS AVERAGE
A2: Class + No of stdn | B2: Class Avg
A3: 10Sci2 (26)
A4: 10Sci3 (25)
A5: 10A (31)
A6: 10M (30)
A7: 10B (31)
A8: 10E (32)
A9: 10R (31)

Sheet By Class
A2: Menengah 4A
D3: Distinction | F3: Credit | J3: Pass | L3: Fail
A4: Subjects | B4: Taught By | C4: Total | D4: 1 | E4: 2 | F4: 3 | G4: 4 | H4: 5 | I4: 6 | J4: 7 | K4: 8 | L4: 9 | M4: Total 1-6 | N4: % 1-6 | O4: Total 1-8 | P4: % 1-8
A5: B.Melayu | N5: =((M5/C5)*100) -> #DIV/0! | O5: =SUM(D5:K5) -> 0 | P5: =((O5/C5)*100) -> #DIV/0!
A6: English | N6: =((M6/C6)*100) -> #DIV/0! | O6: =SUM(D6:K6) -> 0 | P6: =((O6/C6)*100) -> #DIV/0!
A7: Maths | N7: =((M7/C7)*100) -> #DIV/0! | O7: =SUM(D7:K7) -> 0 | P7: =((O7/C7)*100) -> #DIV/0!
A8: Add Maths | N8: =((M8/C8)*100) -> #DIV/0! | O8: =SUM(D8:K8) -> 0 | P8: =((O8/C8)*100) -> #DIV/0!
A9: Physics | N9: =((M9/C9)*100) -> #DIV/0! | O9: =SUM(D9:K9) -> 0 | P9: =((O9/C9)*100) -> #DIV/0!
A10: Chemistry | N10: =((M10/C10)*100) -> #DIV/0! | O10: =SUM(D10:K10) -> 0 | P10: =((O10/C10)*100) -> #DIV/0!
A11: Biology | N11: =((M11/C11)*100) -> #DIV/0! | O11: =SUM(D11:K11) -> 0 | P11: =((O11/C11)*100) -> #DIV/0!
A12: Geography | N12: =((M12/C12)*100) -> #DIV/0! | O12: =SUM(D12:K12) -> 0 | P12: =((O12/C12)*100) -> #DIV/0!
A13: Computer | N13: =((M13/C13)*100) -> #DIV/0! | O13: =SUM(D13:K13) -> 0 | P13: =((O13/C13)*100) -> #DIV/0!
N14: =AVERAGE(N5:N13) -> #DIV/0! | P14: =AVERAGE(P5:P13) -> #DIV/0!
A16: Menengah 4B
D17: Distinction | F17: Credit | J17: Pass | L17: Fail
A18: Subjects | B18: Taught By | C18: Total | D18: 1 | E18: 2 | F18: 3 | G18: 4 | H18: 5 | I18: 6 | J18: 7 | K18: 8 | L18: 9 | M18: Total 1-6 | N18: % 1-6 | O18: Total 1-8 | P18: % 1-8
A19: B.Melayu | N19: =((M19/C19)*100) -> #DIV/0! | O19: =SUM(D19:K19) -> 0 | P19: =((O19/C19)*100) -> #DIV/0!
A20: English | N20: =((M20/C20)*100) -> #DIV/0! | O20: =SUM(D20:K20) -> 0 | P20: =((O20/C20)*100) -> #DIV/0!
A21: Maths | N21: =((M21/C21)*100) -> #DIV/0! | O21: =SUM(D21:K21) -> 0 | P21: =((O21/C21)*100) -> #DIV/0!
A22: Physics | N22: =((M22/C22)*100) -> #DIV/0! | O22: 10 | P22: =((O22/C22)*100) -> #DIV/0!
A23: Chemistry | N23: =((M23/C23)*100) -> #DIV/0! | O23: 10 | P23: =((O23/C23)*100) -> #DIV/0!
A24: Biology | N24: =((M24/C24)*100) -> #DIV/0! | O24: 19 | P24: =((O24/C24)*100) -> #DIV/0!
A25: Geography | N25: =((M25/C25)*100) -> #DIV/0! | O25: 19 | P25: =((O25/C25)*100) -> #DIV/0!
A26: Economics | N26: =((M26/C26)*100) -> #DIV/0! | O26: 3 | P26: =((O26/C26)*100) -> #DIV/0!
A27: Computer | N27: =((M27/C27)*100) -> #DIV/0! | O27: 2 | P27: =((O27/C27)*100) -> #DIV/0!
A28: POA | N28: =((M28/C28)*100) -> #DIV/0! | O28: 12 | P28: =((O28/C28)*100) -> #DIV/0!
N29: =AVERAGE(N19:N28) -> #DIV/0! | P29: =AVERAGE(P19:P28) -> #DIV/0!
A31: Menengah 4C
D32: Distinction | F32: Credit | J32: Pass | L32: Fail
A33: Subjects | B33: Taught By | C33: Total | D33: 1 | E33: 2 | F33: 3 | G33: 4 | H33: 5 | I33: 6 | J33: 7 | K33: 8 | L33: 9 | M33: Total 1-6 | N33: % 1-6 | O33: Total 1-8 | P33: % 1-8
A34: B.Melayu | N34: =((M34/C34)*100) -> #DIV/0! | O34: 18 | P34: =((O34/C34)*100) -> #DIV/0!
A35: English | N35: =((M35/C35)*100) -> #DIV/0! | O35: 15 | P35: =((O35/C35)*100) -> #DIV/0!
A36: Maths | N36: =((M36/C36)*100) -> #DIV/0! | O36: 9 | P36: =((O36/C36)*100) -> #DIV/0!
A37: Comb Sc | N37: =((M37/C37)*100) -> #DIV/0! | O37: 6 | P37: =((O37/C37)*100) -> #DIV/0!
A38: Geography | N38: =((M38/C38)*100) -> #DIV/0! | O38: 7 | P38: =((O38/C38)*100) -> #DIV/0!
A39: History | N39: =((M39/C39)*100) -> #DIV/0! | O39: 14 | P39: =((O39/C39)*100) -> #DIV/0!
A40: IRK | N40: =((M40/C40)*100) -> #DIV/0! | O40: 16 | P40: =((O40/C40)*100) -> #DIV/0!
A41: Commerce | N41: =((M41/C41)*100) -> #DIV/0! | O41: 14 | P41: =((O41/C41)*100) -> #DIV/0!
A42: Agr Sc | N42: =((M42/C42)*100) -> #DIV/0! | O42: 2 | P42: =((O42/C42)*100) -> #DIV/0!
N43: =AVERAGE(N34:N42) -> #DIV/0! | P43: =AVERAGE(P34:P42) -> #DIV/0!
...

Sheet IGCSE SUBJECTS
A1: Y10 MID YEAR EXAMINATION 2016
A2: SEKOLAH MENENGAH PG ANAK PUTERI HAJAH MASNA
A4: IGCSE SUBJECTS
C6: NUMBER OF CANDIDATES OBTAINING | O6: PERCENTAGE FOR GRADES
C7: NO. OF CANDIDATE | E7: Distinction | G7: Credit | I7: Pass | M7: Fail | N7: ABSENT | O7: Distinction | P7: Credit | Q7: Pass | R7: Fail | S7: Credit | T7: Pass
A8: Subject | C8: REGISTERED | D8: SAT | E8: A* | F8: A | G8: B | H8: C | I8: D | J8: E | K8: F | L8: G | M8: U | N8: X | O8: A*- A | P8: B-C | Q8: D-G | R8: U | S8: % A* - C | T8: % A* - G
A9: IGCSE English E2L (Core) | C9: ='ANALYSIS BY SUBJECTS'!#REF! -> #REF! | D9: ='ANALYSIS BY SUBJECTS'!#REF! -> #REF! | H9: ='ANALYSIS BY SUBJECTS'!#REF! -> #REF! | I9: ='ANALYSIS BY SUBJECTS'!#REF! -> #REF! | J9: ='ANALYSIS BY SUBJECTS'!#REF! -> #REF! | K9: ='ANALYSIS BY SUBJECTS'!#REF! -> #REF! | L9: ='ANALYSIS BY SUBJECTS'!#REF! -> #REF! | M9: ='ANALYSIS BY SUBJECTS'!#REF! -> #REF! | O9: =((E9+F9)/C9) -> #REF! | P9: =(SUM(G9:H9)/C9) -> #REF! | Q9: =(SUM(I9:L9)/C9) -> #REF! | R9: =M9/C9 -> #REF! | S9: =(SUM(E9:H9)/C9) -> #REF! | T9: =(SUM(E9:L9)/D9) -> #REF!
A10: IGCSE Mathematics (Core) | C10: ='ANALYSIS BY SUBJECTS'!$C$47 -> 37 | D10: ='ANALYSIS BY SUBJECTS'!$C$47 -> 37 | H10: 1 | I10: ='ANALYSIS BY SUBJECTS'!#REF! -> #REF! | J10: 2 | K10: 15 | L10: 38 | M10: 27 | O10: =((E10+F10)/C10) -> 0 | P10: =(SUM(G10:H10)/C10) -> 0.027027027 | Q10: =(SUM(I10:L10)/C10) -> #REF! | R10: =M10/C10 -> 0.72972973 | S10: =(SUM(E10:H10)/C10) -> 0.027027027 | T10: =(SUM(E10:L10)/D10) -> #REF!
A11: IGCSE PE (Extended) | C11: 21 | D11: 21 | E11: ='ANALYSIS BY SUBJECTS'!#REF! -> #REF! | F11: ='ANALYSIS BY SUBJECTS'!#REF! -> #REF! | G11: 2 | H11: 7 | I11: 4 | J11: 1 | K11: 0 | L11: 0 | M11: ='ANALYSIS BY SUBJECTS'!#REF! -> #REF! | O11: =((E11+F11)/C11) -> #REF! | P11: =(SUM(G11:H11)/C11) -> 0.42857143 | Q11: =(SUM(I11:L11)/C11) -> 0.23809524 | R11: =M11/C11 -> #REF! | S11: =(SUM(E11:H11)/C11) -> #REF! | T11: =(SUM(E11:L11)/D11) -> #REF!
A12: IGCSE ICT (Extended) | O12: =((E12+F12)/C12) -> #DIV/0! | P12: =(SUM(G12:H12)/C12) -> #DIV/0! | Q12: =(SUM(I12:L12)/C12) -> #DIV/0! | R12: =M12/C12 -> #DIV/0! | S12: =(SUM(E12:H12)/C12) -> #DIV/0! | T12: =(SUM(E12:L12)/D12) -> #DIV/0!

Sheet OVERALL ANALYSIS
A1: SEKOLAH MENENGAH PG ANAK PUTERI HAJAH MASNA
A2: OVERALL RESULTS - YEAR 10 END OF YEAR EXAMINATION 2025
C4: NUMBER OF CANDIDATES OBTAINING | O4: PERCENTAGE FOR GRADES | U4: REMARKS
C5: NO. OF CANDIDATE | E5: Distinction | G5: Credit | K5: Pass | M5: Fail | N5: ABSENT | O5: Distinction | P5: Credit | Q5: Pass | R5: Fail | S5: Credit | T5: Pass
A6: Subject | C6: REGISTERED | D6: SAT | E6: A*1 | F6: A2 | G6: B3 | H6: B4 | I6: C5 | J6: C6 | K6: D7 | L6: E8 | M6: U | N6: X | O6: 1-2 | P6: 3-6 | Q6: 7-8 | R6: 9 | S6: % 1-6 | T6: % 1-8
A7: B.Melayu | C7: ='ANALYSIS BY SUBJECTS'!C179 -> 149 | D7: ='ANALYSIS BY SUBJECTS'!C179 -> 149 | E7: ='ANALYSIS BY SUBJECTS'!D179 -> 0 | F7: ='ANALYSIS BY SUBJECTS'!E179 -> 2 | G7: ='ANALYSIS BY SUBJECTS'!F179 -> 9 | H7: ='ANALYSIS BY SUBJECTS'!G179 -> 21 | I7: ='ANALYSIS BY SUBJECTS'!H179 -> 14 | J7: ='ANALYSIS BY SUBJECTS'!I179 -> 18 | K7: ='ANALYSIS BY SUBJECTS'!J179 -> 41 | ... M7: ='ANALYSIS BY SUBJECTS'!L179 -> 18 | N7: 0 | O7: =((E7+F7)/C7) -> 0.013422819 | P7: =(SUM(G7:J7)/C7) -> 0.41610738 | Q7: =(SUM(K7:L7)/C7) -> 0.44966443 | R7: =M7/C7 -> 0.12080537 | S7: ='OVERALL PERFORMANCES'!B3 -> 61.073826 | T7: ='OVERALL PERFORMANCES'!C3 -> 87.919463
A8: English Language | C8: ='ANALYSIS BY SUBJECTS'!C180 -> 149 | D8: ='ANALYSIS BY SUBJECTS'!C180 -> 149 | E8: ='ANALYSIS BY SUBJECTS'!D180 -> 0 | F8: ='ANALYSIS BY SUBJECTS'!E180 -> 16 | G8: ='ANALYSIS BY SUBJECTS'!F180 -> 10 | H8: ='ANALYSIS BY SUBJECTS'!G180 -> 13 | I8: ='ANALYSIS BY SUBJECTS'!H180 -> 24 | J8: ='ANALYSIS BY SUBJECTS'!I180 -> 25 | K8: ='ANALYSIS BY SUBJECTS'!J180 -> 35 | ... M8: ='ANALYSIS BY SUBJECTS'!L180 -> 12 | N8: 0 | O8: =((E8+F8)/C8) -> 0.10738255 | P8: =(SUM(G8:J8)/C8) -> 0.48322148 | Q8: =(SUM(K8:L8)/C8) -> 0.32885906 | R8: =M8/C8 -> 0.080536913 | S8: ='OVERALL PERFORMANCES'!B4 -> 59.060403 | T8: ='OVERALL PERFORMANCES'!C4 -> 91.946309
A9: Mathematics D | C9: ='ANALYSIS BY SUBJECTS'!C181 -> 108 | D9: ='ANALYSIS BY SUBJECTS'!C181 -> 108 | E9: ='ANALYSIS BY SUBJECTS'!D181 -> 0 | F9: ='ANALYSIS BY SUBJECTS'!E181 -> 11 | G9: ='ANALYSIS BY SUBJECTS'!F181 -> 3 | H9: ='ANALYSIS BY SUBJECTS'!G181 -> 8 | I9: ='ANALYSIS BY SUBJECTS'!H181 -> 6 | J9: ='ANALYSIS BY SUBJECTS'!I181 -> 4 | K9: ='ANALYSIS BY SUBJECTS'!J181 -> 13 | ... M9: ='ANALYSIS BY SUBJECTS'!L181 -> 49 | N9: 0 | O9: =((E9+F9)/C9) -> 0.10185185 | P9: =(SUM(G9:J9)/C9) -> 0.19444444 | Q9: =(SUM(K9:L9)/C9) -> 0.25 | R9: =M9/C9 -> 0.4537037 | S9: ='OVERALL PERFORMANCES'!B5 -> 29.62963 | T9: ='OVERALL PERFORMANCES'!C5 -> 54.62963
A10: Physics | C10: ='ANALYSIS BY SUBJECTS'!C182 -> 54 | D10: ='ANALYSIS BY SUBJECTS'!C182 -> 54 | E10: ='ANALYSIS BY SUBJECTS'!D182 -> 0 | F10: ='ANALYSIS BY SUBJECTS'!E182 -> 4 | G10: ='ANALYSIS BY SUBJECTS'!F182 -> 2 | H10: ='ANALYSIS BY SUBJECTS'!G182 -> 3 | I10: ='ANALYSIS BY SUBJECTS'!H182 -> 8 | J10: ='ANALYSIS BY SUBJECTS'!I182 -> 6 | K10: ='ANALYSIS BY SUBJECTS'!J182 -> 7 | ... M10: ='ANALYSIS BY SUBJECTS'!L182 -> 20 | N10: 0 | O10: =((E10+F10)/C10) -> 0.074074074 | P10: =(SUM(G10:J10)/C10) -> 0.35185185 | Q10: =(SUM(K10:L10)/C10) -> 0.2037037 | R10: =M10/C10 -> 0.37037037 | S10: ='OVERALL PERFORMANCES'!B6 -> 42.592593 | T10: ='OVERALL PERFORMANCES'!C6 -> 62.962963
A11: Chemistry | C11: ='ANALYSIS BY SUBJECTS'!C183 -> 37 | D11: ='ANALYSIS BY SUBJECTS'!C183 -> 37 | E11: ='ANALYSIS BY SUBJECTS'!D183 -> 1 | F11: ='ANALYSIS BY SUBJECTS'!E183 -> 3 | G11: ='ANALYSIS BY SUBJECTS'!F183 -> 3 | H11: ='ANALYSIS BY SUBJECTS'!G183 -> 7 | I11: ='ANALYSIS BY SUBJECTS'!H183 -> 4 | J11: ='ANALYSIS BY SUBJECTS'!I183 -> 5 | K11: ='ANALYSIS BY SUBJECTS'!J183 -> 6 | ... M11: ='ANALYSIS BY SUBJECTS'!L183 -> 2 | N11: 0 | O11: =((E11+F11)/C11) -> 0.10810811 | P11: =(SUM(G11:J11)/C11) -> 0.51351351 | Q11: =(SUM(K11:L11)/C11) -> 0.32432432 | R11: =M11/C11 -> 0.054054054 | S11: ='OVERALL PERFORMANCES'!B7 -> 62.162162 | T11: ='OVERALL PERFORMANCES'!C7 -> 94.594595
A12: Biology | C12: ='ANALYSIS BY SUBJECTS'!C184 -> 35 | D12: ='ANALYSIS BY SUBJECTS'!C184 -> 35 | E12: ='ANALYSIS BY SUBJECTS'!D184 -> 0 | F12: ='ANALYSIS BY SUBJECTS'!E184 -> 0 | G12: ='ANALYSIS BY SUBJECTS'!F184 -> 3 | H12: ='ANALYSIS BY SUBJECTS'!G184 -> 5 | I12: ='ANALYSIS BY SUBJECTS'!H184 -> 3 | J12: ='ANALYSIS BY SUBJECTS'!I184 -> 13 | K12: ='ANALYSIS BY SUBJECTS'!J184 -> 4 | ... M12: ='ANALYSIS BY SUBJECTS'!L184 -> 2 | N12: 0 | O12: =((E12+F12)/C12) -> 0 | P12: =(SUM(G12:J12)/C12) -> 0.68571429 | Q12: =(SUM(K12:L12)/C12) -> 0.25714286 | R12: =M12/C12 -> 0.057142857 | S12: ='OVERALL PERFORMANCES'!B8 -> 68.571429 | T12: ='OVERALL PERFORMANCES'!C8 -> 94.285714
A13: Combined Science | C13: ='ANALYSIS BY SUBJECTS'!C185 -> 41 | D13: ='ANALYSIS BY SUBJECTS'!C185 -> 41 | E13: ='ANALYSIS BY SUBJECTS'!D185 -> 0 | F13: ='ANALYSIS BY SUBJECTS'!E185 -> 0 | G13: ='ANALYSIS BY SUBJECTS'!F185 -> 0 | H13: ='ANALYSIS BY SUBJECTS'!G185 -> 0 | I13: ='ANALYSIS BY SUBJECTS'!H185 -> 1 | J13: ='ANALYSIS BY SUBJECTS'!I185 -> 0 | K13: ='ANALYSIS BY SUBJECTS'!J185 -> 1 | ... M13: ='ANALYSIS BY SUBJECTS'!L185 -> 30 | N13: 0 | O13: =((E13+F13)/C13) -> 0 | P13: =(SUM(G13:J13)/C13) -> 0.024390244 | Q13: =(SUM(K13:L13)/C13) -> 0.24390244 | R13: =M13/C13 -> 0.73170732 | S13: ='OVERALL PERFORMANCES'!B9 -> 2.4390244 | T13: ='OVERALL PERFORMANCES'!C9 -> 26.829268
A14: Geography | C14: ='ANALYSIS BY SUBJECTS'!C186 -> 63 | D14: ='ANALYSIS BY SUBJECTS'!C186 -> 63 | E14: ='ANALYSIS BY SUBJECTS'!D186 -> 0 | F14: ='ANALYSIS BY SUBJECTS'!E186 -> 0 | G14: ='ANALYSIS BY SUBJECTS'!F186 -> 0 | H14: ='ANALYSIS BY SUBJECTS'!G186 -> 0 | I14: ='ANALYSIS BY SUBJECTS'!H186 -> 1 | J14: ='ANALYSIS BY SUBJECTS'!I186 -> 4 | K14: ='ANALYSIS BY SUBJECTS'!J186 -> 13 | ... M14: ='ANALYSIS BY SUBJECTS'!L186 -> 27 | N14: 0 | O14: =((E14+F14)/C14) -> 0 | P14: =(SUM(G14:J14)/C14) -> 0.079365079 | Q14: =(SUM(K14:L14)/C14) -> 0.49206349 | R14: =M14/C14 -> 0.42857143 | S14: ='OVERALL PERFORMANCES'!B10 -> 7.9365079 | T14: ='OVERALL PERFORMANCES'!C10 -> 57.142857
A15: IRK | C15: ='ANALYSIS BY SUBJECTS'!C187 -> 148 | D15: ='ANALYSIS BY SUBJECTS'!C187 -> 148 | E15: ='ANALYSIS BY SUBJECTS'!D187 -> 10 | F15: ='ANALYSIS BY SUBJECTS'!E187 -> 25 | G15: ='ANALYSIS BY SUBJECTS'!F187 -> 15 | H15: ='ANALYSIS BY SUBJECTS'!G187 -> 12 | I15: ='ANALYSIS BY SUBJECTS'!H187 -> 15 | J15: ='ANALYSIS BY SUBJECTS'!I187 -> 15 | K15: ='ANALYSIS BY SUBJECTS'!J187 -> 16 | ... M15: ='ANALYSIS BY SUBJECTS'!L187 -> 25 | N15: 0 | O15: =((E15+F15)/C15) -> 0.23648649 | P15: =(SUM(G15:J15)/C15) -> 0.38513514 | Q15: =(SUM(K15:L15)/C15) -> 0.20945946 | R15: =M15/C15 -> 0.16891892 | S15: ='OVERALL PERFORMANCES'!B11 -> 62.162162 | T15: ='OVERALL PERFORMANCES'!C11 -> 83.108108
A16: History | C16: ='ANALYSIS BY SUBJECTS'!C188 -> 23 | D16: ='ANALYSIS BY SUBJECTS'!C188 -> 23 | E16: ='ANALYSIS BY SUBJECTS'!D188 -> 0 | F16: ='ANALYSIS BY SUBJECTS'!E188 -> 4 | G16: ='ANALYSIS BY SUBJECTS'!F188 -> 1 | H16: ='ANALYSIS BY SUBJECTS'!G188 -> 0 | I16: ='ANALYSIS BY SUBJECTS'!H188 -> 1 | J16: ='ANALYSIS BY SUBJECTS'!I188 -> 1 | K16: ='ANALYSIS BY SUBJECTS'!J188 -> 5 | ... M16: ='ANALYSIS BY SUBJECTS'!L188 -> 2 | N16: 0 | O16: =((E16+F16)/C16) -> 0.17391304 | P16: =(SUM(G16:J16)/C16) -> 0.13043478 | Q16: =(SUM(K16:L16)/C16) -> 0.60869565 | R16: =M16/C16 -> 0.086956522 | S16: ='OVERALL PERFORMANCES'!B12 -> 30.434783 | T16: ='OVERALL PERFORMANCES'!C12 -> 91.304348
A17: Commerce | C17: ='ANALYSIS BY SUBJECTS'!C189 -> 11 | D17: ='ANALYSIS BY SUBJECTS'!C189 -> 11 | E17: ='ANALYSIS BY SUBJECTS'!D189 -> 0 | F17: ='ANALYSIS BY SUBJECTS'!E189 -> 1 | G17: ='ANALYSIS BY SUBJECTS'!F189 -> 0 | H17: ='ANALYSIS BY SUBJECTS'!G189 -> 0 | I17: ='ANALYSIS BY SUBJECTS'!H189 -> 2 | J17: ='ANALYSIS BY SUBJECTS'!I189 -> 5 | K17: ='ANALYSIS BY SUBJECTS'!J189 -> 1 | ... M17: ='ANALYSIS BY SUBJECTS'!L189 -> 0 | N17: 0 | O17: =((E17+F17)/C17) -> 0.090909091 | P17: =(SUM(G17:J17)/C17) -> 0.63636364 | Q17: =(SUM(K17:L17)/C17) -> 0.27272727 | R17: =M17/C17 -> 0 | S17: ='OVERALL PERFORMANCES'!B13 -> 72.727273 | T17: ='OVERALL PERFORMANCES'!C13 -> 100
A18: Economics | C18: ='ANALYSIS BY SUBJECTS'!C190 -> 12 | D18: ='ANALYSIS BY SUBJECTS'!C190 -> 12 | E18: ='ANALYSIS BY SUBJECTS'!D190 -> 0 | F18: ='ANALYSIS BY SUBJECTS'!E190 -> 0 | G18: ='ANALYSIS BY SUBJECTS'!F190 -> 1 | H18: ='ANALYSIS BY SUBJECTS'!G190 -> 0 | I18: ='ANALYSIS BY SUBJECTS'!H190 -> 2 | J18: ='ANALYSIS BY SUBJECTS'!I190 -> 1 | K18: ='ANALYSIS BY SUBJECTS'!J190 -> 5 | ... M18: ='ANALYSIS BY SUBJECTS'!L190 -> 1 | N18: 0 | O18: =((E18+F18)/C18) -> 0 | P18: =(SUM(G18:J18)/C18) -> 0.33333333 | Q18: =(SUM(K18:L18)/C18) -> 0.58333333 | R18: =M18/C18 -> 0.083333333 | S18: ='OVERALL PERFORMANCES'!B14 -> 33.333333 | T18: ='OVERALL PERFORMANCES'!C14 -> 91.666667
... A22: Agriculture | C22: ='ANALYSIS BY SUBJECTS'!C194 -> 5 | D22: ='ANALYSIS BY SUBJECTS'!C194 -> 5 | E22: ='ANALYSIS BY SUBJECTS'!D194 -> 0 | F22: ='ANALYSIS BY SUBJECTS'!E194 -> 0 | G22: ='ANALYSIS BY SUBJECTS'!F194 -> 1 | H22: ='ANALYSIS BY SUBJECTS'!G194 -> 0 | I22: ='ANALYSIS BY SUBJECTS'!H194 -> 1 | J22: ='ANALYSIS BY SUBJECTS'!I194 -> 1 | K22: ='ANALYSIS BY SUBJECTS'!J194 -> 0 | ... M22: ='ANALYSIS BY SUBJECTS'!L194 -> 1 | N22: 0 | O22: =((E22+F22)/C22) -> 0 | P22: =(SUM(G22:J22)/C22) -> 0.6 | Q22: =(SUM(K22:L22)/C22) -> 0.2 | R22: =M22/C22 -> 0.2 | S22: ='OVERALL PERFORMANCES'!B18 -> 60 | T22: ='OVERALL PERFORMANCES'!C18 -> 80
A23: Sastera | C23: ='ANALYSIS BY SUBJECTS'!C194 -> 5 | D23: ='ANALYSIS BY SUBJECTS'!C194 -> 5 | E23: ='ANALYSIS BY SUBJECTS'!D194 -> 0 | F23: ='ANALYSIS BY SUBJECTS'!E194 -> 0 | G23: ='ANALYSIS BY SUBJECTS'!F194 -> 1 | H23: ='ANALYSIS BY SUBJECTS'!G194 -> 0 | I23: ='ANALYSIS BY SUBJECTS'!H194 -> 1 | J23: ='ANALYSIS BY SUBJECTS'!I194 -> 1 | K23: ='ANALYSIS BY SUBJECTS'!J194 -> 0 | ... M23: ='ANALYSIS BY SUBJECTS'!L194 -> 1 | N23: 0 | O23: =((E23+F23)/C23) -> 0 | P23: =(SUM(G23:J23)/C23) -> 0.6 | Q23: =(SUM(K23:L23)/C23) -> 0.2 | R23: =M23/C23 -> 0.2 | S23: ='OVERALL PERFORMANCES'!B18 -> 60 | T23: ='OVERALL PERFORMANCES'!C18 -> 80
A24: Computer Science | C24: ='ANALYSIS BY SUBJECTS'!$C$165 -> 20 | D24: ='ANALYSIS BY SUBJECTS'!C165 -> 20 | E24: ='ANALYSIS BY SUBJECTS'!D165 -> 0 | F24: ='ANALYSIS BY SUBJECTS'!E165 -> 2 | G24: ='ANALYSIS BY SUBJECTS'!F165 -> 3 | H24: ='ANALYSIS BY SUBJECTS'!G165 -> 1 | I24: ='ANALYSIS BY SUBJECTS'!H165 -> 5 | J24: ='ANALYSIS BY SUBJECTS'!I165 -> 2 | K24: ='ANALYSIS BY SUBJECTS'!J165 -> 4 | ... M24: ='ANALYSIS BY SUBJECTS'!L165 -> 1 | N24: 0 | O24: =((E24+F24)/C24) -> 0.1 | P24: =(SUM(G24:J24)/C24) -> 0.55 | Q24: =(SUM(K24:L24)/C24) -> 0.3 | R24: =M24/C24 -> 0.05 | S24: ='OVERALL PERFORMANCES'!B19 -> 56.097561 | T24: ='OVERALL PERFORMANCES'!C19 -> 87.804878
A25: IG ICT | C25: ='ANALYSIS BY SUBJECTS'!C197 -> 10 | D25: ='ANALYSIS BY SUBJECTS'!D197 -> 0 | E25: ='ANALYSIS BY SUBJECTS'!E197 -> 0 | F25: ='ANALYSIS BY SUBJECTS'!F197 -> 0 | G25: ='ANALYSIS BY SUBJECTS'!G197 -> 2 | H25: ='ANALYSIS BY SUBJECTS'!H197 -> 0 | I25: ='ANALYSIS BY SUBJECTS'!I197 -> 2 | J25: ='ANALYSIS BY SUBJECTS'!J197 -> 3 | ... M25: ='ANALYSIS BY SUBJECTS'!M197 -> 4 | N25: 0 | O25: =((E25+F25)/C25) -> 0 | P25: =(SUM(G25:J25)/C25) -> 0.7 | Q25: =(SUM(K25:L25)/C25) -> 0.3 | R25: =M25/C25 -> 0.4 | S25: ='OVERALL PERFORMANCES'!B20 -> 65 | T25: ='OVERALL PERFORMANCES'!C20 -> 95
C27: NUMBER OF CANDIDATES OBTAINING | O27: PERCENTAGE FOR GRADES | U27: REMARKS
C28: NO. OF CANDIDATE | E28: Distinction | G28: Credit | I28: Pass | M28: Fail | N28: ABSENT | O28: Distinction | P28: Credit | Q28: Pass | R28: Fail | S28: Credit | T28: Pass
A29: Subject | C29: REGISTERED | D29: SAT | E29: A* | F29: A | G29: B | H29: C | I29: D | J29: E | K29: F | L29: G | M29: U | N29: X | O29: A*- A | P29: B-C | Q29: D-G | R29: U | S29: % A* - C | T29: % A* - G
A30: IGCSE English E2L (Core) | C30: ='ANALYSIS BY SUBJECTS'!#REF! -> #REF! | D30: ='ANALYSIS BY SUBJECTS'!#REF! -> #REF! | H30: ='ANALYSIS BY SUBJECTS'!#REF! -> #REF! | I30: ='ANALYSIS BY SUBJECTS'!#REF! -> #REF! | J30: ='ANALYSIS BY SUBJECTS'!#REF! -> #REF! | K30: ='ANALYSIS BY SUBJECTS'!#REF! -> #REF! | L30: ='ANALYSIS BY SUBJECTS'!#REF! -> #REF! | M30: ='ANALYSIS BY SUBJECTS'!#REF! -> #REF! | N30: 0 | O30: =((E30+F30)/C30) -> #REF! | P30: =(SUM(G30:H30)/C30) -> #REF! | Q30: =(SUM(I30:L30)/C30) -> #REF! | R30: =M30/C30 -> #REF! | S30: =(SUM(E30:H30)/C30) -> #REF! | T30: =(SUM(E30:L30)/D30) -> #REF!
A31: IGCSE Mathematics (Core) | C31: ='ANALYSIS BY SUBJECTS'!$C$47 -> 37 | D31: ='ANALYSIS BY SUBJECTS'!$C$47 -> 37 | H31: ='ANALYSIS BY SUBJECTS'!D47 -> 0 | I31: ='ANALYSIS BY SUBJECTS'!E47 -> 0 | J31: ='ANALYSIS BY SUBJECTS'!F47 -> 6 | K31: ='ANALYSIS BY SUBJECTS'!G47 -> 2 | L31: ='ANALYSIS BY SUBJECTS'!H47 -> 7 | M31: ='ANALYSIS BY SUBJECTS'!I47 -> 5 | N31: 0 | O31: =((E31+F31)/C31) -> 0 | P31: =(SUM(G31:H31)/C31) -> 0 | Q31: =(SUM(I31:L31)/C31) -> 0.40540541 | R31: =M31/C31 -> 0.13513514 | S31: =(SUM(E31:H31)/C31) -> 0 | T31: =(SUM(E31:L31)/D31) -> 0.40540541

Sheet Sheet1
A1: Y10 MID YEAR EXAMINATION 2016
A2: SEKOLAH MENENGAH PG ANAK PUTERI HAJAH MASNA
A4: No. Of Candidate Registered | E4: 195
A5: No. Of Candidate Sitting | E5: 195
A6: Withdrawn | E6: 0
A8: Credit Attained | B8: No. Of Student | D8: %
A9: 9
A10: 8
A11: 7
A12: 6
A13: 5
A14: 4
A15: 3
A16: 2
A17: 1
A18: 0
A19: Total | B19: 195
C22: No. of Student | D22: %
A23: 4 or more Credits | D23: =C23/B19 -> 0
A24: 5 or more Credits | D24: =C24/B19 -> 0

Sheet Sheet2

Sheet 3'O' and 5'O' & above
A1: YEAR 10 END OF YEAR EXAMINATION 2025
B3: No. of Candidates | C3: No. of Credits Obtained | M3: 5 'O' & above | O3: 3 'O' & above
C4: 9 | D4: 8 | E4: 7 | F4: 6 | G4: 5 | H4: 4 | I4: 3 | J4: 2 | K4: 1 | L4: 0 | M4: No. of Candidates | N4: % | O4: No. of Candidates | P4: %
A5: 10SCI2 | B5: =SUM(_xlfn.ANCHORARRAY(C5)) -> 21 | C5: {=TRANSPOSE([1]Master!$BV$47:$BV$56)} -> 2 | D5: 1 | E5: 4 | F5: 2 | G5: 3 | H5: 4 | I5: 1 | J5: 0 | K5: 4 | L5: 0 | M5: =SUM(C5:G5) -> 12 | N5: =M5/B5 -> 0.57142857 | O5: =SUM(C5:I5) -> 17 | P5: =O5/B5 -> 0.80952381
A6: 10SCI3 | B6: =SUM(_xlfn.ANCHORARRAY(C6)) -> 15 | C6: {=TRANSPOSE([2]Master!$BM$47:$BM$56)} -> 0 | D6: 0 | E6: 0 | F6: 0 | G6: 0 | H6: 0 | I6: 0 | J6: 0 | K6: 0 | L6: 15 | M6: =SUM(D6:H6) -> 0 | N6: =M6/B6 -> 0 | O6: =SUM(D6:J6) -> 0 | P6: =O6/B6 -> 0
A7: 10P | B7: =SUM(_xlfn.ANCHORARRAY(C7)) -> 24 | C7: {=TRANSPOSE([3]Master!$BI$46:$BI$55)} -> 0 | D7: 0 | E7: 0 | F7: 4 | G7: 3 | H7: 2 | I7: 10 | J7: 4 | K7: 1 | L7: 0 | M7: =SUM(C7:G7) -> 7 | N7: =M7/B7 -> 0.29166667 | O7: =SUM(C7:I7) -> 19 | P7: =O7/B7 -> 0.79166667
A8: 10R | B8: =SUM(_xlfn.ANCHORARRAY(C8)) -> 24 | C8: {=TRANSPOSE([4]Master!$BR$47:$BR$56)} -> 0 | D8: 0 | E8: 0 | F8: 1 | G8: 1 | H8: 7 | I8: 12 | J8: 3 | K8: 0 | L8: 0 | M8: =SUM(C8:G8) -> 2 | N8: =M8/B8 -> 0.083333333 | O8: =SUM(C8:I8) -> 21 | P8: =O8/B8 -> 0.875
A9: 10I | B9: =SUM(_xlfn.ANCHORARRAY(C9)) -> 26 | C9: {=TRANSPOSE([12]Master!$BI$47:$BI$56)} -> 0 | D9: 0 | E9: 0 | F9: 0 | G9: 0 | H9: 2 | I9: 3 | J9: 9 | K9: 6 | L9: 6 | M9: =SUM(C9:G9) -> 0 | N9: =M9/B9 -> 0 | O9: =SUM(C9:I9) -> 5 | P9: =O9/B9 -> 0.19230769
A10: 10M | B10: =SUM(_xlfn.ANCHORARRAY(C10)) -> 21 | C10: {=TRANSPOSE([13]Master!$BR$47:$BR$56)} -> 0 | D10: 0 | E10: 0 | F10: 0 | G10: 0 | H10: 1 | I10: 5 | J10: 9 | K10: 5 | L10: 1 | M10: =SUM(C10:G10) -> 0 | N10: =M10/B10 -> 0 | O10: =SUM(C10:I10) -> 6 | P10: =O10/B10 -> 0.28571429
A11: 10E | B11: =SUM(_xlfn.ANCHORARRAY(C11)) -> 20 | C11: {=TRANSPOSE([14]Master!$BA$47:$BA$56)} -> 0 | D11: 0 | E11: 0 | F11: 0 | G11: 1 | H11: 2 | I11: 6 | J11: 5 | K11: 3 | L11: 3 | M11: =SUM(C11:G11) -> 1 | N11: =M11/B11 -> 0.05 | O11: =SUM(C11:I11) -> 9 | P11: =O11/B11 -> 0.45
A12: Total No. of Candidates | B12: =SUM(B5:B11) -> 151 | C12: =SUM(C5:C11) -> 2 | D12: =SUM(D5:D11) -> 1 | E12: =SUM(E5:E11) -> 4 | F12: =SUM(F5:F11) -> 7 | G12: =SUM(G5:G11) -> 8 | H12: =SUM(H5:H11) -> 18 | I12: =SUM(I5:I11) -> 37 | ... M12: =SUM(M5:M11) -> 22 | N12: =M12/B12 -> 0.14569536 | O12: =SUM(O5:O11) -> 77 | P12: =O12/B12 -> 0.50993377
A14: % obtained 5'O' & above | B14: =$N$12 -> 0.14569536
A15: % obtained 3'O' & above | B15: =$P$12 -> 0.50993377

Sheet No.of Credits Attained
A1: YEAR 10 END OF YEAR EXAMINATION 2025
A3: No. Of Candidate Registered | E3: 200
A4: No. Of Candidate Sitting | E4: =$B$18 -> 151
A5: Withdrawn | E5: 0
A7: Credit Attained | B7: No. Of Student | D7: %
A8: 9 | B8: ='3''O'' and 5''O'' & above'!$C$12 -> 2 | D8: =B8/B18 -> 0.013245033
A9: 8 | B9: ='3''O'' and 5''O'' & above'!$D$12 -> 1 | D9: =B9/B18 -> 0.0066225166
A10: 7 | B10: ='3''O'' and 5''O'' & above'!$E$12 -> 4 | D10: =B10/B18 -> 0.026490066
A11: 6 | B11: ='3''O'' and 5''O'' & above'!$F$12 -> 7 | D11: =B11/B18 -> 0.046357616
A12: 5 | B12: ='3''O'' and 5''O'' & above'!$G$12 -> 8 | D12: =B12/B18 -> 0.052980132
A13: 4 | B13: ='3''O'' and 5''O'' & above'!$H$12 -> 18 | D13: =B13/B18 -> 0.1192053
A14: 3 | B14: ='3''O'' and 5''O'' & above'!$I$12 -> 37 | D14: =B14/B18 -> 0.24503311
A15: 2 | B15: ='3''O'' and 5''O'' & above'!$J$12 -> 30 | D15: =B15/B18 -> 0.1986755
A16: 1 | B16: ='3''O'' and 5''O'' & above'!$K$12 -> 19 | D16: =B16/B18 -> 0.12582781
A17: 0 | B17: ='3''O'' and 5''O'' & above'!$L$12 -> 25 | D17: =B17/B18 -> 0.16556291
A18: Total | B18: =SUM(B8:C17) -> 151
C21: No. of Student | D21: %
A22: 3 or more Credits | C22: =SUM(B8:C14) -> 77 | D22: =C22/B18 -> 0.50993377
A23: 4 or more Credits | C23: =SUM(B8:C13) -> 40 | D23: =C23/B18 -> 0.26490066
A24: 5 or more Credits | C24: =SUM(B8:C12) -> 22 | D24: =C24/B18 -> 0.14569536
